Workbook

Sheet 사용안내
B2: 27SS 소재일정 역산 트래커 — 출고일 기준, 설·춘절 보정 + 비수기 선정 + 금액 요약 (0808 원본)
B4: 정렬 순서
B5: ① S코드(봄) 전체 — 납기상 최우선 그룹
B6: ② 비수기 선정 스타일(봄 제외) — 봄코드 바로 아래 배치 (출고일과 무관하게 우선 조율 대상)
B7: ③ 나머지 M(여름) → X(사계절) — 각 그룹 안에서는 출고일 주차 순
B9: 계산 로직
B10: ① 출고예정일 = 출고일 주차를 날짜로 환산 (1주=1일, 2주=8일, 3주=15일, 4주=22일 / 9~12월은 전년도)
B11: ② 제품입고 시점 = 출고예정일 − 2주(14일). 입고시점이 한국 설 연휴(2/5~2/8)에 걸치면 연휴 전(2/4)으로 앞당김
B12: ③ 소재입고 마감일 = 제품입고 시점 − 90일 − 공장휴무 보정일 (중국·베트남 춘절 2/1~2/15, 한국 설 2/5~2/8)
B13: ④ 작지 미발행(X/부분) 또는 소재입고일 > 마감일 → S코드(봄) '★ 납기위험', M/X 시즌 '◆ 지연주의'
B14: ⑤ 소재입고 책임: CMT = 본사(소재팀) / 완사입·ODM = 생산처 (수/C/완 컬럼 기준 자동)
B15: ⑥ 원가합 = Σ(기획수량×입고원가), 소매가합 = Σ(기획수량×예상소매가) — 0808 원본 총원가/총공급가 컬럼 기준
... B40: · 8UTCM27101은 컬러별 출고일 상이(1월3주/4월2주) → 다수 값 적용, 확인 필요

Sheet 기준정보
B2: 기준정보 (노란색 = 조정 가능한 입력값)
B4: 기준일 (오늘) | C4: =TODAY() | D4: 판정 기준일. 파일 열 때 자동 갱신
B5: 입고 리드타임(일) | C5: 14 | D5: 출고예정일 − 2주 = 제품입고 시점
B6: 소재 리드타임(일) | C6: 90 | D6: 제품입고 시점 − 90일 = 소재입고 마감일
B7: 시즌 연도 | C7: 2027 | D7: 27SS 출고 연도. 9~12월 주차는 전년(2026)으로 환산
B8: 춘절 공장휴무 시작 | C8: 46419 | D8: 중국·베트남 공장 가동중단 가정 (전후 2주)
B9: 춘절 공장휴무 종료 | C9: 46433 | D9: 실제 공장별 휴무 확정 시 조정
B10: 한국 설 연휴 시작 | C10: 46423 | D10: 설날 2/6(토), 연휴 2/5(금)~2/7(일)
B11: 한국 설 연휴 종료 | C11: 46426 | D11: 대체공휴일 2/8(월) 포함
B13: 소재입고 책임 구분 (수/C/완 기준)
B14: C / CMT | C14: 본사(소재팀) 책임 — 소재 발주·입고 본사 컨트롤
B15: 완(완사입) / ODM | C15: 생산처 책임 — 생산처가 소재 수배·입고 컨트롤

Sheet 소재역산 트래커
A1: 27SS 소재일정 역산 트래커 — 정렬: S코드(봄) → 비수기 선정 → 나머지 (424 스타일)
A2: 기준일: | B2: =기준정보!$C$4 | C2: 리드타임: | D2: ="입고 "&기준정보!$C$5&"일 + 소재 "&기준정보!$C$6&"일 + 휴무보정" | G2: 노란색 = 입력 · ★ = S코드 작지 미발행/소재마감 초과 · 정렬: ①봄(S) ②비수기 선정 ③나머지 · 금액은 [금액 요약] 참조
A4: NO | B4: MD | C4: DS | D4: Style Code | E4: 품명 | F4: 컬러 구성 | G4: 시즌 | H4: 생산형태 (수/C/완) | I4: 출고차순 | J4: 출고일(주차) | K4: 출고예정일 | L4: 제품입고 시점 (출고-2주, 설연휴 보정) | M4: 공장휴무 보정 (일) | N4: 소재입고 마감일 (입고-90일-보정) | O4: 마감까지 D-day | P4: 비수기 선정 | Q4: 작지발행 | R4: 사양확정 (전산 실시간) | S4: 소재입고 예정/실제일 | T4: 소재입고 책임 | U4: 생산처 | V4: 생산처 (소재DB) | W4: 원산지 | X4: 원단처 (에이전시) | Y4: 겉감정보 (원단처+품명) | Z4: 안감정보 (원단처+품명) | AA4: 기획수량 | AB4: 원가합 (원) | AC4: 소매가합 (원) | AD4: 납기1차 (전산참고) | AE4: 리스크 사유 | AF4: 판정 | AG4: 조율상태 | AH4: 메모/조치사항
A5: 1 | B5: 최진민 | C5: 강기환 | D5: JKJGS27002 | E5: 히어로 여성 고어텍스 3L PRO 재킷 | F5: LPI-2, BLK(BLACK) | G5: =IF($D5="","",IF(MID($D5,5,1)="S","S(봄)",IF(MID($D5,5,1)="M","M(여름)",IF(MID($D5,5,1)="X","X(사계절)",MID($D5,5,1))))) | H5: 완사입 | I5: S1 | J5: 1월2주 | K5: =IF($J5="","",IFERROR(DATE(IF(VALUE(LEFT($J5,FIND("월",$J5)-1))>=9,기준정보!$C$7-1,기준정보!$C$7),VALUE(LEFT($J5,FIND("월",$J5)-1)),1+7*(VALUE(SUBSTITUTE(MID($J5,FIND("월",$J5)+1,5),"주",""))-1)),"")) | L5: =IF($K5="","",IF(AND($K5-기준정보!$C$5>=기준정보!$C$10,$K5-기준정보!$C$5<=기준정보!$C$11),기준정보!$C$10-1,$K5-기준정보!$C$5)) | M5: =IF($L5="","",IF(OR(ISNUMBER(SEARCH("중국",$W5)),ISNUMBER(SEARCH("베트남",$W5))),MAX(0,MIN($L5,기준정보!$C$9)-MAX($L5-기준정보!$C$6,기준정보!$C$8)+1),IF(ISNUMBER(SEARCH("한국",$W5)),MAX(0,MIN($L5,기준정보!$C$11)-MAX($L5-기준정보!$C$6,기준정보!$C$10)+1),0))) | N5: =IF($L5="","",$L5-기준정보!$C$6-$M5) | O5: =IF($N5="","",$N5-기준정보!$C$4) | Q5: O | R5: =IF(COUNTIF(EDW_RAW!$A$2:$A$1500,$D5)=0,"",IF(COUNTIFS(EDW_RAW!$A$2:$A$1500,$D5,EDW_RAW!$U$2:$U$1500,"<>~",EDW_RAW!$U$2:$U$1500,"<>")=COUNTIF(EDW_RAW!$A$2:$A$1500,$D5),"O",IF(COUNTIFS(EDW_RAW!$A$2:$A$1500,$D5,EDW_RAW!$U$2:$U$1500,"<>~",EDW_RAW!$U$2:$U$1500,"<>")>0,"부분","X"))) | T5: =IF($H5="","",IF(AND(ISNUMBER(SEARCH("CMT",$H5)),OR(ISNUMBER(SEARCH("완사입",$H5)),ISNUMBER(SEARCH("ODM",$H5)))),"본사/생산처 혼재",IF(ISNUMBER(SEARCH("CMT",$H5)),"본사(소재팀)","생산처"))) | U5: 포마트 | V5: =IFERROR(TEXTJOIN(" / ",TRUE,UNIQUE(FILTER(소재DB_RAW!$K$3:$K$2000,(소재DB_RAW!$G$3:$G$2000=$D5)*ISERROR(SEARCH("drop",소재DB_RAW!$C$3:$C$2000))))),"") | W5: 베트남 | X5: =IFERROR(TEXTJOIN(" / ",TRUE,UNIQUE(FILTER(소재DB_RAW!$N$3:$N$2000,(소재DB_RAW!$G$3:$G$2000=$D5)*ISERROR(SEARCH("drop",소재DB_RAW!$C$3:$C$2000))))),"") | Y5: =IFERROR(TEXTJOIN(CHAR(10),TRUE,UNIQUE(FILTER(소재DB_RAW!$N$3:$N$2000&") "&소재DB_RAW!$O$3:$O$2000,(소재DB_RAW!$G$3:$G$2000=$D5)*ISNUMBER(SEARCH("겉감",소재DB_RAW!$M$3:$M$2000))*ISERROR(SEARCH("drop",소재DB_RAW!$C$3:$C$2000))))),"") | Z5: =IFERROR(TEXTJOIN(CHAR(10),TRUE,UNIQUE(FILTER(소재DB_RAW!$N$3:$N$2000&") "&소재DB_RAW!$O$3:$O$2000,(소재DB_RAW!$G$3:$G$2000=$D5)*ISNUMBER(SEARCH("안감",소재DB_RAW!$M$3:$M$2000))*ISERROR(SEARCH("drop",소재DB_RAW!$C$3:$C$2000))))),"") | AA5: 190 | AB5: 47398730 | AC5: 188100000 | AE5: =IF($K5="","출고일 미정",IF($Q5="X","작지 미발행",IF($Q5="부분","작지 일부 미발행",IF(AND($S5<>"",$S5>$N5),"소재입고 마감("&TEXT($N5,"MM/DD")&") 초과",IF($Q5="","발행여부 확인 필요",IF($S5="","소재 입고일정 확인 필요","정상")))))) | AF5: =IF($K5="","",IF(OR(LEFT($AE5,2)="작지",LEFT($AE5,4)="소재입고"),IF(LEFT($G5,1)="S","★ 납기위험(S코드)","◆ 지연주의"),IF($AE5="정상","✓ 정상","? 확인필요")))
A6: 2 | B6: 최진민 | C6: 강기환 | D6: JKJJS27012 | E6: 히어로 여성 프리마로프트 HEAVY 인슐레이션 재킷 | F6: GRY(GRAY), BLK(BLACK) | G6: =IF($D6="","",IF(MID($D6,5,1)="S","S(봄)",IF(MID($D6,5,1)="M","M(여름)",IF(MID($D6,5,1)="X","X(사계절)",MID($D6,5,1))))) | H6: 완사입 | I6: S1 | J6: 1월2주 | K6: =IF($J6="","",IFERROR(DATE(IF(VALUE(LEFT($J6,FIND("월",$J6)-1))>=9,기준정보!$C$7-1,기준정보!$C$7),VALUE(LEFT($J6,FIND("월",$J6)-1)),1+7*(VALUE(SUBSTITUTE(MID($J6,FIND("월",$J6)+1,5),"주",""))-1)),"")) | L6: =IF($K6="","",IF(AND($K6-기준정보!$C$5>=기준정보!$C$10,$K6-기준정보!$C$5<=기준정보!$C$11),기준정보!$C$10-1,$K6-기준정보!$C$5)) | M6: =IF($L6="","",IF(OR(ISNUMBER(SEARCH("중국",$W6)),ISNUMBER(SEARCH("베트남",$W6))),MAX(0,MIN($L6,기준정보!$C$9)-MAX($L6-기준정보!$C$6,기준정보!$C$8)+1),IF(ISNUMBER(SEARCH("한국",$W6)),MAX(0,MIN($L6,기준정보!$C$11)-MAX($L6-기준정보!$C$6,기준정보!$C$10)+1),0))) | N6: =IF($L6="","",$L6-기준정보!$C$6-$M6) | O6: =IF($N6="","",$N6-기준정보!$C$4) | Q6: O | R6: =IF(COUNTIF(EDW_RAW!$A$2:$A$1500,$D6)=0,"",IF(COUNTIFS(EDW_RAW!$A$2:$A$1500,$D6,EDW_RAW!$U$2:$U$1500,"<>~",EDW_RAW!$U$2:$U$1500,"<>")=COUNTIF(EDW_RAW!$A$2:$A$1500,$D6),"O",IF(COUNTIFS(EDW_RAW!$A$2:$A$1500,$D6,EDW_RAW!$U$2:$U$1500,"<>~",EDW_RAW!$U$2:$U$1500,"<>")>0,"부분","X"))) | T6: =IF($H6="","",IF(AND(ISNUMBER(SEARCH("CMT",$H6)),OR(ISNUMBER(SEARCH("완사입",$H6)),ISNUMBER(SEARCH("ODM",$H6)))),"본사/생산처 혼재",IF(ISNUMBER(SEARCH("CMT",$H6)),"본사(소재팀)","생산처"))) | U6: 원전 | V6: =IFERROR(TEXTJOIN(" / ",TRUE,UNIQUE(FILTER(소재DB_RAW!$K$3:$K$2000,(소재DB_RAW!$G$3:$G$2000=$D6)*ISERROR(SEARCH("drop",소재DB_RAW!$C$3:$C$2000))))),"") | W6: 인도네시아 | X6: =IFERROR(TEXTJOIN(" / ",TRUE,UNIQUE(FILTER(소재DB_RAW!$N$3:$N$2000,(소재DB_RAW!$G$3:$G$2000=$D6)*ISERROR(SEARCH("drop",소재DB_RAW!$C$3:$C$2000))))),"") | Y6: =IFERROR(TEXTJOIN(CHAR(10),TRUE,UNIQUE(FILTER(소재DB_RAW!$N$3:$N$2000&") "&소재DB_RAW!$O$3:$O$2000,(소재DB_RAW!$G$3:$G$2000=$D6)*ISNUMBER(SEARCH("겉감",소재DB_RAW!$M$3:$M$2000))*ISERROR(SEARCH("drop",소재DB_RAW!$C$3:$C$2000))))),"") | Z6: =IFERROR(TEXTJOIN(CHAR(10),TRUE,UNIQUE(FILTER(소재DB_RAW!$N$3:$N$2000&") "&소재DB_RAW!$O$3:$O$2000,(소재DB_RAW!$G$3:$G$2000=$D6)*ISNUMBER(SEARCH("안감",소재DB_RAW!$M$3:$M$2000))*ISERROR(SEARCH("drop",소재DB_RAW!$C$3:$C$2000))))),"") | AA6: 550 | AB6: 46312750 | AC6: 214500000 | AE6: =IF($K6="","출고일 미정",IF($Q6="X","작지 미발행",IF($Q6="부분","작지 일부 미발행",IF(AND($S6<>"",$S6>$N6),"소재입고 마감("&TEXT($N6,"MM/DD")&") 초과",IF($Q6="","발행여부 확인 필요",IF($S6="","소재 입고일정 확인 필요","정상")))))) | AF6: =IF($K6="","",IF(OR(LEFT($AE6,2)="작지",LEFT($AE6,4)="소재입고"),IF(LEFT($G6,1)="S","★ 납기위험(S코드)","◆ 지연주의"),IF($AE6="정상","✓ 정상","? 확인필요")))
A7: 3 | B7: 최진민 | C7: 강기환 | D7: JKJJS27016 | E7: 히어로 여성 프리마로프트 LIGHT 인슐레이션 재킷 | F7: LPI-2, BLK(BLACK) | G7: =IF($D7="","",IF(MID($D7,5,1)="S","S(봄)",IF(MID($D7,5,1)="M","M(여름)",IF(MID($D7,5,1)="X","X(사계절)",MID($D7,5,1))))) | H7: 완사입 | I7: S1 | J7: 1월2주 | K7: =IF($J7="","",IFERROR(DATE(IF(VALUE(LEFT($J7,FIND("월",$J7)-1))>=9,기준정보!$C$7-1,기준정보!$C$7),VALUE(LEFT($J7,FIND("월",$J7)-1)),1+7*(VALUE(SUBSTITUTE(MID($J7,FIND("월",$J7)+1,5),"주",""))-1)),"")) | L7: =IF($K7="","",IF(AND($K7-기준정보!$C$5>=기준정보!$C$10,$K7-기준정보!$C$5<=기준정보!$C$11),기준정보!$C$10-1,$K7-기준정보!$C$5)) | M7: =IF($L7="","",IF(OR(ISNUMBER(SEARCH("중국",$W7)),ISNUMBER(SEARCH("베트남",$W7))),MAX(0,MIN($L7,기준정보!$C$9)-MAX($L7-기준정보!$C$6,기준정보!$C$8)+1),IF(ISNUMBER(SEARCH("한국",$W7)),MAX(0,MIN($L7,기준정보!$C$11)-MAX($L7-기준정보!$C$6,기준정보!$C$10)+1),0))) | N7: =IF($L7="","",$L7-기준정보!$C$6-$M7) | O7: =IF($N7="","",$N7-기준정보!$C$4) | Q7: O | R7: =IF(COUNTIF(EDW_RAW!$A$2:$A$1500,$D7)=0,"",IF(COUNTIFS(EDW_RAW!$A$2:$A$1500,$D7,EDW_RAW!$U$2:$U$1500,"<>~",EDW_RAW!$U$2:$U$1500,"<>")=COUNTIF(EDW_RAW!$A$2:$A$1500,$D7),"O",IF(COUNTIFS(EDW_RAW!$A$2:$A$1500,$D7,EDW_RAW!$U$2:$U$1500,"<>~",EDW_RAW!$U$2:$U$1500,"<>")>0,"부분","X"))) | T7: =IF($H7="","",IF(AND(ISNUMBER(SEARCH("CMT",$H7)),OR(ISNUMBER(SEARCH("완사입",$H7)),ISNUMBER(SEARCH("ODM",$H7)))),"본사/생산처 혼재",IF(ISNUMBER(SEARCH("CMT",$H7)),"본사(소재팀)","생산처"))) | U7: 원전 | V7: =IFERROR(TEXTJOIN(" / ",TRUE,UNIQUE(FILTER(소재DB_RAW!$K$3:$K$2000,(소재DB_RAW!$G$3:$G$2000=$D7)*ISERROR(SEARCH("drop",소재DB_RAW!$C$3:$C$2000))))),"") | W7: 인도네시아 | X7: =IFERROR(TEXTJOIN(" / ",TRUE,UNIQUE(FILTER(소재DB_RAW!$N$3:$N$2000,(소재DB_RAW!$G$3:$G$2000=$D7)*ISERROR(SEARCH("drop",소재DB_RAW!$C$3:$C$2000))))),"") | Y7: =IFERROR(TEXTJOIN(CHAR(10),TRUE,UNIQUE(FILTER(소재DB_RAW!$N$3:$N$2000&") "&소재DB_RAW!$O$3:$O$2000,(소재DB_RAW!$G$3:$G$2000=$D7)*ISNUMBER(SEARCH("겉감",소재DB_RAW!$M$3:$M$2000))*ISERROR(SEARCH("drop",소재DB_RAW!$C$3:$C$2000))))),"") | Z7: =IFERROR(TEXTJOIN(CHAR(10),TRUE,UNIQUE(FILTER(소재DB_RAW!$N$3:$N$2000&") "&소재DB_RAW!$O$3:$O$2000,(소재DB_RAW!$G$3:$G$2000=$D7)*ISNUMBER(SEARCH("안감",소재DB_RAW!$M$3:$M$2000))*ISERROR(SEARCH("drop",소재DB_RAW!$C$3:$C$2000))))),"") | AA7: 600 | AB7: 46083000 | AC7: 210000000 | AE7: =IF($K7="","출고일 미정",IF($Q7="X","작지 미발행",IF($Q7="부분","작지 일부 미발행",IF(AND($S7<>"",$S7>$N7),"소재입고 마감("&TEXT($N7,"MM/DD")&") 초과",IF($Q7="","발행여부 확인 필요",IF($S7="","소재 입고일정 확인 필요","정상")))))) | AF7: =IF($K7="","",IF(OR(LEFT($AE7,2)="작지",LEFT($AE7,4)="소재입고"),IF(LEFT($G7,1)="S","★ 납기위험(S코드)","◆ 지연주의"),IF($AE7="정상","✓ 정상","? 확인필요")))
A8: 4 | B8: 최진민 | C8: 김지원 | D8: JKJJS27022 | E8: 히어로 여성 스톰플리스 프로 LIGHT 소프트쉘 재킷 | F8: LGY(L/GRAY), BLK(BLACK) | G8: =IF($D8="","",IF(MID($D8,5,1)="S","S(봄)",IF(MID($D8,5,1)="M","M(여름)",IF(MID($D8,5,1)="X","X(사계절)",MID($D8,5,1))))) | H8: 완사입 | I8: S1 | J8: 1월2주 | K8: =IF($J8="","",IFERROR(DATE(IF(VALUE(LEFT($J8,FIND("월",$J8)-1))>=9,기준정보!$C$7-1,기준정보!$C$7),VALUE(LEFT($J8,FIND("월",$J8)-1)),1+7*(VALUE(SUBSTITUTE(MID($J8,FIND("월",$J8)+1,5),"주",""))-1)),"")) | L8: =IF($K8="","",IF(AND($K8-기준정보!$C$5>=기준정보!$C$10,$K8-기준정보!$C$5<=기준정보!$C$11),기준정보!$C$10-1,$K8-기준정보!$C$5)) | M8: =IF($L8="","",IF(OR(ISNUMBER(SEARCH("중국",$W8)),ISNUMBER(SEARCH("베트남",$W8))),MAX(0,MIN($L8,기준정보!$C$9)-MAX($L8-기준정보!$C$6,기준정보!$C$8)+1),IF(ISNUMBER(SEARCH("한국",$W8)),MAX(0,MIN($L8,기준정보!$C$11)-MAX($L8-기준정보!$C$6,기준정보!$C$10)+1),0))) | N8: =IF($L8="","",$L8-기준정보!$C$6-$M8) | O8: =IF($N8="","",$N8-기준정보!$C$4) | Q8: O | R8: =IF(COUNTIF(EDW_RAW!$A$2:$A$1500,$D8)=0,"",IF(COUNTIFS(EDW_RAW!$A$2:$A$1500,$D8,EDW_RAW!$U$2:$U$1500,"<>~",EDW_RAW!$U$2:$U$1500,"<>")=COUNTIF(EDW_RAW!$A$2:$A$1500,$D8),"O",IF(COUNTIFS(EDW_RAW!$A$2:$A$1500,$D8,EDW_RAW!$U$2:$U$1500,"<>~",EDW_RAW!$U$2:$U$1500,"<>")>0,"부분","X"))) | T8: =IF($H8="","",IF(AND(ISNUMBER(SEARCH("CMT",$H8)),OR(ISNUMBER(SEARCH("완사입",$H8)),ISNUMBER(SEARCH("ODM",$H8)))),"본사/생산처 혼재",IF(ISNUMBER(SEARCH("CMT",$H8)),"본사(소재팀)","생산처"))) | U8: 원전 | V8: =IFERROR(TEXTJOIN(" / ",TRUE,UNIQUE(FILTER(소재DB_RAW!$K$3:$K$2000,(소재DB_RAW!$G$3:$G$2000=$D8)*ISERROR(SEARCH("drop",소재DB_RAW!$C$3:$C$2000))))),"") | W8: 인도네시아 | X8: =IFERROR(TEXTJOIN(" / ",TRUE,UNIQUE(FILTER(소재DB_RAW!$N$3:$N$2000,(소재DB_RAW!$G$3:$G$2000=$D8)*ISERROR(SEARCH("drop",소재DB_RAW!$C$3:$C$2000))))),"") | Y8: =IFERROR(TEXTJOIN(CHAR(10),TRUE,UNIQUE(FILTER(소재DB_RAW!$N$3:$N$2000&") "&소재DB_RAW!$O$3:$O$2000,(소재DB_RAW!$G$3:$G$2000=$D8)*ISNUMBER(SEARCH("겉감",소재DB_RAW!$M$3:$M$2000))*ISERROR(SEARCH("drop",소재DB_RAW!$C$3:$C$2000))))),"") | Z8: =IFERROR(TEXTJOIN(CHAR(10),TRUE,UNIQUE(FILTER(소재DB_RAW!$N$3:$N$2000&") "&소재DB_RAW!$O$3:$O$2000,(소재DB_RAW!$G$3:$G$2000=$D8)*ISNUMBER(SEARCH("안감",소재DB_RAW!$M$3:$M$2000))*ISERROR(SEARCH("drop",소재DB_RAW!$C$3:$C$2000))))),"") | AA8: 400 | AB8: 24726400 | AC8: 128000000 | AE8: =IF($K8="","출고일 미정",IF($Q8="X","작지 미발행",IF($Q8="부분","작지 일부 미발행",IF(AND($S8<>"",$S8>$N8),"소재입고 마감("&TEXT($N8,"MM/DD")&") 초과",IF($Q8="","발행여부 확인 필요",IF($S8="","소재 입고일정 확인 필요","정상")))))) | AF8: =IF($K8="","",IF(OR(LEFT($AE8,2)="작지",LEFT($AE8,4)="소재입고"),IF(LEFT($G8,1)="S","★ 납기위험(S코드)","◆ 지연주의"),IF($AE8="정상","✓ 정상","? 확인필요")))
A9: 5 | B9: 최진민 | C9: 김지원 | D9: JKPNS27062 | E9: 히어로 여성 스톰플리스 프로 LIGHT 소프트쉘 팬츠 | F9: GRY(GRAY), BLK(BLACK) | G9: =IF($D9="","",IF(MID($D9,5,1)="S","S(봄)",IF(MID($D9,5,1)="M","M(여름)",IF(MID($D9,5,1)="X","X(사계절)",MID($D9,5,1))))) | H9: 완사입 | I9: S1 | J9: 1월2주 | K9: =IF($J9="","",IFERROR(DATE(IF(VALUE(LEFT($J9,FIND("월",$J9)-1))>=9,기준정보!$C$7-1,기준정보!$C$7),VALUE(LEFT($J9,FIND("월",$J9)-1)),1+7*(VALUE(SUBSTITUTE(MID($J9,FIND("월",$J9)+1,5),"주",""))-1)),"")) | L9: =IF($K9="","",IF(AND($K9-기준정보!$C$5>=기준정보!$C$10,$K9-기준정보!$C$5<=기준정보!$C$11),기준정보!$C$10-1,$K9-기준정보!$C$5)) | M9: =IF($L9="","",IF(OR(ISNUMBER(SEARCH("중국",$W9)),ISNUMBER(SEARCH("베트남",$W9))),MAX(0,MIN($L9,기준정보!$C$9)-MAX($L9-기준정보!$C$6,기준정보!$C$8)+1),IF(ISNUMBER(SEARCH("한국",$W9)),MAX(0,MIN($L9,기준정보!$C$11)-MAX($L9-기준정보!$C$6,기준정보!$C$10)+1),0))) | N9: =IF($L9="","",$L9-기준정보!$C$6-$M9) | O9: =IF($N9="","",$N9-기준정보!$C$4) | Q9: O | R9: =IF(COUNTIF(EDW_RAW!$A$2:$A$1500,$D9)=0,"",IF(COUNTIFS(EDW_RAW!$A$2:$A$1500,$D9,EDW_RAW!$U$2:$U$1500,"<>~",EDW_RAW!$U$2:$U$1500,"<>")=COUNTIF(EDW_RAW!$A$2:$A$1500,$D9),"O",IF(COUNTIFS(EDW_RAW!$A$2:$A$1500,$D9,EDW_RAW!$U$2:$U$1500,"<>~",EDW_RAW!$U$2:$U$1500,"<>")>0,"부분","X"))) | T9: =IF($H9="","",IF(AND(ISNUMBER(SEARCH("CMT",$H9)),OR(ISNUMBER(SEARCH("완사입",$H9)),ISNUMBER(SEARCH("ODM",$H9)))),"본사/생산처 혼재",IF(ISNUMBER(SEARCH("CMT",$H9)),"본사(소재팀)","생산처"))) | U9: 거림 | V9: =IFERROR(TEXTJOIN(" / ",TRUE,UNIQUE(FILTER(소재DB_RAW!$K$3:$K$2000,(소재DB_RAW!$G$3:$G$2000=$D9)*ISERROR(SEARCH("drop",소재DB_RAW!$C$3:$C$2000))))),"") | W9: 베트남 | X9: =IFERROR(TEXTJOIN(" / ",TRUE,UNIQUE(FILTER(소재DB_RAW!$N$3:$N$2000,(소재DB_RAW!$G$3:$G$2000=$D9)*ISERROR(SEARCH("drop",소재DB_RAW!$C$3:$C$2000))))),"") | Y9: =IFERROR(TEXTJOIN(CHAR(10),TRUE,UNIQUE(FILTER(소재DB_RAW!$N$3:$N$2000&") "&소재DB_RAW!$O$3:$O$2000,(소재DB_RAW!$G$3:$G$2000=$D9)*ISNUMBER(SEARCH("겉감",소재DB_RAW!$M$3:$M$2000))*ISERROR(SEARCH("drop",소재DB_RAW!$C$3:$C$2000))))),"") | Z9: =IFERROR(TEXTJOIN(CHAR(10),TRUE,UNIQUE(FILTER(소재DB_RAW!$N$3:$N$2000&") "&소재DB_RAW!$O$3:$O$2000,(소재DB_RAW!$G$3:$G$2000=$D9)*ISNUMBER(SEARCH("안감",소재DB_RAW!$M$3:$M$2000))*ISERROR(SEARCH("drop",소재DB_RAW!$C$3:$C$2000))))),"") | AA9: 350 | AB9: 20101900 | AC9: 94500000 | AE9: =IF($K9="","출고일 미정",IF($Q9="X","작지 미발행",IF($Q9="부분","작지 일부 미발행",IF(AND($S9<>"",$S9>$N9),"소재입고 마감("&TEXT($N9,"MM/DD")&") 초과",IF($Q9="","발행여부 확인 필요",IF($S9="","소재 입고일정 확인 필요","정상")))))) | AF9: =IF($K9="","",IF(OR(LEFT($AE9,2)="작지",LEFT($AE9,4)="소재입고"),IF(LEFT($G9,1)="S","★ 납기위험(S코드)","◆ 지연주의"),IF($AE9="정상","✓ 정상","? 확인필요")))
A10: 6 | B10: 최진민 | C10: 김지원 | D10: JKPNS27072 | E10: 히어로 여성 클라이밍 팬츠 | F10: GRY-1, BLK(BLACK) | G10: =IF($D10="","",IF(MID($D10,5,1)="S","S(봄)",IF(MID($D10,5,1)="M","M(여름)",IF(MID($D10,5,1)="X","X(사계절)",MID($D10,5,1))))) | H10: 완사입 | I10: S1 | J10: 1월2주 | K10: =IF($J10="","",IFERROR(DATE(IF(VALUE(LEFT($J10,FIND("월",$J10)-1))>=9,기준정보!$C$7-1,기준정보!$C$7),VALUE(LEFT($J10,FIND("월",$J10)-1)),1+7*(VALUE(SUBSTITUTE(MID($J10,FIND("월",$J10)+1,5),"주",""))-1)),"")) | L10: =IF($K10="","",IF(AND($K10-기준정보!$C$5>=기준정보!$C$10,$K10-기준정보!$C$5<=기준정보!$C$11),기준정보!$C$10-1,$K10-기준정보!$C$5)) | M10: =IF($L10="","",IF(OR(ISNUMBER(SEARCH("중국",$W10)),ISNUMBER(SEARCH("베트남",$W10))),MAX(0,MIN($L10,기준정보!$C$9)-MAX($L10-기준정보!$C$6,기준정보!$C$8)+1),IF(ISNUMBER(SEARCH("한국",$W10)),MAX(0,MIN($L10,기준정보!$C$11)-MAX($L10-기준정보!$C$6,기준정보!$C$10)+1),0))) | N10: =IF($L10="","",$L10-기준정보!$C$6-$M10) | O10: =IF($N10="","",$N10-기준정보!$C$4) | Q10: O | R10: =IF(COUNTIF(EDW_RAW!$A$2:$A$1500,$D10)=0,"",IF(COUNTIFS(EDW_RAW!$A$2:$A$1500,$D10,EDW_RAW!$U$2:$U$1500,"<>~",EDW_RAW!$U$2:$U$1500,"<>")=COUNTIF(EDW_RAW!$A$2:$A$1500,$D10),"O",IF(COUNTIFS(EDW_RAW!$A$2:$A$1500,$D10,EDW_RAW!$U$2:$U$1500,"<>~",EDW_RAW!$U$2:$U$1500,"<>")>0,"부분","X"))) | T10: =IF($H10="","",IF(AND(ISNUMBER(SEARCH("CMT",$H10)),OR(ISNUMBER(SEARCH("완사입",$H10)),ISNUMBER(SEARCH("ODM",$H10)))),"본사/생산처 혼재",IF(ISNUMBER(SEARCH("CMT",$H10)),"본사(소재팀)","생산처"))) | U10: 거림 | V10: =IFERROR(TEXTJOIN(" / ",TRUE,UNIQUE(FILTER(소재DB_RAW!$K$3:$K$2000,(소재DB_RAW!$G$3:$G$2000=$D10)*ISERROR(SEARCH("drop",소재DB_RAW!$C$3:$C$2000))))),"") | W10: 베트남 | X10: =IFERROR(TEXTJOIN(" / ",TRUE,UNIQUE(FILTER(소재DB_RAW!$N$3:$N$2000,(소재DB_RAW!$G$3:$G$2000=$D10)*ISERROR(SEARCH("drop",소재DB_RAW!$C$3:$C$2000))))),"") | Y10: =IFERROR(TEXTJOIN(CHAR(10),TRUE,UNIQUE(FILTER(소재DB_RAW!$N$3:$N$2000&") "&소재DB_RAW!$O$3:$O$2000,(소재DB_RAW!$G$3:$G$2000=$D10)*ISNUMBER(SEARCH("겉감",소재DB_RAW!$M$3:$M$2000))*ISERROR(SEARCH("drop",소재DB_RAW!$C$3:$C$2000))))),"") | Z10: =IFERROR(TEXTJOIN(CHAR(10),TRUE,UNIQUE(FILTER(소재DB_RAW!$N$3:$N$2000&") "&소재DB_RAW!$O$3:$O$2000,(소재DB_RAW!$G$3:$G$2000=$D10)*ISNUMBER(SEARCH("안감",소재DB_RAW!$M$3:$M$2000))*ISERROR(SEARCH("drop",소재DB_RAW!$C$3:$C$2000))))),"") | AA10: 200 | AB10: 16675200 | AC10: 64000000 | AE10: =IF($K10="","출고일 미정",IF($Q10="X","작지 미발행",IF($Q10="부분","작지 일부 미발행",IF(AND($S10<>"",$S10>$N10),"소재입고 마감("&TEXT($N10,"MM/DD")&") 초과",IF($Q10="","발행여부 확인 필요",IF($S10="","소재 입고일정 확인 필요","정상")))))) | AF10: =IF($K10="","",IF(OR(LEFT($AE10,2)="작지",LEFT($AE10,4)="소재입고"),IF(LEFT($G10,1)="S","★ 납기위험(S코드)","◆ 지연주의"),IF($AE10="정상","✓ 정상","? 확인필요")))
A11: 7 | B11: 최진민 | C11: 김지원 | D11: JKTBS27058 | E11: 히어로 여성 니트도트 긴팔 라운드티 | F11: DGY-1, BLK(BLACK) | G11: =IF($D11="","",IF(MID($D11,5,1)="S","S(봄)",IF(MID($D11,5,1)="M","M(여름)",IF(MID($D11,5,1)="X","X(사계절)",MID($D11,5,1))))) | H11: 완사입 | I11: S1 | J11: 1월2주 | K11: =IF($J11="","",IFERROR(DATE(IF(VALUE(LEFT($J11,FIND("월",$J11)-1))>=9,기준정보!$C$7-1,기준정보!$C$7),VALUE(LEFT($J11,FIND("월",$J11)-1)),1+7*(VALUE(SUBSTITUTE(MID($J11,FIND("월",$J11)+1,5),"주",""))-1)),"")) | L11: =IF($K11="","",IF(AND($K11-기준정보!$C$5>=기준정보!$C$10,$K11-기준정보!$C$5<=기준정보!$C$11),기준정보!$C$10-1,$K11-기준정보!$C$5)) | M11: =IF($L11="","",IF(OR(ISNUMBER(SEARCH("중국",$W11)),ISNUMBER(SEARCH("베트남",$W11))),MAX(0,MIN($L11,기준정보!$C$9)-MAX($L11-기준정보!$C$6,기준정보!$C$8)+1),IF(ISNUMBER(SEARCH("한국",$W11)),MAX(0,MIN($L11,기준정보!$C$11)-MAX($L11-기준정보!$C$6,기준정보!$C$10)+1),0))) | N11: =IF($L11="","",$L11-기준정보!$C$6-$M11) | O11: =IF($N11="","",$N11-기준정보!$C$4) | Q11: O | R11: =IF(COUNTIF(EDW_RAW!$A$2:$A$1500,$D11)=0,"",IF(COUNTIFS(EDW_RAW!$A$2:$A$1500,$D11,EDW_RAW!$U$2:$U$1500,"<>~",EDW_RAW!$U$2:$U$1500,"<>")=COUNTIF(EDW_RAW!$A$2:$A$1500,$D11),"O",IF(COUNTIFS(EDW_RAW!$A$2:$A$1500,$D11,EDW_RAW!$U$2:$U$1500,"<>~",EDW_RAW!$U$2:$U$1500,"<>")>0,"부분","X"))) | T11: =IF($H11="","",IF(AND(ISNUMBER(SEARCH("CMT",$H11)),OR(ISNUMBER(SEARCH("완사입",$H11)),ISNUMBER(SEARCH("ODM",$H11)))),"본사/생산처 혼재",IF(ISNUMBER(SEARCH("CMT",$H11)),"본사(소재팀)","생산처"))) | U11: 태화 | V11: =IFERROR(TEXTJOIN(" / ",TRUE,UNIQUE(FILTER(소재DB_RAW!$K$3:$K$2000,(소재DB_RAW!$G$3:$G$2000=$D11)*ISERROR(SEARCH("drop",소재DB_RAW!$C$3:$C$2000))))),"") | W11: 베트남 | X11: =IFERROR(TEXTJOIN(" / ",TRUE,UNIQUE(FILTER(소재DB_RAW!$N$3:$N$2000,(소재DB_RAW!$G$3:$G$2000=$D11)*ISERROR(SEARCH("drop",소재DB_RAW!$C$3:$C$2000))))),"") | Y11: =IFERROR(TEXTJOIN(CHAR(10),TRUE,UNIQUE(FILTER(소재DB_RAW!$N$3:$N$2000&") "&소재DB_RAW!$O$3:$O$2000,(소재DB_RAW!$G$3:$G$2000=$D11)*ISNUMBER(SEARCH("겉감",소재DB_RAW!$M$3:$M$2000))*ISERROR(SEARCH("drop",소재DB_RAW!$C$3:$C$2000))))),"") | Z11: =IFERROR(TEXTJOIN(CHAR(10),TRUE,UNIQUE(FILTER(소재DB_RAW!$N$3:$N$2000&") "&소재DB_RAW!$O$3:$O$2000,(소재DB_RAW!$G$3:$G$2000=$D11)*ISNUMBER(SEARCH("안감",소재DB_RAW!$M$3:$M$2000))*ISERROR(SEARCH("drop",소재DB_RAW!$C$3:$C$2000))))),"") | AA11: 180 | AB11: 4716720 | AC11: 24840000 | AE11: =IF($K11="","출고일 미정",IF($Q11="X","작지 미발행",IF($Q11="부분","작지 일부 미발행",IF(AND($S11<>"",$S11>$N11),"소재입고 마감("&TEXT($N11,"MM/DD")&") 초과",IF($Q11="","발행여부 확인 필요",IF($S11="","소재 입고일정 확인 필요","정상")))))) | AF11: =IF($K11="","",IF(OR(LEFT($AE11,2)="작지",LEFT($AE11,4)="소재입고"),IF(LEFT($G11,1)="S","★ 납기위험(S코드)","◆ 지연주의"),IF($AE11="정상","✓ 정상","? 확인필요")))
A12: 8 | B12: 최진민 | C12: 강기환 | D12: JWJGS27001 | E12: 히어로 남성 고어텍스 3L PRO 재킷 | F12: GBU(G/BLUE), DGY-1 | G12: =IF($D12="","",IF(MID($D12,5,1)="S","S(봄)",IF(MID($D12,5,1)="M","M(여름)",IF(MID($D12,5,1)="X","X(사계절)",MID($D12,5,1))))) | H12: 완사입 | I12: S1 | J12: 1월2주 | K12: =IF($J12="","",IFERROR(DATE(IF(VALUE(LEFT($J12,FIND("월",$J12)-1))>=9,기준정보!$C$7-1,기준정보!$C$7),VALUE(LEFT($J12,FIND("월",$J12)-1)),1+7*(VALUE(SUBSTITUTE(MID($J12,FIND("월",$J12)+1,5),"주",""))-1)),"")) | L12: =IF($K12="","",IF(AND($K12-기준정보!$C$5>=기준정보!$C$10,$K12-기준정보!$C$5<=기준정보!$C$11),기준정보!$C$10-1,$K12-기준정보!$C$5)) | M12: =IF($L12="","",IF(OR(ISNUMBER(SEARCH("중국",$W12)),ISNUMBER(SEARCH("베트남",$W12))),MAX(0,MIN($L12,기준정보!$C$9)-MAX($L12-기준정보!$C$6,기준정보!$C$8)+1),IF(ISNUMBER(SEARCH("한국",$W12)),MAX(0,MIN($L12,기준정보!$C$11)-MAX($L12-기준정보!$C$6,기준정보!$C$10)+1),0))) | N12: =IF($L12="","",$L12-기준정보!$C$6-$M12) | O12: =IF($N12="","",$N12-기준정보!$C$4) | Q12: O | R12: =IF(COUNTIF(EDW_RAW!$A$2:$A$1500,$D12)=0,"",IF(COUNTIFS(EDW_RAW!$A$2:$A$1500,$D12,EDW_RAW!$U$2:$U$1500,"<>~",EDW_RAW!$U$2:$U$1500,"<>")=COUNTIF(EDW_RAW!$A$2:$A$1500,$D12),"O",IF(COUNTIFS(EDW_RAW!$A$2:$A$1500,$D12,EDW_RAW!$U$2:$U$1500,"<>~",EDW_RAW!$U$2:$U$1500,"<>")>0,"부분","X"))) | T12: =IF($H12="","",IF(AND(ISNUMBER(SEARCH("CMT",$H12)),OR(ISNUMBER(SEARCH("완사입",$H12)),ISNUMBER(SEARCH("ODM",$H12)))),"본사/생산처 혼재",IF(ISNUMBER(SEARCH("CMT",$H12)),"본사(소재팀)","생산처"))) | U12: 포마트 | V12: =IFERROR(TEXTJOIN(" / ",TRUE,UNIQUE(FILTER(소재DB_RAW!$K$3:$K$2000,(소재DB_RAW!$G$3:$G$2000=$D12)*ISERROR(SEARCH("drop",소재DB_RAW!$C$3:$C$2000))))),"") | W12: 베트남 | X12: =IFERROR(TEXTJOIN(" / ",TRUE,UNIQUE(FILTER(소재DB_RAW!$N$3:$N$2000,(소재DB_RAW!$G$3:$G$2000=$D12)*ISERROR(SEARCH("drop",소재DB_RAW!$C$3:$C$2000))))),"") | Y12: =IFERROR(TEXTJOIN(CHAR(10),TRUE,UNIQUE(FILTER(소재DB_RAW!$N$3:$N$2000&") "&소재DB_RAW!$O$3:$O$2000,(소재DB_RAW!$G$3:$G$2000=$D12)*ISNUMBER(SEARCH("겉감",소재DB_RAW!$M$3:$M$2000))*ISERROR(SEARCH("drop",소재DB_RAW!$C$3:$C$2000))))),"") | Z12: =IFERROR(TEXTJOIN(CHAR(10),TRUE,UNIQUE(FILTER(소재DB_RAW!$N$3:$N$2000&") "&소재DB_RAW!$O$3:$O$2000,(소재DB_RAW!$G$3:$G$2000=$D12)*ISNUMBER(SEARCH("안감",소재DB_RAW!$M$3:$M$2000))*ISERROR(SEARCH("drop",소재DB_RAW!$C$3:$C$2000))))),"") | AA12: 250 | AB12: 68675250 | AC12: 247500000 | AE12: =IF($K12="","출고일 미정",IF($Q12="X","작지 미발행",IF($Q12="부분","작지 일부 미발행",IF(AND($S12<>"",$S12>$N12),"소재입고 마감("&TEXT($N12,"MM/DD")&") 초과",IF($Q12="","발행여부 확인 필요",IF($S12="","소재 입고일정 확인 필요","정상")))))) | AF12: =IF($K12="","",IF(OR(LEFT($AE12,2)="작지",LEFT($AE12,4)="소재입고"),IF(LEFT($G12,1)="S","★ 납기위험(S코드)","◆ 지연주의"),IF($AE12="정상","✓ 정상","? 확인필요")))
A13: 9 | B13: 최진민 | C13: 강기환 | D13: JWJJS27011 | E13: 히어로 남성 프리마로프트 HEAVY 인슐레이션 재킷 | F13: GRY-1, BLK(BLACK) | G13: =IF($D13="","",IF(MID($D13,5,1)="S","S(봄)",IF(MID($D13,5,1)="M","M(여름)",IF(MID($D13,5,1)="X","X(사계절)",MID($D13,5,1))))) | H13: 완사입 | I13: S1 | J13: 1월2주 | K13: =IF($J13="","",IFERROR(DATE(IF(VALUE(LEFT($J13,FIND("월",$J13)-1))>=9,기준정보!$C$7-1,기준정보!$C$7),VALUE(LEFT($J13,FIND("월",$J13)-1)),1+7*(VALUE(SUBSTITUTE(MID($J13,FIND("월",$J13)+1,5),"주",""))-1)),"")) | L13: =IF($K13="","",IF(AND($K13-기준정보!$C$5>=기준정보!$C$10,$K13-기준정보!$C$5<=기준정보!$C$11),기준정보!$C$10-1,$K13-기준정보!$C$5)) | M13: =IF($L13="","",IF(OR(ISNUMBER(SEARCH("중국",$W13)),ISNUMBER(SEARCH("베트남",$W13))),MAX(0,MIN($L13,기준정보!$C$9)-MAX($L13-기준정보!$C$6,기준정보!$C$8)+1),IF(ISNUMBER(SEARCH("한국",$W13)),MAX(0,MIN($L13,기준정보!$C$11)-MAX($L13-기준정보!$C$6,기준정보!$C$10)+1),0))) | N13: =IF($L13="","",$L13-기준정보!$C$6-$M13) | O13: =IF($N13="","",$N13-기준정보!$C$4) | Q13: O | R13: =IF(COUNTIF(EDW_RAW!$A$2:$A$1500,$D13)=0,"",IF(COUNTIFS(EDW_RAW!$A$2:$A$1500,$D13,EDW_RAW!$U$2:$U$1500,"<>~",EDW_RAW!$U$2:$U$1500,"<>")=COUNTIF(EDW_RAW!$A$2:$A$1500,$D13),"O",IF(COUNTIFS(EDW_RAW!$A$2:$A$1500,$D13,EDW_RAW!$U$2:$U$1500,"<>~",EDW_RAW!$U$2:$U$1500,"<>")>0,"부분","X"))) | T13: =IF($H13="","",IF(AND(ISNUMBER(SEARCH("CMT",$H13)),OR(ISNUMBER(SEARCH("완사입",$H13)),ISNUMBER(SEARCH("ODM",$H13)))),"본사/생산처 혼재",IF(ISNUMBER(SEARCH("CMT",$H13)),"본사(소재팀)","생산처"))) | U13: 원전 | V13: =IFERROR(TEXTJOIN(" / ",TRUE,UNIQUE(FILTER(소재DB_RAW!$K$3:$K$2000,(소재DB_RAW!$G$3:$G$2000=$D13)*ISERROR(SEARCH("drop",소재DB_RAW!$C$3:$C$2000))))),"") | W13: 인도네시아 | X13: =IFERROR(TEXTJOIN(" / ",TRUE,UNIQUE(FILTER(소재DB_RAW!$N$3:$N$2000,(소재DB_RAW!$G$3:$G$2000=$D13)*ISERROR(SEARCH("drop",소재DB_RAW!$C$3:$C$2000))))),"") | Y13: =IFERROR(TEXTJOIN(CHAR(10),TRUE,UNIQUE(FILTER(소재DB_RAW!$N$3:$N$2000&") "&소재DB_RAW!$O$3:$O$2000,(소재DB_RAW!$G$3:$G$2000=$D13)*ISNUMBER(SEARCH("겉감",소재DB_RAW!$M$3:$M$2000))*ISERROR(SEARCH("drop",소재DB_RAW!$C$3:$C$2000))))),"") | Z13: =IFERROR(TEXTJOIN(CHAR(10),TRUE,UNIQUE(FILTER(소재DB_RAW!$N$3:$N$2000&") "&소재DB_RAW!$O$3:$O$2000,(소재DB_RAW!$G$3:$G$2000=$D13)*ISNUMBER(SEARCH("안감",소재DB_RAW!$M$3:$M$2000))*ISERROR(SEARCH("drop",소재DB_RAW!$C$3:$C$2000))))),"") | AA13: 2350 | AB13: 215013250 | AC13: 916500000 | AE13: =IF($K13="","출고일 미정",IF($Q13="X","작지 미발행",IF($Q13="부분","작지 일부 미발행",IF(AND($S13<>"",$S13>$N13),"소재입고 마감("&TEXT($N13,"MM/DD")&") 초과",IF($Q13="","발행여부 확인 필요",IF($S13="","소재 입고일정 확인 필요","정상")))))) | AF13: =IF($K13="","",IF(OR(LEFT($AE13,2)="작지",LEFT($AE13,4)="소재입고"),IF(LEFT($G13,1)="S","★ 납기위험(S코드)","◆ 지연주의"),IF($AE13="정상","✓ 정상","? 확인필요")))
A14: 10 | B14: 최진민 | C14: 강기환 | D14: JWJJS27015 | E14: 히어로 남성 프리마로프트 LIGHT 인슐레이션 재킷 | F14: DBU(D/BLUE), BLK(BLACK) | G14: =IF($D14="","",IF(MID($D14,5,1)="S","S(봄)",IF(MID($D14,5,1)="M","M(여름)",IF(MID($D14,5,1)="X","X(사계절)",MID($D14,5,1))))) | H14: 완사입 | I14: S1 | J14: 1월2주 | K14: =IF($J14="","",IFERROR(DATE(IF(VALUE(LEFT($J14,FIND("월",$J14)-1))>=9,기준정보!$C$7-1,기준정보!$C$7),VALUE(LEFT($J14,FIND("월",$J14)-1)),1+7*(VALUE(SUBSTITUTE(MID($J14,FIND("월",$J14)+1,5),"주",""))-1)),"")) | L14: =IF($K14="","",IF(AND($K14-기준정보!$C$5>=기준정보!$C$10,$K14-기준정보!$C$5<=기준정보!$C$11),기준정보!$C$10-1,$K14-기준정보!$C$5)) | M14: =IF($L14="","",IF(OR(ISNUMBER(SEARCH("중국",$W14)),ISNUMBER(SEARCH("베트남",$W14))),MAX(0,MIN($L14,기준정보!$C$9)-MAX($L14-기준정보!$C$6,기준정보!$C$8)+1),IF(ISNUMBER(SEARCH("한국",$W14)),MAX(0,MIN($L14,기준정보!$C$11)-MAX($L14-기준정보!$C$6,기준정보!$C$10)+1),0))) | N14: =IF($L14="","",$L14-기준정보!$C$6-$M14) | O14: =IF($N14="","",$N14-기준정보!$C$4) | Q14: O | R14: =IF(COUNTIF(EDW_RAW!$A$2:$A$1500,$D14)=0,"",IF(COUNTIFS(EDW_RAW!$A$2:$A$1500,$D14,EDW_RAW!$U$2:$U$1500,"<>~",EDW_RAW!$U$2:$U$1500,"<>")=COUNTIF(EDW_RAW!$A$2:$A$1500,$D14),"O",IF(COUNTIFS(EDW_RAW!$A$2:$A$1500,$D14,EDW_RAW!$U$2:$U$1500,"<>~",EDW_RAW!$U$2:$U$1500,"<>")>0,"부분","X"))) | T14: =IF($H14="","",IF(AND(ISNUMBER(SEARCH("CMT",$H14)),OR(ISNUMBER(SEARCH("완사입",$H14)),ISNUMBER(SEARCH("ODM",$H14)))),"본사/생산처 혼재",IF(ISNUMBER(SEARCH("CMT",$H14)),"본사(소재팀)","생산처"))) | U14: 원전 | V14: =IFERROR(TEXTJOIN(" / ",TRUE,UNIQUE(FILTER(소재DB_RAW!$K$3:$K$2000,(소재DB_RAW!$G$3:$G$2000=$D14)*ISERROR(SEARCH("drop",소재DB_RAW!$C$3:$C$2000))))),"") | W14: 인도네시아 | X14: =IFERROR(TEXTJOIN(" / ",TRUE,UNIQUE(FILTER(소재DB_RAW!$N$3:$N$2000,(소재DB_RAW!$G$3:$G$2000=$D14)*ISERROR(SEARCH("drop",소재DB_RAW!$C$3:$C$2000))))),"") | Y14: =IFERROR(TEXTJOIN(CHAR(10),TRUE,UNIQUE(FILTER(소재DB_RAW!$N$3:$N$2000&") "&소재DB_RAW!$O$3:$O$2000,(소재DB_RAW!$G$3:$G$2000=$D14)*ISNUMBER(SEARCH("겉감",소재DB_RAW!$M$3:$M$2000))*ISERROR(SEARCH("drop",소재DB_RAW!$C$3:$C$2000))))),"") | Z14: =IFERROR(TEXTJOIN(CHAR(10),TRUE,UNIQUE(FILTER(소재DB_RAW!$N$3:$N$2000&") "&소재DB_RAW!$O$3:$O$2000,(소재DB_RAW!$G$3:$G$2000=$D14)*ISNUMBER(SEARCH("안감",소재DB_RAW!$M$3:$M$2000))*ISERROR(SEARCH("drop",소재DB_RAW!$C$3:$C$2000))))),"") | AA14: 2250 | AB14: 186752250 | AC14: 787500000 | AE14: =IF($K14="","출고일 미정",IF($Q14="X","작지 미발행",IF($Q14="부분","작지 일부 미발행",IF(AND($S14<>"",$S14>$N14),"소재입고 마감("&TEXT($N14,"MM/DD")&") 초과",IF($Q14="","발행여부 확인 필요",IF($S14="","소재 입고일정 확인 필요","정상")))))) | AF14: =IF($K14="","",IF(OR(LEFT($AE14,2)="작지",LEFT($AE14,4)="소재입고"),IF(LEFT($G14,1)="S","★ 납기위험(S코드)","◆ 지연주의"),IF($AE14="정상","✓ 정상","? 확인필요")))
A15: 11 | B15: 최진민 | C15: 김지원 | D15: JWJJS27021 | E15: 히어로 남성 스톰플리스 프로 LIGHT 소프트쉘 재킷 | F15: DBU(D/BLUE), BLK(BLACK) | G15: =IF($D15="","",IF(MID($D15,5,1)="S","S(봄)",IF(MID($D15,5,1)="M","M(여름)",IF(MID($D15,5,1)="X","X(사계절)",MID($D15,5,1))))) | H15: 완사입 | I15: S1 | J15: 1월2주 | K15: =IF($J15="","",IFERROR(DATE(IF(VALUE(LEFT($J15,FIND("월",$J15)-1))>=9,기준정보!$C$7-1,기준정보!$C$7),VALUE(LEFT($J15,FIND("월",$J15)-1)),1+7*(VALUE(SUBSTITUTE(MID($J15,FIND("월",$J15)+1,5),"주",""))-1)),"")) | L15: =IF($K15="","",IF(AND($K15-기준정보!$C$5>=기준정보!$C$10,$K15-기준정보!$C$5<=기준정보!$C$11),기준정보!$C$10-1,$K15-기준정보!$C$5)) | M15: =IF($L15="","",IF(OR(ISNUMBER(SEARCH("중국",$W15)),ISNUMBER(SEARCH("베트남",$W15))),MAX(0,MIN($L15,기준정보!$C$9)-MAX($L15-기준정보!$C$6,기준정보!$C$8)+1),IF(ISNUMBER(SEARCH("한국",$W15)),MAX(0,MIN($L15,기준정보!$C$11)-MAX($L15-기준정보!$C$6,기준정보!$C$10)+1),0))) | N15: =IF($L15="","",$L15-기준정보!$C$6-$M15) | O15: =IF($N15="","",$N15-기준정보!$C$4) | Q15: O | R15: =IF(COUNTIF(EDW_RAW!$A$2:$A$1500,$D15)=0,"",IF(COUNTIFS(EDW_RAW!$A$2:$A$1500,$D15,EDW_RAW!$U$2:$U$1500,"<>~",EDW_RAW!$U$2:$U$1500,"<>")=COUNTIF(EDW_RAW!$A$2:$A$1500,$D15),"O",IF(COUNTIFS(EDW_RAW!$A$2:$A$1500,$D15,EDW_RAW!$U$2:$U$1500,"<>~",EDW_RAW!$U$2:$U$1500,"<>")>0,"부분","X"))) | T15: =IF($H15="","",IF(AND(ISNUMBER(SEARCH("CMT",$H15)),OR(ISNUMBER(SEARCH("완사입",$H15)),ISNUMBER(SEARCH("ODM",$H15)))),"본사/생산처 혼재",IF(ISNUMBER(SEARCH("CMT",$H15)),"본사(소재팀)","생산처"))) | U15: 원전 | V15: =IFERROR(TEXTJOIN(" / ",TRUE,UNIQUE(FILTER(소재DB_RAW!$K$3:$K$2000,(소재DB_RAW!$G$3:$G$2000=$D15)*ISERROR(SEARCH("drop",소재DB_RAW!$C$3:$C$2000))))),"") | W15: 인도네시아 | X15: =IFERROR(TEXTJOIN(" / ",TRUE,UNIQUE(FILTER(소재DB_RAW!$N$3:$N$2000,(소재DB_RAW!$G$3:$G$2000=$D15)*ISERROR(SEARCH("drop",소재DB_RAW!$C$3:$C$2000))))),"") | Y15: =IFERROR(TEXTJOIN(CHAR(10),TRUE,UNIQUE(FILTER(소재DB_RAW!$N$3:$N$2000&") "&소재DB_RAW!$O$3:$O$2000,(소재DB_RAW!$G$3:$G$2000=$D15)*ISNUMBER(SEARCH("겉감",소재DB_RAW!$M$3:$M$2000))*ISERROR(SEARCH("drop",소재DB_RAW!$C$3:$C$2000))))),"") | Z15: =IFERROR(TEXTJOIN(CHAR(10),TRUE,UNIQUE(FILTER(소재DB_RAW!$N$3:$N$2000&") "&소재DB_RAW!$O$3:$O$2000,(소재DB_RAW!$G$3:$G$2000=$D15)*ISNUMBER(SEARCH("안감",소재DB_RAW!$M$3:$M$2000))*ISERROR(SEARCH("drop",소재DB_RAW!$C$3:$C$2000))))),"") | AA15: 3000 | AB15: 199377000 | AC15: 960000000 | AE15: =IF($K15="","출고일 미정",IF($Q15="X","작지 미발행",IF($Q15="부분","작지 일부 미발행",IF(AND($S15<>"",$S15>$N15),"소재입고 마감("&TEXT($N15,"MM/DD")&") 초과",IF($Q15="","발행여부 확인 필요",IF($S15="","소재 입고일정 확인 필요","정상")))))) | AF15: =IF($K15="","",IF(OR(LEFT($AE15,2)="작지",LEFT($AE15,4)="소재입고"),IF(LEFT($G15,1)="S","★ 납기위험(S코드)","◆ 지연주의"),IF($AE15="정상","✓ 정상","? 확인필요")))
A16: 12 | B16: 최진민 | C16: 김지원 | D16: JWPNS27061 | E16: 히어로 남성 스톰플리스 프로 LIGHT 소프트쉘 팬츠 | F16: GBU(G/BLUE), BLK(BLACK) | G16: =IF($D16="","",IF(MID($D16,5,1)="S","S(봄)",IF(MID($D16,5,1)="M","M(여름)",IF(MID($D16,5,1)="X","X(사계절)",MID($D16,5,1))))) | H16: 완사입 | I16: S1 | J16: 1월2주 | K16: =IF($J16="","",IFERROR(DATE(IF(VALUE(LEFT($J16,FIND("월",$J16)-1))>=9,기준정보!$C$7-1,기준정보!$C$7),VALUE(LEFT($J16,FIND("월",$J16)-1)),1+7*(VALUE(SUBSTITUTE(MID($J16,FIND("월",$J16)+1,5),"주",""))-1)),"")) | L16: =IF($K16="","",IF(AND($K16-기준정보!$C$5>=기준정보!$C$10,$K16-기준정보!$C$5<=기준정보!$C$11),기준정보!$C$10-1,$K16-기준정보!$C$5)) | M16: =IF($L16="","",IF(OR(ISNUMBER(SEARCH("중국",$W16)),ISNUMBER(SEARCH("베트남",$W16))),MAX(0,MIN($L16,기준정보!$C$9)-MAX($L16-기준정보!$C$6,기준정보!$C$8)+1),IF(ISNUMBER(SEARCH("한국",$W16)),MAX(0,MIN($L16,기준정보!$C$11)-MAX($L16-기준정보!$C$6,기준정보!$C$10)+1),0))) | N16: =IF($L16="","",$L16-기준정보!$C$6-$M16) | O16: =IF($N16="","",$N16-기준정보!$C$4) | Q16: O | R16: =IF(COUNTIF(EDW_RAW!$A$2:$A$1500,$D16)=0,"",IF(COUNTIFS(EDW_RAW!$A$2:$A$1500,$D16,EDW_RAW!$U$2:$U$1500,"<>~",EDW_RAW!$U$2:$U$1500,"<>")=COUNTIF(EDW_RAW!$A$2:$A$1500,$D16),"O",IF(COUNTIFS(EDW_RAW!$A$2:$A$1500,$D16,EDW_RAW!$U$2:$U$1500,"<>~",EDW_RAW!$U$2:$U$1500,"<>")>0,"부분","X"))) | T16: =IF($H16="","",IF(AND(ISNUMBER(SEARCH("CMT",$H16)),OR(ISNUMBER(SEARCH("완사입",$H16)),ISNUMBER(SEARCH("ODM",$H16)))),"본사/생산처 혼재",IF(ISNUMBER(SEARCH("CMT",$H16)),"본사(소재팀)","생산처"))) | U16: 거림 | V16: =IFERROR(TEXTJOIN(" / ",TRUE,UNIQUE(FILTER(소재DB_RAW!$K$3:$K$2000,(소재DB_RAW!$G$3:$G$2000=$D16)*ISERROR(SEARCH("drop",소재DB_RAW!$C$3:$C$2000))))),"") | W16: 베트남 | X16: =IFERROR(TEXTJOIN(" / ",TRUE,UNIQUE(FILTER(소재DB_RAW!$N$3:$N$2000,(소재DB_RAW!$G$3:$G$2000=$D16)*ISERROR(SEARCH("drop",소재DB_RAW!$C$3:$C$2000))))),"") | Y16: =IFERROR(TEXTJOIN(CHAR(10),TRUE,UNIQUE(FILTER(소재DB_RAW!$N$3:$N$2000&") "&소재DB_RAW!$O$3:$O$2000,(소재DB_RAW!$G$3:$G$2000=$D16)*ISNUMBER(SEARCH("겉감",소재DB_RAW!$M$3:$M$2000))*ISERROR(SEARCH("drop",소재DB_RAW!$C$3:$C$2000))))),"") | Z16: =IFERROR(TEXTJOIN(CHAR(10),TRUE,UNIQUE(FILTER(소재DB_RAW!$N$3:$N$2000&") "&소재DB_RAW!$O$3:$O$2000,(소재DB_RAW!$G$3:$G$2000=$D16)*ISNUMBER(SEARCH("안감",소재DB_RAW!$M$3:$M$2000))*ISERROR(SEARCH("drop",소재DB_RAW!$C$3:$C$2000))))),"") | AA16: 1100 | AB16: 61816700 | AC16: 297000000 | AE16: =IF($K16="","출고일 미정",IF($Q16="X","작지 미발행",IF($Q16="부분","작지 일부 미발행",IF(AND($S16<>"",$S16>$N16),"소재입고 마감("&TEXT($N16,"MM/DD")&") 초과",IF($Q16="","발행여부 확인 필요",IF($S16="","소재 입고일정 확인 필요","정상")))))) | AF16: =IF($K16="","",IF(OR(LEFT($AE16,2)="작지",LEFT($AE16,4)="소재입고"),IF(LEFT($G16,1)="S","★ 납기위험(S코드)","◆ 지연주의"),IF($AE16="정상","✓ 정상","? 확인필요")))
... A18: 14 | B18: 최진민 | C18: 김지원 | D18: JWTBS27057 | E18: 히어로 남성 니트도트 긴팔 라운드티 | F18: DBU(D/BLUE), BLK(BLACK) | G18: =IF($D18="","",IF(MID($D18,5,1)="S","S(봄)",IF(MID($D18,5,1)="M","M(여름)",IF(MID($D18,5,1)="X","X(사계절)",MID($D18,5,1))))) | H18: 완사입 | I18: S1 | J18: 1월2주 | K18: =IF($J18="","",IFERROR(DATE(IF(VALUE(LEFT($J18,FIND("월",$J18)-1))>=9,기준정보!$C$7-1,기준정보!$C$7),VALUE(LEFT($J18,FIND("월",$J18)-1)),1+7*(VALUE(SUBSTITUTE(MID($J18,FIND("월",$J18)+1,5),"주",""))-1)),"")) | L18: =IF($K18="","",IF(AND($K18-기준정보!$C$5>=기준정보!$C$10,$K18-기준정보!$C$5<=기준정보!$C$11),기준정보!$C$10-1,$K18-기준정보!$C$5)) | M18: =IF($L18="","",IF(OR(ISNUMBER(SEARCH("중국",$W18)),ISNUMBER(SEARCH("베트남",$W18))),MAX(0,MIN($L18,기준정보!$C$9)-MAX($L18-기준정보!$C$6,기준정보!$C$8)+1),IF(ISNUMBER(SEARCH("한국",$W18)),MAX(0,MIN($L18,기준정보!$C$11)-MAX($L18-기준정보!$C$6,기준정보!$C$10)+1),0))) | N18: =IF($L18="","",$L18-기준정보!$C$6-$M18) | O18: =IF($N18="","",$N18-기준정보!$C$4) | Q18: O | R18: =IF(COUNTIF(EDW_RAW!$A$2:$A$1500,$D18)=0,"",IF(COUNTIFS(EDW_RAW!$A$2:$A$1500,$D18,EDW_RAW!$U$2:$U$1500,"<>~",EDW_RAW!$U$2:$U$1500,"<>")=COUNTIF(EDW_RAW!$A$2:$A$1500,$D18),"O",IF(COUNTIFS(EDW_RAW!$A$2:$A$1500,$D18,EDW_RAW!$U$2:$U$1500,"<>~",EDW_RAW!$U$2:$U$1500,"<>")>0,"부분","X"))) | T18: =IF($H18="","",IF(AND(ISNUMBER(SEARCH("CMT",$H18)),OR(ISNUMBER(SEARCH("완사입",$H18)),ISNUMBER(SEARCH("ODM",$H18)))),"본사/생산처 혼재",IF(ISNUMBER(SEARCH("CMT",$H18)),"본사(소재팀)","생산처"))) | U18: 태화 | V18: =IFERROR(TEXTJOIN(" / ",TRUE,UNIQUE(FILTER(소재DB_RAW!$K$3:$K$2000,(소재DB_RAW!$G$3:$G$2000=$D18)*ISERROR(SEARCH("drop",소재DB_RAW!$C$3:$C$2000))))),"") | W18: 베트남 | X18: =IFERROR(TEXTJOIN(" / ",TRUE,UNIQUE(FILTER(소재DB_RAW!$N$3:$N$2000,(소재DB_RAW!$G$3:$G$2000=$D18)*ISERROR(SEARCH("drop",소재DB_RAW!$C$3:$C$2000))))),"") | Y18: =IFERROR(TEXTJOIN(CHAR(10),TRUE,UNIQUE(FILTER(소재DB_RAW!$N$3:$N$2000&") "&소재DB_RAW!$O$3:$O$2000,(소재DB_RAW!$G$3:$G$2000=$D18)*ISNUMBER(SEARCH("겉감",소재DB_RAW!$M$3:$M$2000))*ISERROR(SEARCH("drop",소재DB_RAW!$C$3:$C$2000))))),"") | Z18: =IFERROR(TEXTJOIN(CHAR(10),TRUE,UNIQUE(FILTER(소재DB_RAW!$N$3:$N$2000&") "&소재DB_RAW!$O$3:$O$2000,(소재DB_RAW!$G$3:$G$2000=$D18)*ISNUMBER(SEARCH("안감",소재DB_RAW!$M$3:$M$2000))*ISERROR(SEARCH("drop",소재DB_RAW!$C$3:$C$2000))))),"") | AA18: 300 | AB18: 8055900 | AC18: 41400000 | AE18: =IF($K18="","출고일 미정",IF($Q18="X","작지 미발행",IF($Q18="부분","작지 일부 미발행",IF(AND($S18<>"",$S18>$N18),"소재입고 마감("&TEXT($N18,"MM/DD")&") 초과",IF($Q18="","발행여부 확인 필요",IF($S18="","소재 입고일정 확인 필요","정상")))))) | AF18: =IF($K18="","",IF(OR(LEFT($AE18,2)="작지",LEFT($AE18,4)="소재입고"),IF(LEFT($G18,1)="S","★ 납기위험(S코드)","◆ 지연주의"),IF($AE18="정상","✓ 정상","? 확인필요")))
A19: 15 | B19: 김준래 | C19: 권혁일 | D19: TLTBS27511 | E19: 남성 베이직 폴로 긴팔 티셔츠 | F19: LLA-1, CIN(CINDER), DGY-3 | G19: =IF($D19="","",IF(MID($D19,5,1)="S","S(봄)",IF(MID($D19,5,1)="M","M(여름)",IF(MID($D19,5,1)="X","X(사계절)",MID($D19,5,1))))) | H19: ODM | J19: 1월2주 | K19: =IF($J19="","",IFERROR(DATE(IF(VALUE(LEFT($J19,FIND("월",$J19)-1))>=9,기준정보!$C$7-1,기준정보!$C$7),VALUE(LEFT($J19,FIND("월",$J19)-1)),1+7*(VALUE(SUBSTITUTE(MID($J19,FIND("월",$J19)+1,5),"주",""))-1)),"")) | L19: =IF($K19="","",IF(AND($K19-기준정보!$C$5>=기준정보!$C$10,$K19-기준정보!$C$5<=기준정보!$C$11),기준정보!$C$10-1,$K19-기준정보!$C$5)) | M19: =IF($L19="","",IF(OR(ISNUMBER(SEARCH("중국",$W19)),ISNUMBER(SEARCH("베트남",$W19))),MAX(0,MIN($L19,기준정보!$C$9)-MAX($L19-기준정보!$C$6,기준정보!$C$8)+1),IF(ISNUMBER(SEARCH("한국",$W19)),MAX(0,MIN($L19,기준정보!$C$11)-MAX($L19-기준정보!$C$6,기준정보!$C$10)+1),0))) | N19: =IF($L19="","",$L19-기준정보!$C$6-$M19) | O19: =IF($N19="","",$N19-기준정보!$C$4) | Q19: O | R19: =IF(COUNTIF(EDW_RAW!$A$2:$A$1500,$D19)=0,"",IF(COUNTIFS(EDW_RAW!$A$2:$A$1500,$D19,EDW_RAW!$U$2:$U$1500,"<>~",EDW_RAW!$U$2:$U$1500,"<>")=COUNTIF(EDW_RAW!$A$2:$A$1500,$D19),"O",IF(COUNTIFS(EDW_RAW!$A$2:$A$1500,$D19,EDW_RAW!$U$2:$U$1500,"<>~",EDW_RAW!$U$2:$U$1500,"<>")>0,"부분","X"))) | T19: =IF($H19="","",IF(AND(ISNUMBER(SEARCH("CMT",$H19)),OR(ISNUMBER(SEARCH("완사입",$H19)),ISNUMBER(SEARCH("ODM",$H19)))),"본사/생산처 혼재",IF(ISNUMBER(SEARCH("CMT",$H19)),"본사(소재팀)","생산처"))) | U19: TESSELLATION | V19: =IFERROR(TEXTJOIN(" / ",TRUE,UNIQUE(FILTER(소재DB_RAW!$K$3:$K$2000,(소재DB_RAW!$G$3:$G$2000=$D19)*ISERROR(SEARCH("drop",소재DB_RAW!$C$3:$C$2000))))),"") | W19: 중국 | X19: =IFERROR(TEXTJOIN(" / ",TRUE,UNIQUE(FILTER(소재DB_RAW!$N$3:$N$2000,(소재DB_RAW!$G$3:$G$2000=$D19)*ISERROR(SEARCH("drop",소재DB_RAW!$C$3:$C$2000))))),"") | Y19: =IFERROR(TEXTJOIN(CHAR(10),TRUE,UNIQUE(FILTER(소재DB_RAW!$N$3:$N$2000&") "&소재DB_RAW!$O$3:$O$2000,(소재DB_RAW!$G$3:$G$2000=$D19)*ISNUMBER(SEARCH("겉감",소재DB_RAW!$M$3:$M$2000))*ISERROR(SEARCH("drop",소재DB_RAW!$C$3:$C$2000))))),"") | Z19: =IFERROR(TEXTJOIN(CHAR(10),TRUE,UNIQUE(FILTER(소재DB_RAW!$N$3:$N$2000&") "&소재DB_RAW!$O$3:$O$2000,(소재DB_RAW!$G$3:$G$2000=$D19)*ISNUMBER(SEARCH("안감",소재DB_RAW!$M$3:$M$2000))*ISERROR(SEARCH("drop",소재DB_RAW!$C$3:$C$2000))))),"") | AA19: 8000 | AB19: 188464000 | AC19: 1024000000 | AE19: =IF($K19="","출고일 미정",IF($Q19="X","작지 미발행",IF($Q19="부분","작지 일부 미발행",IF(AND($S19<>"",$S19>$N19),"소재입고 마감("&TEXT($N19,"MM/DD")&") 초과",IF($Q19="","발행여부 확인 필요",IF($S19="","소재 입고일정 확인 필요","정상")))))) | AF19: =IF($K19="","",IF(OR(LEFT($AE19,2)="작지",LEFT($AE19,4)="소재입고"),IF(LEFT($G19,1)="S","★ 납기위험(S코드)","◆ 지연주의"),IF($AE19="정상","✓ 정상","? 확인필요")))
A20: 16 | B20: 김준래 | C20: 권혁일 | D20: TLTBS27571 | E20: 춘절 남성 니트 폴로 긴팔 티셔츠 | F20: BLK(BLACK), LAK(LAKE) | G20: =IF($D20="","",IF(MID($D20,5,1)="S","S(봄)",IF(MID($D20,5,1)="M","M(여름)",IF(MID($D20,5,1)="X","X(사계절)",MID($D20,5,1))))) | H20: 완사입 | J20: 1월2주 | K20: =IF($J20="","",IFERROR(DATE(IF(VALUE(LEFT($J20,FIND("월",$J20)-1))>=9,기준정보!$C$7-1,기준정보!$C$7),VALUE(LEFT($J20,FIND("월",$J20)-1)),1+7*(VALUE(SUBSTITUTE(MID($J20,FIND("월",$J20)+1,5),"주",""))-1)),"")) | L20: =IF($K20="","",IF(AND($K20-기준정보!$C$5>=기준정보!$C$10,$K20-기준정보!$C$5<=기준정보!$C$11),기준정보!$C$10-1,$K20-기준정보!$C$5)) | M20: =IF($L20="","",IF(OR(ISNUMBER(SEARCH("중국",$W20)),ISNUMBER(SEARCH("베트남",$W20))),MAX(0,MIN($L20,기준정보!$C$9)-MAX($L20-기준정보!$C$6,기준정보!$C$8)+1),IF(ISNUMBER(SEARCH("한국",$W20)),MAX(0,MIN($L20,기준정보!$C$11)-MAX($L20-기준정보!$C$6,기준정보!$C$10)+1),0))) | N20: =IF($L20="","",$L20-기준정보!$C$6-$M20) | O20: =IF($N20="","",$N20-기준정보!$C$4) | Q20: O | R20: =IF(COUNTIF(EDW_RAW!$A$2:$A$1500,$D20)=0,"",IF(COUNTIFS(EDW_RAW!$A$2:$A$1500,$D20,EDW_RAW!$U$2:$U$1500,"<>~",EDW_RAW!$U$2:$U$1500,"<>")=COUNTIF(EDW_RAW!$A$2:$A$1500,$D20),"O",IF(COUNTIFS(EDW_RAW!$A$2:$A$1500,$D20,EDW_RAW!$U$2:$U$1500,"<>~",EDW_RAW!$U$2:$U$1500,"<>")>0,"부분","X"))) | T20: =IF($H20="","",IF(AND(ISNUMBER(SEARCH("CMT",$H20)),OR(ISNUMBER(SEARCH("완사입",$H20)),ISNUMBER(SEARCH("ODM",$H20)))),"본사/생산처 혼재",IF(ISNUMBER(SEARCH("CMT",$H20)),"본사(소재팀)","생산처"))) | U20: 어필코리아 | V20: =IFERROR(TEXTJOIN(" / ",TRUE,UNIQUE(FILTER(소재DB_RAW!$K$3:$K$2000,(소재DB_RAW!$G$3:$G$2000=$D20)*ISERROR(SEARCH("drop",소재DB_RAW!$C$3:$C$2000))))),"") | W20: 베트남 | X20: =IFERROR(TEXTJOIN(" / ",TRUE,UNIQUE(FILTER(소재DB_RAW!$N$3:$N$2000,(소재DB_RAW!$G$3:$G$2000=$D20)*ISERROR(SEARCH("drop",소재DB_RAW!$C$3:$C$2000))))),"") | Y20: =IFERROR(TEXTJOIN(CHAR(10),TRUE,UNIQUE(FILTER(소재DB_RAW!$N$3:$N$2000&") "&소재DB_RAW!$O$3:$O$2000,(소재DB_RAW!$G$3:$G$2000=$D20)*ISNUMBER(SEARCH("겉감",소재DB_RAW!$M$3:$M$2000))*ISERROR(SEARCH("drop",소재DB_RAW!$C$3:$C$2000))))),"") | Z20: =IFERROR(TEXTJOIN(CHAR(10),TRUE,UNIQUE(FILTER(소재DB_RAW!$N$3:$N$2000&") "&소재DB_RAW!$O$3:$O$2000,(소재DB_RAW!$G$3:$G$2000=$D20)*ISNUMBER(SEARCH("안감",소재DB_RAW!$M$3:$M$2000))*ISERROR(SEARCH("drop",소재DB_RAW!$C$3:$C$2000))))),"") | AA20: 2000 | AB20: 106628000 | AC20: 440000000 | AD20: 1월2주 | AE20: =IF($K20="","출고일 미정",IF($Q20="X","작지 미발행",IF($Q20="부분","작지 일부 미발행",IF(AND($S20<>"",$S20>$N20),"소재입고 마감("&TEXT($N20,"MM/DD")&") 초과",IF($Q20="","발행여부 확인 필요",IF($S20="","소재 입고일정 확인 필요","정상")))))) | AF20: =IF($K20="","",IF(OR(LEFT($AE20,2)="작지",LEFT($AE20,4)="소재입고"),IF(LEFT($G20,1)="S","★ 납기위험(S코드)","◆ 지연주의"),IF($AE20="정상","✓ 정상","? 확인필요")))
A21: 17 | B21: 김준래 | C21: 권혁일 | D21: TVTBS27548 | E21: 여성 베이직 폴로 긴팔 티셔츠 | F21: IVO(IVORY), LPI, NAY | G21: =IF($D21="","",IF(MID($D21,5,1)="S","S(봄)",IF(MID($D21,5,1)="M","M(여름)",IF(MID($D21,5,1)="X","X(사계절)",MID($D21,5,1))))) | H21: ODM | J21: 1월2주 | K21: =IF($J21="","",IFERROR(DATE(IF(VALUE(LEFT($J21,FIND("월",$J21)-1))>=9,기준정보!$C$7-1,기준정보!$C$7),VALUE(LEFT($J21,FIND("월",$J21)-1)),1+7*(VALUE(SUBSTITUTE(MID($J21,FIND("월",$J21)+1,5),"주",""))-1)),"")) | L21: =IF($K21="","",IF(AND($K21-기준정보!$C$5>=기준정보!$C$10,$K21-기준정보!$C$5<=기준정보!$C$11),기준정보!$C$10-1,$K21-기준정보!$C$5)) | M21: =IF($L21="","",IF(OR(ISNUMBER(SEARCH("중국",$W21)),ISNUMBER(SEARCH("베트남",$W21))),MAX(0,MIN($L21,기준정보!$C$9)-MAX($L21-기준정보!$C$6,기준정보!$C$8)+1),IF(ISNUMBER(SEARCH("한국",$W21)),MAX(0,MIN($L21,기준정보!$C$11)-MAX($L21-기준정보!$C$6,기준정보!$C$10)+1),0))) | N21: =IF($L21="","",$L21-기준정보!$C$6-$M21) | O21: =IF($N21="","",$N21-기준정보!$C$4) | Q21: O | R21: =IF(COUNTIF(EDW_RAW!$A$2:$A$1500,$D21)=0,"",IF(COUNTIFS(EDW_RAW!$A$2:$A$1500,$D21,EDW_RAW!$U$2:$U$1500,"<>~",EDW_RAW!$U$2:$U$1500,"<>")=COUNTIF(EDW_RAW!$A$2:$A$1500,$D21),"O",IF(COUNTIFS(EDW_RAW!$A$2:$A$1500,$D21,EDW_RAW!$U$2:$U$1500,"<>~",EDW_RAW!$U$2:$U$1500,"<>")>0,"부분","X"))) | T21: =IF($H21="","",IF(AND(ISNUMBER(SEARCH("CMT",$H21)),OR(ISNUMBER(SEARCH("완사입",$H21)),ISNUMBER(SEARCH("ODM",$H21)))),"본사/생산처 혼재",IF(ISNUMBER(SEARCH("CMT",$H21)),"본사(소재팀)","생산처"))) | U21: TESSELLATION | V21: =IFERROR(TEXTJOIN(" / ",TRUE,UNIQUE(FILTER(소재DB_RAW!$K$3:$K$2000,(소재DB_RAW!$G$3:$G$2000=$D21)*ISERROR(SEARCH("drop",소재DB_RAW!$C$3:$C$2000))))),"") | W21: 베트남 | X21: =IFERROR(TEXTJOIN(" / ",TRUE,UNIQUE(FILTER(소재DB_RAW!$N$3:$N$2000,(소재DB_RAW!$G$3:$G$2000=$D21)*ISERROR(SEARCH("drop",소재DB_RAW!$C$3:$C$2000))))),"") | Y21: =IFERROR(TEXTJOIN(CHAR(10),TRUE,UNIQUE(FILTER(소재DB_RAW!$N$3:$N$2000&") "&소재DB_RAW!$O$3:$O$2000,(소재DB_RAW!$G$3:$G$2000=$D21)*ISNUMBER(SEARCH("겉감",소재DB_RAW!$M$3:$M$2000))*ISERROR(SEARCH("drop",소재DB_RAW!$C$3:$C$2000))))),"") | Z21: =IFERROR(TEXTJOIN(CHAR(10),TRUE,UNIQUE(FILTER(소재DB_RAW!$N$3:$N$2000&") "&소재DB_RAW!$O$3:$O$2000,(소재DB_RAW!$G$3:$G$2000=$D21)*ISNUMBER(SEARCH("안감",소재DB_RAW!$M$3:$M$2000))*ISERROR(SEARCH("drop",소재DB_RAW!$C$3:$C$2000))))),"") | AA21: 3700 | AB21: 81736700 | AC21: 473600000 | AE21: =IF($K21="","출고일 미정",IF($Q21="X","작지 미발행",IF($Q21="부분","작지 일부 미발행",IF(AND($S21<>"",$S21>$N21),"소재입고 마감("&TEXT($N21,"MM/DD")&") 초과",IF($Q21="","발행여부 확인 필요",IF($S21="","소재 입고일정 확인 필요","정상")))))) | AF21: =IF($K21="","",IF(OR(LEFT($AE21,2)="작지",LEFT($AE21,4)="소재입고"),IF(LEFT($G21,1)="S","★ 납기위험(S코드)","◆ 지연주의"),IF($AE21="정상","✓ 정상","? 확인필요")))
A22: 18 | B22: 김준래 | C22: 권혁일 | D22: TVTBS27592 | E22: 춘절 여성 니트 폴로 긴팔 티셔츠 | F22: CRE-2, LLA-1 | G22: =IF($D22="","",IF(MID($D22,5,1)="S","S(봄)",IF(MID($D22,5,1)="M","M(여름)",IF(MID($D22,5,1)="X","X(사계절)",MID($D22,5,1))))) | H22: 완사입 | J22: 1월2주 | K22: =IF($J22="","",IFERROR(DATE(IF(VALUE(LEFT($J22,FIND("월",$J22)-1))>=9,기준정보!$C$7-1,기준정보!$C$7),VALUE(LEFT($J22,FIND("월",$J22)-1)),1+7*(VALUE(SUBSTITUTE(MID($J22,FIND("월",$J22)+1,5),"주",""))-1)),"")) | L22: =IF($K22="","",IF(AND($K22-기준정보!$C$5>=기준정보!$C$10,$K22-기준정보!$C$5<=기준정보!$C$11),기준정보!$C$10-1,$K22-기준정보!$C$5)) | M22: =IF($L22="","",IF(OR(ISNUMBER(SEARCH("중국",$W22)),ISNUMBER(SEARCH("베트남",$W22))),MAX(0,MIN($L22,기준정보!$C$9)-MAX($L22-기준정보!$C$6,기준정보!$C$8)+1),IF(ISNUMBER(SEARCH("한국",$W22)),MAX(0,MIN($L22,기준정보!$C$11)-MAX($L22-기준정보!$C$6,기준정보!$C$10)+1),0))) | N22: =IF($L22="","",$L22-기준정보!$C$6-$M22) | O22: =IF($N22="","",$N22-기준정보!$C$4) | Q22: O | R22: =IF(COUNTIF(EDW_RAW!$A$2:$A$1500,$D22)=0,"",IF(COUNTIFS(EDW_RAW!$A$2:$A$1500,$D22,EDW_RAW!$U$2:$U$1500,"<>~",EDW_RAW!$U$2:$U$1500,"<>")=COUNTIF(EDW_RAW!$A$2:$A$1500,$D22),"O",IF(COUNTIFS(EDW_RAW!$A$2:$A$1500,$D22,EDW_RAW!$U$2:$U$1500,"<>~",EDW_RAW!$U$2:$U$1500,"<>")>0,"부분","X"))) | T22: =IF($H22="","",IF(AND(ISNUMBER(SEARCH("CMT",$H22)),OR(ISNUMBER(SEARCH("완사입",$H22)),ISNUMBER(SEARCH("ODM",$H22)))),"본사/생산처 혼재",IF(ISNUMBER(SEARCH("CMT",$H22)),"본사(소재팀)","생산처"))) | U22: 어필코리아 | V22: =IFERROR(TEXTJOIN(" / ",TRUE,UNIQUE(FILTER(소재DB_RAW!$K$3:$K$2000,(소재DB_RAW!$G$3:$G$2000=$D22)*ISERROR(SEARCH("drop",소재DB_RAW!$C$3:$C$2000))))),"") | W22: 베트남 | X22: =IFERROR(TEXTJOIN(" / ",TRUE,UNIQUE(FILTER(소재DB_RAW!$N$3:$N$2000,(소재DB_RAW!$G$3:$G$2000=$D22)*ISERROR(SEARCH("drop",소재DB_RAW!$C$3:$C$2000))))),"") | Y22: =IFERROR(TEXTJOIN(CHAR(10),TRUE,UNIQUE(FILTER(소재DB_RAW!$N$3:$N$2000&") "&소재DB_RAW!$O$3:$O$2000,(소재DB_RAW!$G$3:$G$2000=$D22)*ISNUMBER(SEARCH("겉감",소재DB_RAW!$M$3:$M$2000))*ISERROR(SEARCH("drop",소재DB_RAW!$C$3:$C$2000))))),"") | Z22: =IFERROR(TEXTJOIN(CHAR(10),TRUE,UNIQUE(FILTER(소재DB_RAW!$N$3:$N$2000&") "&소재DB_RAW!$O$3:$O$2000,(소재DB_RAW!$G$3:$G$2000=$D22)*ISNUMBER(SEARCH("안감",소재DB_RAW!$M$3:$M$2000))*ISERROR(SEARCH("drop",소재DB_RAW!$C$3:$C$2000))))),"") | AA22: 1200 | AB22: 58612800 | AC22: 237600000 | AD22: 1월2주 | AE22: =IF($K22="","출고일 미정",IF($Q22="X","작지 미발행",IF($Q22="부분","작지 일부 미발행",IF(AND($S22<>"",$S22>$N22),"소재입고 마감("&TEXT($N22,"MM/DD")&") 초과",IF($Q22="","발행여부 확인 필요",IF($S22="","소재 입고일정 확인 필요","정상")))))) | AF22: =IF($K22="","",IF(OR(LEFT($AE22,2)="작지",LEFT($AE22,4)="소재입고"),IF(LEFT($G22,1)="S","★ 납기위험(S코드)","◆ 지연주의"),IF($AE22="정상","✓ 정상","? 확인필요")))
A23: 19 | B23: 신인철 | C23: 안세진 | D23: 8GJJS27101 | E23: [WM] 남성 아웃포켓 피싱 재킷 | F23: KHA(KHAKI), BLK(BLACK) | G23: =IF($D23="","",IF(MID($D23,5,1)="S","S(봄)",IF(MID($D23,5,1)="M","M(여름)",IF(MID($D23,5,1)="X","X(사계절)",MID($D23,5,1))))) | H23: 완사입 | I23: 1차 | J23: 1월3주 | K23: =IF($J23="","",IFERROR(DATE(IF(VALUE(LEFT($J23,FIND("월",$J23)-1))>=9,기준정보!$C$7-1,기준정보!$C$7),VALUE(LEFT($J23,FIND("월",$J23)-1)),1+7*(VALUE(SUBSTITUTE(MID($J23,FIND("월",$J23)+1,5),"주",""))-1)),"")) | L23: =IF($K23="","",IF(AND($K23-기준정보!$C$5>=기준정보!$C$10,$K23-기준정보!$C$5<=기준정보!$C$11),기준정보!$C$10-1,$K23-기준정보!$C$5)) | M23: =IF($L23="","",IF(OR(ISNUMBER(SEARCH("중국",$W23)),ISNUMBER(SEARCH("베트남",$W23))),MAX(0,MIN($L23,기준정보!$C$9)-MAX($L23-기준정보!$C$6,기준정보!$C$8)+1),IF(ISNUMBER(SEARCH("한국",$W23)),MAX(0,MIN($L23,기준정보!$C$11)-MAX($L23-기준정보!$C$6,기준정보!$C$10)+1),0))) | N23: =IF($L23="","",$L23-기준정보!$C$6-$M23) | O23: =IF($N23="","",$N23-기준정보!$C$4) | Q23: X | R23: =IF(COUNTIF(EDW_RAW!$A$2:$A$1500,$D23)=0,"",IF(COUNTIFS(EDW_RAW!$A$2:$A$1500,$D23,EDW_RAW!$U$2:$U$1500,"<>~",EDW_RAW!$U$2:$U$1500,"<>")=COUNTIF(EDW_RAW!$A$2:$A$1500,$D23),"O",IF(COUNTIFS(EDW_RAW!$A$2:$A$1500,$D23,EDW_RAW!$U$2:$U$1500,"<>~",EDW_RAW!$U$2:$U$1500,"<>")>0,"부분","X"))) | T23: =IF($H23="","",IF(AND(ISNUMBER(SEARCH("CMT",$H23)),OR(ISNUMBER(SEARCH("완사입",$H23)),ISNUMBER(SEARCH("ODM",$H23)))),"본사/생산처 혼재",IF(ISNUMBER(SEARCH("CMT",$H23)),"본사(소재팀)","생산처"))) | U23: YIC | V23: =IFERROR(TEXTJOIN(" / ",TRUE,UNIQUE(FILTER(소재DB_RAW!$K$3:$K$2000,(소재DB_RAW!$G$3:$G$2000=$D23)*ISERROR(SEARCH("drop",소재DB_RAW!$C$3:$C$2000))))),"") | W23: 베트남 | X23: =IFERROR(TEXTJOIN(" / ",TRUE,UNIQUE(FILTER(소재DB_RAW!$N$3:$N$2000,(소재DB_RAW!$G$3:$G$2000=$D23)*ISERROR(SEARCH("drop",소재DB_RAW!$C$3:$C$2000))))),"") | Y23: =IFERROR(TEXTJOIN(CHAR(10),TRUE,UNIQUE(FILTER(소재DB_RAW!$N$3:$N$2000&") "&소재DB_RAW!$O$3:$O$2000,(소재DB_RAW!$G$3:$G$2000=$D23)*ISNUMBER(SEARCH("겉감",소재DB_RAW!$M$3:$M$2000))*ISERROR(SEARCH("drop",소재DB_RAW!$C$3:$C$2000))))),"") | Z23: =IFERROR(TEXTJOIN(CHAR(10),TRUE,UNIQUE(FILTER(소재DB_RAW!$N$3:$N$2000&") "&소재DB_RAW!$O$3:$O$2000,(소재DB_RAW!$G$3:$G$2000=$D23)*ISNUMBER(SEARCH("안감",소재DB_RAW!$M$3:$M$2000))*ISERROR(SEARCH("drop",소재DB_RAW!$C$3:$C$2000))))),"") | AA23: 0 | AB23: 64250000 | AC23: 180000000 | AE23: =IF($K23="","출고일 미정",IF($Q23="X","작지 미발행",IF($Q23="부분","작지 일부 미발행",IF(AND($S23<>"",$S23>$N23),"소재입고 마감("&TEXT($N23,"MM/DD")&") 초과",IF($Q23="","발행여부 확인 필요",IF($S23="","소재 입고일정 확인 필요","정상")))))) | AF23: =IF($K23="","",IF(OR(LEFT($AE23,2)="작지",LEFT($AE23,4)="소재입고"),IF(LEFT($G23,1)="S","★ 납기위험(S코드)","◆ 지연주의"),IF($AE23="정상","✓ 정상","? 확인필요")))
A24: 20 | B24: 신인철 | C24: 안세진 | D24: 8GPNS27101 | E24: [WM] 남성 유틸리티 피싱 카고 팬츠 | F24: KHA(KHAKI), BLK(BLACK) | G24: =IF($D24="","",IF(MID($D24,5,1)="S","S(봄)",IF(MID($D24,5,1)="M","M(여름)",IF(MID($D24,5,1)="X","X(사계절)",MID($D24,5,1))))) | H24: 완사입 | I24: 1차 | J24: 1월3주 | K24: =IF($J24="","",IFERROR(DATE(IF(VALUE(LEFT($J24,FIND("월",$J24)-1))>=9,기준정보!$C$7-1,기준정보!$C$7),VALUE(LEFT($J24,FIND("월",$J24)-1)),1+7*(VALUE(SUBSTITUTE(MID($J24,FIND("월",$J24)+1,5),"주",""))-1)),"")) | L24: =IF($K24="","",IF(AND($K24-기준정보!$C$5>=기준정보!$C$10,$K24-기준정보!$C$5<=기준정보!$C$11),기준정보!$C$10-1,$K24-기준정보!$C$5)) | M24: =IF($L24="","",IF(OR(ISNUMBER(SEARCH("중국",$W24)),ISNUMBER(SEARCH("베트남",$W24))),MAX(0,MIN($L24,기준정보!$C$9)-MAX($L24-기준정보!$C$6,기준정보!$C$8)+1),IF(ISNUMBER(SEARCH("한국",$W24)),MAX(0,MIN($L24,기준정보!$C$11)-MAX($L24-기준정보!$C$6,기준정보!$C$10)+1),0))) | N24: =IF($L24="","",$L24-기준정보!$C$6-$M24) | O24: =IF($N24="","",$N24-기준정보!$C$4) | Q24: X | R24: =IF(COUNTIF(EDW_RAW!$A$2:$A$1500,$D24)=0,"",IF(COUNTIFS(EDW_RAW!$A$2:$A$1500,$D24,EDW_RAW!$U$2:$U$1500,"<>~",EDW_RAW!$U$2:$U$1500,"<>")=COUNTIF(EDW_RAW!$A$2:$A$1500,$D24),"O",IF(COUNTIFS(EDW_RAW!$A$2:$A$1500,$D24,EDW_RAW!$U$2:$U$1500,"<>~",EDW_RAW!$U$2:$U$1500,"<>")>0,"부분","X"))) | T24: =IF($H24="","",IF(AND(ISNUMBER(SEARCH("CMT",$H24)),OR(ISNUMBER(SEARCH("완사입",$H24)),ISNUMBER(SEARCH("ODM",$H24)))),"본사/생산처 혼재",IF(ISNUMBER(SEARCH("CMT",$H24)),"본사(소재팀)","생산처"))) | U24: YIC | V24: =IFERROR(TEXTJOIN(" / ",TRUE,UNIQUE(FILTER(소재DB_RAW!$K$3:$K$2000,(소재DB_RAW!$G$3:$G$2000=$D24)*ISERROR(SEARCH("drop",소재DB_RAW!$C$3:$C$2000))))),"") | W24: 베트남 | X24: =IFERROR(TEXTJOIN(" / ",TRUE,UNIQUE(FILTER(소재DB_RAW!$N$3:$N$2000,(소재DB_RAW!$G$3:$G$2000=$D24)*ISERROR(SEARCH("drop",소재DB_RAW!$C$3:$C$2000))))),"") | Y24: =IFERROR(TEXTJOIN(CHAR(10),TRUE,UNIQUE(FILTER(소재DB_RAW!$N$3:$N$2000&") "&소재DB_RAW!$O$3:$O$2000,(소재DB_RAW!$G$3:$G$2000=$D24)*ISNUMBER(SEARCH("겉감",소재DB_RAW!$M$3:$M$2000))*ISERROR(SEARCH("drop",소재DB_RAW!$C$3:$C$2000))))),"") | Z24: =IFERROR(TEXTJOIN(CHAR(10),TRUE,UNIQUE(FILTER(소재DB_RAW!$N$3:$N$2000&") "&소재DB_RAW!$O$3:$O$2000,(소재DB_RAW!$G$3:$G$2000=$D24)*ISNUMBER(SEARCH("안감",소재DB_RAW!$M$3:$M$2000))*ISERROR(SEARCH("drop",소재DB_RAW!$C$3:$C$2000))))),"") | AA24: 0 | AB24: 34930000 | AC24: 87500000 | AE24: =IF($K24="","출고일 미정",IF($Q24="X","작지 미발행",IF($Q24="부분","작지 일부 미발행",IF(AND($S24<>"",$S24>$N24),"소재입고 마감("&TEXT($N24,"MM/DD")&") 초과",IF($Q24="","발행여부 확인 필요",IF($S24="","소재 입고일정 확인 필요","정상")))))) | AF24: =IF($K24="","",IF(OR(LEFT($AE24,2)="작지",LEFT($AE24,4)="소재입고"),IF(LEFT($G24,1)="S","★ 납기위험(S코드)","◆ 지연주의"),IF($AE24="정상","✓ 정상","? 확인필요")))
A25: 21 | B25: 신인철 | C25: 장지은 | D25: 8HJJS27102 | E25: [WM] 여성 아웃포켓 피싱 재킷 | F25: CAM(CAMEL), BLK(BLACK) | G25: =IF($D25="","",IF(MID($D25,5,1)="S","S(봄)",IF(MID($D25,5,1)="M","M(여름)",IF(MID($D25,5,1)="X","X(사계절)",MID($D25,5,1))))) | H25: 완사입 | I25: 1차 | J25: 1월3주 | K25: =IF($J25="","",IFERROR(DATE(IF(VALUE(LEFT($J25,FIND("월",$J25)-1))>=9,기준정보!$C$7-1,기준정보!$C$7),VALUE(LEFT($J25,FIND("월",$J25)-1)),1+7*(VALUE(SUBSTITUTE(MID($J25,FIND("월",$J25)+1,5),"주",""))-1)),"")) | L25: =IF($K25="","",IF(AND($K25-기준정보!$C$5>=기준정보!$C$10,$K25-기준정보!$C$5<=기준정보!$C$11),기준정보!$C$10-1,$K25-기준정보!$C$5)) | M25: =IF($L25="","",IF(OR(ISNUMBER(SEARCH("중국",$W25)),ISNUMBER(SEARCH("베트남",$W25))),MAX(0,MIN($L25,기준정보!$C$9)-MAX($L25-기준정보!$C$6,기준정보!$C$8)+1),IF(ISNUMBER(SEARCH("한국",$W25)),MAX(0,MIN($L25,기준정보!$C$11)-MAX($L25-기준정보!$C$6,기준정보!$C$10)+1),0))) | N25: =IF($L25="","",$L25-기준정보!$C$6-$M25) | O25: =IF($N25="","",$N25-기준정보!$C$4) | Q25: X | R25: =IF(COUNTIF(EDW_RAW!$A$2:$A$1500,$D25)=0,"",IF(COUNTIFS(EDW_RAW!$A$2:$A$1500,$D25,EDW_RAW!$U$2:$U$1500,"<>~",EDW_RAW!$U$2:$U$1500,"<>")=COUNTIF(EDW_RAW!$A$2:$A$1500,$D25),"O",IF(COUNTIFS(EDW_RAW!$A$2:$A$1500,$D25,EDW_RAW!$U$2:$U$1500,"<>~",EDW_RAW!$U$2:$U$1500,"<>")>0,"부분","X"))) | T25: =IF($H25="","",IF(AND(ISNUMBER(SEARCH("CMT",$H25)),OR(ISNUMBER(SEARCH("완사입",$H25)),ISNUMBER(SEARCH("ODM",$H25)))),"본사/생산처 혼재",IF(ISNUMBER(SEARCH("CMT",$H25)),"본사(소재팀)","생산처"))) | U25: YIC | V25: =IFERROR(TEXTJOIN(" / ",TRUE,UNIQUE(FILTER(소재DB_RAW!$K$3:$K$2000,(소재DB_RAW!$G$3:$G$2000=$D25)*ISERROR(SEARCH("drop",소재DB_RAW!$C$3:$C$2000))))),"") | W25: 베트남 | X25: =IFERROR(TEXTJOIN(" / ",TRUE,UNIQUE(FILTER(소재DB_RAW!$N$3:$N$2000,(소재DB_RAW!$G$3:$G$2000=$D25)*ISERROR(SEARCH("drop",소재DB_RAW!$C$3:$C$2000))))),"") | Y25: =IFERROR(TEXTJOIN(CHAR(10),TRUE,UNIQUE(FILTER(소재DB_RAW!$N$3:$N$2000&") "&소재DB_RAW!$O$3:$O$2000,(소재DB_RAW!$G$3:$G$2000=$D25)*ISNUMBER(SEARCH("겉감",소재DB_RAW!$M$3:$M$2000))*ISERROR(SEARCH("drop",소재DB_RAW!$C$3:$C$2000))))),"") | Z25: =IFERROR(TEXTJOIN(CHAR(10),TRUE,UNIQUE(FILTER(소재DB_RAW!$N$3:$N$2000&") "&소재DB_RAW!$O$3:$O$2000,(소재DB_RAW!$G$3:$G$2000=$D25)*ISNUMBER(SEARCH("안감",소재DB_RAW!$M$3:$M$2000))*ISERROR(SEARCH("drop",소재DB_RAW!$C$3:$C$2000))))),"") | AA25: 0 | AB25: 56850000 | AC25: 180000000 | AE25: =IF($K25="","출고일 미정",IF($Q25="X","작지 미발행",IF($Q25="부분","작지 일부 미발행",IF(AND($S25<>"",$S25>$N25),"소재입고 마감("&TEXT($N25,"MM/DD")&") 초과",IF($Q25="","발행여부 확인 필요",IF($S25="","소재 입고일정 확인 필요","정상")))))) | AF25: =IF($K25="","",IF(OR(LEFT($AE25,2)="작지",LEFT($AE25,4)="소재입고"),IF(LEFT($G25,1)="S","★ 납기위험(S코드)","◆ 지연주의"),IF($AE25="정상","✓ 정상","? 확인필요")))
A26: 22 | B26: 신인철 | C26: 장지은 | D26: 8HPNS27102 | E26: [WM] 여성 유틸리티 피싱 카고 팬츠 | F26: CAM(CAMEL), BLK(BLACK) | G26: =IF($D26="","",IF(MID($D26,5,1)="S","S(봄)",IF(MID($D26,5,1)="M","M(여름)",IF(MID($D26,5,1)="X","X(사계절)",MID($D26,5,1))))) | H26: 완사입 | I26: 1차 | J26: 1월3주 | K26: =IF($J26="","",IFERROR(DATE(IF(VALUE(LEFT($J26,FIND("월",$J26)-1))>=9,기준정보!$C$7-1,기준정보!$C$7),VALUE(LEFT($J26,FIND("월",$J26)-1)),1+7*(VALUE(SUBSTITUTE(MID($J26,FIND("월",$J26)+1,5),"주",""))-1)),"")) | L26: =IF($K26="","",IF(AND($K26-기준정보!$C$5>=기준정보!$C$10,$K26-기준정보!$C$5<=기준정보!$C$11),기준정보!$C$10-1,$K26-기준정보!$C$5)) | M26: =IF($L26="","",IF(OR(ISNUMBER(SEARCH("중국",$W26)),ISNUMBER(SEARCH("베트남",$W26))),MAX(0,MIN($L26,기준정보!$C$9)-MAX($L26-기준정보!$C$6,기준정보!$C$8)+1),IF(ISNUMBER(SEARCH("한국",$W26)),MAX(0,MIN($L26,기준정보!$C$11)-MAX($L26-기준정보!$C$6,기준정보!$C$10)+1),0))) | N26: =IF($L26="","",$L26-기준정보!$C$6-$M26) | O26: =IF($N26="","",$N26-기준정보!$C$4) | Q26: X | R26: =IF(COUNTIF(EDW_RAW!$A$2:$A$1500,$D26)=0,"",IF(COUNTIFS(EDW_RAW!$A$2:$A$1500,$D26,EDW_RAW!$U$2:$U$1500,"<>~",EDW_RAW!$U$2:$U$1500,"<>")=COUNTIF(EDW_RAW!$A$2:$A$1500,$D26),"O",IF(COUNTIFS(EDW_RAW!$A$2:$A$1500,$D26,EDW_RAW!$U$2:$U$1500,"<>~",EDW_RAW!$U$2:$U$1500,"<>")>0,"부분","X"))) | T26: =IF($H26="","",IF(AND(ISNUMBER(SEARCH("CMT",$H26)),OR(ISNUMBER(SEARCH("완사입",$H26)),ISNUMBER(SEARCH("ODM",$H26)))),"본사/생산처 혼재",IF(ISNUMBER(SEARCH("CMT",$H26)),"본사(소재팀)","생산처"))) | U26: YIC | V26: =IFERROR(TEXTJOIN(" / ",TRUE,UNIQUE(FILTER(소재DB_RAW!$K$3:$K$2000,(소재DB_RAW!$G$3:$G$2000=$D26)*ISERROR(SEARCH("drop",소재DB_RAW!$C$3:$C$2000))))),"") | W26: 베트남 | X26: =IFERROR(TEXTJOIN(" / ",TRUE,UNIQUE(FILTER(소재DB_RAW!$N$3:$N$2000,(소재DB_RAW!$G$3:$G$2000=$D26)*ISERROR(SEARCH("drop",소재DB_RAW!$C$3:$C$2000))))),"") | Y26: =IFERROR(TEXTJOIN(CHAR(10),TRUE,UNIQUE(FILTER(소재DB_RAW!$N$3:$N$2000&") "&소재DB_RAW!$O$3:$O$2000,(소재DB_RAW!$G$3:$G$2000=$D26)*ISNUMBER(SEARCH("겉감",소재DB_RAW!$M$3:$M$2000))*ISERROR(SEARCH("drop",소재DB_RAW!$C$3:$C$2000))))),"") | Z26: =IFERROR(TEXTJOIN(CHAR(10),TRUE,UNIQUE(FILTER(소재DB_RAW!$N$3:$N$2000&") "&소재DB_RAW!$O$3:$O$2000,(소재DB_RAW!$G$3:$G$2000=$D26)*ISNUMBER(SEARCH("안감",소재DB_RAW!$M$3:$M$2000))*ISERROR(SEARCH("drop",소재DB_RAW!$C$3:$C$2000))))),"") | AA26: 0 | AB26: 44500000 | AC26: 125000000 | AE26: =IF($K26="","출고일 미정",IF($Q26="X","작지 미발행",IF($Q26="부분","작지 일부 미발행",IF(AND($S26<>"",$S26>$N26),"소재입고 마감("&TEXT($N26,"MM/DD")&") 초과",IF($Q26="","발행여부 확인 필요",IF($S26="","소재 입고일정 확인 필요","정상")))))) | AF26: =IF($K26="","",IF(OR(LEFT($AE26,2)="작지",LEFT($AE26,4)="소재입고"),IF(LEFT($G26,1)="S","★ 납기위험(S코드)","◆ 지연주의"),IF($AE26="정상","✓ 정상","? 확인필요")))
A27: 23 | B27: 신인철 | C27: 안세진 | D27: 8NHAS27101 | E27: [WM] 남녀공용 3지 익스퍼트 장갑 | F27: BLK(BLACK) | G27: =IF($D27="","",IF(MID($D27,5,1)="S","S(봄)",IF(MID($D27,5,1)="M","M(여름)",IF(MID($D27,5,1)="X","X(사계절)",MID($D27,5,1))))) | H27: 완사입 | I27: 1차 | J27: 1월3주 | K27: =IF($J27="","",IFERROR(DATE(IF(VALUE(LEFT($J27,FIND("월",$J27)-1))>=9,기준정보!$C$7-1,기준정보!$C$7),VALUE(LEFT($J27,FIND("월",$J27)-1)),1+7*(VALUE(SUBSTITUTE(MID($J27,FIND("월",$J27)+1,5),"주",""))-1)),"")) | L27: =IF($K27="","",IF(AND($K27-기준정보!$C$5>=기준정보!$C$10,$K27-기준정보!$C$5<=기준정보!$C$11),기준정보!$C$10-1,$K27-기준정보!$C$5)) | M27: =IF($L27="","",IF(OR(ISNUMBER(SEARCH("중국",$W27)),ISNUMBER(SEARCH("베트남",$W27))),MAX(0,MIN($L27,기준정보!$C$9)-MAX($L27-기준정보!$C$6,기준정보!$C$8)+1),IF(ISNUMBER(SEARCH("한국",$W27)),MAX(0,MIN($L27,기준정보!$C$11)-MAX($L27-기준정보!$C$6,기준정보!$C$10)+1),0))) | N27: =IF($L27="","",$L27-기준정보!$C$6-$M27) | O27: =IF($N27="","",$N27-기준정보!$C$4) | Q27: X | R27: =IF(COUNTIF(EDW_RAW!$A$2:$A$1500,$D27)=0,"",IF(COUNTIFS(EDW_RAW!$A$2:$A$1500,$D27,EDW_RAW!$U$2:$U$1500,"<>~",EDW_RAW!$U$2:$U$1500,"<>")=COUNTIF(EDW_RAW!$A$2:$A$1500,$D27),"O",IF(COUNTIFS(EDW_RAW!$A$2:$A$1500,$D27,EDW_RAW!$U$2:$U$1500,"<>~",EDW_RAW!$U$2:$U$1500,"<>")>0,"부분","X"))) | T27: =IF($H27="","",IF(AND(ISNUMBER(SEARCH("CMT",$H27)),OR(ISNUMBER(SEARCH("완사입",$H27)),ISNUMBER(SEARCH("ODM",$H27)))),"본사/생산처 혼재",IF(ISNUMBER(SEARCH("CMT",$H27)),"본사(소재팀)","생산처"))) | U27: 시즈 | V27: =IFERROR(TEXTJOIN(" / ",TRUE,UNIQUE(FILTER(소재DB_RAW!$K$3:$K$2000,(소재DB_RAW!$G$3:$G$2000=$D27)*ISERROR(SEARCH("drop",소재DB_RAW!$C$3:$C$2000))))),"") | W27: 베트남 | X27: =IFERROR(TEXTJOIN(" / ",TRUE,UNIQUE(FILTER(소재DB_RAW!$N$3:$N$2000,(소재DB_RAW!$G$3:$G$2000=$D27)*ISERROR(SEARCH("drop",소재DB_RAW!$C$3:$C$2000))))),"") | Y27: =IFERROR(TEXTJOIN(CHAR(10),TRUE,UNIQUE(FILTER(소재DB_RAW!$N$3:$N$2000&") "&소재DB_RAW!$O$3:$O$2000,(소재DB_RAW!$G$3:$G$2000=$D27)*ISNUMBER(SEARCH("겉감",소재DB_RAW!$M$3:$M$2000))*ISERROR(SEARCH("drop",소재DB_RAW!$C$3:$C$2000))))),"") | Z27: =IFERROR(TEXTJOIN(CHAR(10),TRUE,UNIQUE(FILTER(소재DB_RAW!$N$3:$N$2000&") "&소재DB_RAW!$O$3:$O$2000,(소재DB_RAW!$G$3:$G$2000=$D27)*ISNUMBER(SEARCH("안감",소재DB_RAW!$M$3:$M$2000))*ISERROR(SEARCH("drop",소재DB_RAW!$C$3:$C$2000))))),"") | AA27: 0 | AB27: 2558824 | AC27: 8700000 | AE27: =IF($K27="","출고일 미정",IF($Q27="X","작지 미발행",IF($Q27="부분","작지 일부 미발행",IF(AND($S27<>"",$S27>$N27),"소재입고 마감("&TEXT($N27,"MM/DD")&") 초과",IF($Q27="","발행여부 확인 필요",IF($S27="","소재 입고일정 확인 필요","정상")))))) | AF27: =IF($K27="","",IF(OR(LEFT($AE27,2)="작지",LEFT($AE27,4)="소재입고"),IF(LEFT($G27,1)="S","★ 납기위험(S코드)","◆ 지연주의"),IF($AE27="정상","✓ 정상","? 확인필요")))
