Workbook

Sheet 사용안내
B2: 27FW 소재일정 역산 트래커 — 생진테 출고일 기준, 띤쨘·르바란 보정 (v1)
B4: 정렬 순서
B5: ① A코드(가을) 전체 — 납기상 최우선 그룹
B6: ② 비수기 선정 스타일(가을 제외) — 27FW 비수기 선정 수령 시 반영 예정 (현재 공란)
B7: ③ 나머지 W(겨울) → X(사계절) — 각 그룹 안에서는 출고일 주차 순
B9: 계산 로직
B10: ① 출고예정일 = 생진테 출고일 주차를 날짜로 환산 (1주=1일, 2주=8일, 3주=15일, 4주=22일 / 전 주차 2027년)
B11: ② 제품입고 시점 = 출고예정일 − 2주(14일). 입고시점이 생산국 휴무에 걸치면 휴무 전으로 앞당김
B12: ③ 소재입고 마감일 = 제품입고 시점 − 100일 − 공장휴무 보정일 (FW 난이도 반영, 27SS는 90일)
B13: ④ 공장휴무 보정: 생산기간(마감~입고)이 휴무와 겹친 일수만큼 마감 추가 앞당김 —
B14: 미얀마 생산분 = 띤쨘 4/9~4/18(10일), 인도네시아 생산분 = 르바란 3/4~3/17(14일). 기준정보에서 조정 가능
B15: ⑤ 작지 미발행(X/부분) 또는 소재입고일 > 마감일 → A코드(가을) '★ 납기위험', W/X '◆ 지연주의'
... B28: · 이월 품번 1건 포함: QYHFW25421 (25년 기획, 생진테 등재분)

Sheet 기준정보
B2: 기준정보 (노란색 = 조정 가능한 입력값)
B4: 기준일 (오늘) | C4: =TODAY() | D4: 판정 기준일. 파일 열 때 자동 갱신
B5: 입고 리드타임(일) | C5: 14 | D5: 출고예정일 − 2주 = 제품입고 시점
B6: 소재 리드타임(일) | C6: 100 | D6: 제품입고 시점 − 100일 = 소재입고 마감일 (FW 난이도 반영)
B7: 시즌 연도 | C7: 2027 | D7: 27FW 출고 주차는 전부 2027년으로 환산 (담당자 확정)
B8: 띤쨘 휴무 시작 | C8: 46486 | D8: 미얀마 생산분. 공휴일 4/13~17 + 앞뒤 생산처 추가 휴무
B9: 띤쨘 휴무 종료 | C9: 46495 | D9: 실제 공장별 휴무 확정 시 조정
B10: 르바란 휴무 시작 | C10: 46450 | D10: 인도네시아 생산분. Eid 3/10 전후 귀향(mudik) 포함 2주
B11: 르바란 휴무 종료 | C11: 46463 | D11: 실제 공장별 휴무 확정 시 조정
B13: 소재입고 책임 구분 (수/C/완 기준)
B14: C / CMT | C14: 본사(소재팀) 책임 — 소재 발주·입고 본사 컨트롤
B15: 완(완사입) / ODM | C15: 생산처 책임 — 생산처가 소재 수배·입고 컨트롤

Sheet 소재역산 트래커
A1: 27FW 소재일정 역산 트래커 — 정렬: A코드(가을) → 비수기 선정 → W→X (425 스타일)
A2: 기준일: | B2: =기준정보!$C$4 | C2: 리드타임: | D2: ="입고 "&기준정보!$C$5&"일 + 소재 "&기준정보!$C$6&"일 + 휴무보정" | G2: 노란색 = 입력 · ★ = A코드 작지 미발행/소재마감 초과 · 비수기/작지/사양확정/소재DB 열은 원본 수령 대기
A4: NO | B4: MD | C4: DS | D4: Style Code | E4: 품명 | F4: 컬러 구성 | G4: 시즌 | H4: 생산형태 (수/C/완) | I4: 출고일(주차) | J4: 출고예정일 | K4: 제품입고 시점 (출고-2주, 휴무 보정) | L4: 공장휴무 보정 (일) | M4: 소재입고 마감일 (입고-100일-보정) | N4: 마감까지 D-day | O4: 비수기 선정 (대기) | P4: 작지발행 (일매·EDW 대기) | Q4: 사양확정 (EDW 대기) | R4: 소재입고 예정/실제일 | S4: 소재입고 책임 | T4: 생산처 | U4: 원산지 | V4: 원단처 (소재DB 대기) | W4: 겉감정보 (대기) | X4: 안감정보 (대기) | Y4: LAB DIP CFM (대기) | Z4: 기획수량 | AA4: 원가합 (원) | AB4: 소매가합 (원) | AC4: 입고예정일 (생진테 참고) | AD4: 리스크 사유 | AE4: 판정 | AF4: 조율상태 | AG4: 메모/조치사항
A5: 1 | B5: 이재헌 | C5: 나영길 | D5: JKJJA27402 | E5: 여성 경량 후디드 방풍 재킷 | F5: ABE/EFL/DEB | G5: =IF($D5="","",IF(MID($D5,5,1)="A","A(가을)",IF(MID($D5,5,1)="W","W(겨울)",IF(MID($D5,5,1)="X","X(사계절)",MID($D5,5,1))))) | I5: 8월1주 | J5: =IF($I5="","",IFERROR(DATE(기준정보!$C$7,VALUE(LEFT($I5,FIND("월",$I5)-1)),1+7*(VALUE(SUBSTITUTE(MID($I5,FIND("월",$I5)+1,5),"주",""))-1)),"")) | K5: =IF($J5="","",IF(AND(ISNUMBER(SEARCH("미얀마",$U5)),$J5-기준정보!$C$5>=기준정보!$C$8,$J5-기준정보!$C$5<=기준정보!$C$9),기준정보!$C$8-1,IF(AND(ISNUMBER(SEARCH("인도네시아",$U5)),$J5-기준정보!$C$5>=기준정보!$C$10,$J5-기준정보!$C$5<=기준정보!$C$11),기준정보!$C$10-1,$J5-기준정보!$C$5))) | L5: =IF($K5="","",IF(ISNUMBER(SEARCH("미얀마",$U5)),MAX(0,MIN($K5,기준정보!$C$9)-MAX($K5-기준정보!$C$6,기준정보!$C$8)+1),IF(ISNUMBER(SEARCH("인도네시아",$U5)),MAX(0,MIN($K5,기준정보!$C$11)-MAX($K5-기준정보!$C$6,기준정보!$C$10)+1),0))) | M5: =IF($K5="","",$K5-기준정보!$C$6-$L5) | N5: =IF($M5="","",$M5-기준정보!$C$4) | S5: =IF($H5="","",IF($H5="C","본사(소재팀)",IF($H5="완","생산처","확인 필요"))) | T5: 기도 | U5: 베트남 | Z5: 300 | AA5: 20855400 | AB5: 66000000 | AD5: =IF($J5="","출고일 미정",IF($P5="X","작지 미발행",IF($P5="부분","작지 일부 미발행",IF(AND($R5<>"",$R5>$M5),"소재입고 마감("&TEXT($M5,"MM/DD")&") 초과",IF($P5="","발행여부 확인 필요",IF($R5="","소재 입고일정 확인 필요","정상")))))) | AE5: =IF($J5="","",IF(OR(LEFT($AD5,2)="작지",LEFT($AD5,4)="소재입고"),IF(LEFT($G5,1)="A","★ 납기위험(A코드)","◆ 지연주의"),IF($AD5="정상","✓ 정상","? 확인필요")))
A6: 2 | B6: 문도혁 | C6: 엄창용 | D6: JKPNA27612 | E6: 여성 릴렉스핏 벤틸레이션 팬츠 | F6: DEP/CTP | G6: =IF($D6="","",IF(MID($D6,5,1)="A","A(가을)",IF(MID($D6,5,1)="W","W(겨울)",IF(MID($D6,5,1)="X","X(사계절)",MID($D6,5,1))))) | I6: 8월1주 | J6: =IF($I6="","",IFERROR(DATE(기준정보!$C$7,VALUE(LEFT($I6,FIND("월",$I6)-1)),1+7*(VALUE(SUBSTITUTE(MID($I6,FIND("월",$I6)+1,5),"주",""))-1)),"")) | K6: =IF($J6="","",IF(AND(ISNUMBER(SEARCH("미얀마",$U6)),$J6-기준정보!$C$5>=기준정보!$C$8,$J6-기준정보!$C$5<=기준정보!$C$9),기준정보!$C$8-1,IF(AND(ISNUMBER(SEARCH("인도네시아",$U6)),$J6-기준정보!$C$5>=기준정보!$C$10,$J6-기준정보!$C$5<=기준정보!$C$11),기준정보!$C$10-1,$J6-기준정보!$C$5))) | L6: =IF($K6="","",IF(ISNUMBER(SEARCH("미얀마",$U6)),MAX(0,MIN($K6,기준정보!$C$9)-MAX($K6-기준정보!$C$6,기준정보!$C$8)+1),IF(ISNUMBER(SEARCH("인도네시아",$U6)),MAX(0,MIN($K6,기준정보!$C$11)-MAX($K6-기준정보!$C$6,기준정보!$C$10)+1),0))) | M6: =IF($K6="","",$K6-기준정보!$C$6-$L6) | N6: =IF($M6="","",$M6-기준정보!$C$4) | S6: =IF($H6="","",IF($H6="C","본사(소재팀)",IF($H6="완","생산처","확인 필요"))) | T6: TBO | U6: 베트남 | Z6: 400 | AA6: 17200000 | AB6: 88000000 | AD6: =IF($J6="","출고일 미정",IF($P6="X","작지 미발행",IF($P6="부분","작지 일부 미발행",IF(AND($R6<>"",$R6>$M6),"소재입고 마감("&TEXT($M6,"MM/DD")&") 초과",IF($P6="","발행여부 확인 필요",IF($R6="","소재 입고일정 확인 필요","정상")))))) | AE6: =IF($J6="","",IF(OR(LEFT($AD6,2)="작지",LEFT($AD6,4)="소재입고"),IF(LEFT($G6,1)="A","★ 납기위험(A코드)","◆ 지연주의"),IF($AD6="정상","✓ 정상","? 확인필요")))
A7: 3 | B7: 정영준 | C7: 엄창용 | D7: JKSXA27612 | E7: 여성 긴팔 스트라이프 셔츠 | F7: ABU/CHR | G7: =IF($D7="","",IF(MID($D7,5,1)="A","A(가을)",IF(MID($D7,5,1)="W","W(겨울)",IF(MID($D7,5,1)="X","X(사계절)",MID($D7,5,1))))) | I7: 8월1주 | J7: =IF($I7="","",IFERROR(DATE(기준정보!$C$7,VALUE(LEFT($I7,FIND("월",$I7)-1)),1+7*(VALUE(SUBSTITUTE(MID($I7,FIND("월",$I7)+1,5),"주",""))-1)),"")) | K7: =IF($J7="","",IF(AND(ISNUMBER(SEARCH("미얀마",$U7)),$J7-기준정보!$C$5>=기준정보!$C$8,$J7-기준정보!$C$5<=기준정보!$C$9),기준정보!$C$8-1,IF(AND(ISNUMBER(SEARCH("인도네시아",$U7)),$J7-기준정보!$C$5>=기준정보!$C$10,$J7-기준정보!$C$5<=기준정보!$C$11),기준정보!$C$10-1,$J7-기준정보!$C$5))) | L7: =IF($K7="","",IF(ISNUMBER(SEARCH("미얀마",$U7)),MAX(0,MIN($K7,기준정보!$C$9)-MAX($K7-기준정보!$C$6,기준정보!$C$8)+1),IF(ISNUMBER(SEARCH("인도네시아",$U7)),MAX(0,MIN($K7,기준정보!$C$11)-MAX($K7-기준정보!$C$6,기준정보!$C$10)+1),0))) | M7: =IF($K7="","",$K7-기준정보!$C$6-$L7) | N7: =IF($M7="","",$M7-기준정보!$C$4) | S7: =IF($H7="","",IF($H7="C","본사(소재팀)",IF($H7="완","생산처","확인 필요"))) | T7: 성원 | U7: 베트남 | Z7: 100 | AA7: 4800000 | AB7: 22000000 | AD7: =IF($J7="","출고일 미정",IF($P7="X","작지 미발행",IF($P7="부분","작지 일부 미발행",IF(AND($R7<>"",$R7>$M7),"소재입고 마감("&TEXT($M7,"MM/DD")&") 초과",IF($P7="","발행여부 확인 필요",IF($R7="","소재 입고일정 확인 필요","정상")))))) | AE7: =IF($J7="","",IF(OR(LEFT($AD7,2)="작지",LEFT($AD7,4)="소재입고"),IF(LEFT($G7,1)="A","★ 납기위험(A코드)","◆ 지연주의"),IF($AD7="정상","✓ 정상","? 확인필요")))
A8: 4 | B8: 정영준 | C8: 엄창용 | D8: JKTBA27612 | E8: 여성 긴팔 폴로 | F8: DEB/AWH | G8: =IF($D8="","",IF(MID($D8,5,1)="A","A(가을)",IF(MID($D8,5,1)="W","W(겨울)",IF(MID($D8,5,1)="X","X(사계절)",MID($D8,5,1))))) | I8: 8월1주 | J8: =IF($I8="","",IFERROR(DATE(기준정보!$C$7,VALUE(LEFT($I8,FIND("월",$I8)-1)),1+7*(VALUE(SUBSTITUTE(MID($I8,FIND("월",$I8)+1,5),"주",""))-1)),"")) | K8: =IF($J8="","",IF(AND(ISNUMBER(SEARCH("미얀마",$U8)),$J8-기준정보!$C$5>=기준정보!$C$8,$J8-기준정보!$C$5<=기준정보!$C$9),기준정보!$C$8-1,IF(AND(ISNUMBER(SEARCH("인도네시아",$U8)),$J8-기준정보!$C$5>=기준정보!$C$10,$J8-기준정보!$C$5<=기준정보!$C$11),기준정보!$C$10-1,$J8-기준정보!$C$5))) | L8: =IF($K8="","",IF(ISNUMBER(SEARCH("미얀마",$U8)),MAX(0,MIN($K8,기준정보!$C$9)-MAX($K8-기준정보!$C$6,기준정보!$C$8)+1),IF(ISNUMBER(SEARCH("인도네시아",$U8)),MAX(0,MIN($K8,기준정보!$C$11)-MAX($K8-기준정보!$C$6,기준정보!$C$10)+1),0))) | M8: =IF($K8="","",$K8-기준정보!$C$6-$L8) | N8: =IF($M8="","",$M8-기준정보!$C$4) | S8: =IF($H8="","",IF($H8="C","본사(소재팀)",IF($H8="완","생산처","확인 필요"))) | T8: IKG | U8: 인도네시아 | Z8: 100 | AA8: 2900000 | AB8: 15800000 | AD8: =IF($J8="","출고일 미정",IF($P8="X","작지 미발행",IF($P8="부분","작지 일부 미발행",IF(AND($R8<>"",$R8>$M8),"소재입고 마감("&TEXT($M8,"MM/DD")&") 초과",IF($P8="","발행여부 확인 필요",IF($R8="","소재 입고일정 확인 필요","정상")))))) | AE8: =IF($J8="","",IF(OR(LEFT($AD8,2)="작지",LEFT($AD8,4)="소재입고"),IF(LEFT($G8,1)="A","★ 납기위험(A코드)","◆ 지연주의"),IF($AD8="정상","✓ 정상","? 확인필요")))
A9: 5 | B9: 정영준 | C9: 엄창용 | D9: JKTCA27612 | E9: 여성 핫멜트 집업 폴로 반팔 티셔츠 | F9: CO1/CO2 | G9: =IF($D9="","",IF(MID($D9,5,1)="A","A(가을)",IF(MID($D9,5,1)="W","W(겨울)",IF(MID($D9,5,1)="X","X(사계절)",MID($D9,5,1))))) | I9: 8월1주 | J9: =IF($I9="","",IFERROR(DATE(기준정보!$C$7,VALUE(LEFT($I9,FIND("월",$I9)-1)),1+7*(VALUE(SUBSTITUTE(MID($I9,FIND("월",$I9)+1,5),"주",""))-1)),"")) | K9: =IF($J9="","",IF(AND(ISNUMBER(SEARCH("미얀마",$U9)),$J9-기준정보!$C$5>=기준정보!$C$8,$J9-기준정보!$C$5<=기준정보!$C$9),기준정보!$C$8-1,IF(AND(ISNUMBER(SEARCH("인도네시아",$U9)),$J9-기준정보!$C$5>=기준정보!$C$10,$J9-기준정보!$C$5<=기준정보!$C$11),기준정보!$C$10-1,$J9-기준정보!$C$5))) | L9: =IF($K9="","",IF(ISNUMBER(SEARCH("미얀마",$U9)),MAX(0,MIN($K9,기준정보!$C$9)-MAX($K9-기준정보!$C$6,기준정보!$C$8)+1),IF(ISNUMBER(SEARCH("인도네시아",$U9)),MAX(0,MIN($K9,기준정보!$C$11)-MAX($K9-기준정보!$C$6,기준정보!$C$10)+1),0))) | M9: =IF($K9="","",$K9-기준정보!$C$6-$L9) | N9: =IF($M9="","",$M9-기준정보!$C$4) | S9: =IF($H9="","",IF($H9="C","본사(소재팀)",IF($H9="완","생산처","확인 필요"))) | Z9: 500 | AA9: 9500000 | AB9: 69000000 | AD9: =IF($J9="","출고일 미정",IF($P9="X","작지 미발행",IF($P9="부분","작지 일부 미발행",IF(AND($R9<>"",$R9>$M9),"소재입고 마감("&TEXT($M9,"MM/DD")&") 초과",IF($P9="","발행여부 확인 필요",IF($R9="","소재 입고일정 확인 필요","정상")))))) | AE9: =IF($J9="","",IF(OR(LEFT($AD9,2)="작지",LEFT($AD9,4)="소재입고"),IF(LEFT($G9,1)="A","★ 납기위험(A코드)","◆ 지연주의"),IF($AD9="정상","✓ 정상","? 확인필요")))
A10: 6 | B10: 김준래 | C10: 엄창용 | D10: JNTBA27613 | E10: 남녀공용 로고 긴팔 라운드 티셔츠 | F10: AWH/DEB | G10: =IF($D10="","",IF(MID($D10,5,1)="A","A(가을)",IF(MID($D10,5,1)="W","W(겨울)",IF(MID($D10,5,1)="X","X(사계절)",MID($D10,5,1))))) | H10: 완 | I10: 8월1주 | J10: =IF($I10="","",IFERROR(DATE(기준정보!$C$7,VALUE(LEFT($I10,FIND("월",$I10)-1)),1+7*(VALUE(SUBSTITUTE(MID($I10,FIND("월",$I10)+1,5),"주",""))-1)),"")) | K10: =IF($J10="","",IF(AND(ISNUMBER(SEARCH("미얀마",$U10)),$J10-기준정보!$C$5>=기준정보!$C$8,$J10-기준정보!$C$5<=기준정보!$C$9),기준정보!$C$8-1,IF(AND(ISNUMBER(SEARCH("인도네시아",$U10)),$J10-기준정보!$C$5>=기준정보!$C$10,$J10-기준정보!$C$5<=기준정보!$C$11),기준정보!$C$10-1,$J10-기준정보!$C$5))) | L10: =IF($K10="","",IF(ISNUMBER(SEARCH("미얀마",$U10)),MAX(0,MIN($K10,기준정보!$C$9)-MAX($K10-기준정보!$C$6,기준정보!$C$8)+1),IF(ISNUMBER(SEARCH("인도네시아",$U10)),MAX(0,MIN($K10,기준정보!$C$11)-MAX($K10-기준정보!$C$6,기준정보!$C$10)+1),0))) | M10: =IF($K10="","",$K10-기준정보!$C$6-$L10) | N10: =IF($M10="","",$M10-기준정보!$C$4) | S10: =IF($H10="","",IF($H10="C","본사(소재팀)",IF($H10="완","생산처","확인 필요"))) | T10: IKG | U10: 인도네시아 | Z10: 1000 | AA10: 20698000 | AB10: 98000000 | AD10: =IF($J10="","출고일 미정",IF($P10="X","작지 미발행",IF($P10="부분","작지 일부 미발행",IF(AND($R10<>"",$R10>$M10),"소재입고 마감("&TEXT($M10,"MM/DD")&") 초과",IF($P10="","발행여부 확인 필요",IF($R10="","소재 입고일정 확인 필요","정상")))))) | AE10: =IF($J10="","",IF(OR(LEFT($AD10,2)="작지",LEFT($AD10,4)="소재입고"),IF(LEFT($G10,1)="A","★ 납기위험(A코드)","◆ 지연주의"),IF($AD10="정상","✓ 정상","? 확인필요")))
A11: 7 | B11: 김준래 | C11: 엄창용 | D11: JNTCA27617 | E11: 남녀공용 로고 반팔 라운드 티셔츠 | F11: CO1/CO2 | G11: =IF($D11="","",IF(MID($D11,5,1)="A","A(가을)",IF(MID($D11,5,1)="W","W(겨울)",IF(MID($D11,5,1)="X","X(사계절)",MID($D11,5,1))))) | H11: 완 | I11: 8월1주 | J11: =IF($I11="","",IFERROR(DATE(기준정보!$C$7,VALUE(LEFT($I11,FIND("월",$I11)-1)),1+7*(VALUE(SUBSTITUTE(MID($I11,FIND("월",$I11)+1,5),"주",""))-1)),"")) | K11: =IF($J11="","",IF(AND(ISNUMBER(SEARCH("미얀마",$U11)),$J11-기준정보!$C$5>=기준정보!$C$8,$J11-기준정보!$C$5<=기준정보!$C$9),기준정보!$C$8-1,IF(AND(ISNUMBER(SEARCH("인도네시아",$U11)),$J11-기준정보!$C$5>=기준정보!$C$10,$J11-기준정보!$C$5<=기준정보!$C$11),기준정보!$C$10-1,$J11-기준정보!$C$5))) | L11: =IF($K11="","",IF(ISNUMBER(SEARCH("미얀마",$U11)),MAX(0,MIN($K11,기준정보!$C$9)-MAX($K11-기준정보!$C$6,기준정보!$C$8)+1),IF(ISNUMBER(SEARCH("인도네시아",$U11)),MAX(0,MIN($K11,기준정보!$C$11)-MAX($K11-기준정보!$C$6,기준정보!$C$10)+1),0))) | M11: =IF($K11="","",$K11-기준정보!$C$6-$L11) | N11: =IF($M11="","",$M11-기준정보!$C$4) | S11: =IF($H11="","",IF($H11="C","본사(소재팀)",IF($H11="완","생산처","확인 필요"))) | T11: IKG | U11: 인도네시아 | Z11: 1000 | AA11: 15000000 | AB11: 88000000 | AD11: =IF($J11="","출고일 미정",IF($P11="X","작지 미발행",IF($P11="부분","작지 일부 미발행",IF(AND($R11<>"",$R11>$M11),"소재입고 마감("&TEXT($M11,"MM/DD")&") 초과",IF($P11="","발행여부 확인 필요",IF($R11="","소재 입고일정 확인 필요","정상")))))) | AE11: =IF($J11="","",IF(OR(LEFT($AD11,2)="작지",LEFT($AD11,4)="소재입고"),IF(LEFT($G11,1)="A","★ 납기위험(A코드)","◆ 지연주의"),IF($AD11="정상","✓ 정상","? 확인필요")))
A12: 8 | B12: 이재헌 | C12: 나영길 | D12: JWJJA27401 | E12: 남성 경량 후디드 방풍 재킷 | F12: ASB/NEG/DEB | G12: =IF($D12="","",IF(MID($D12,5,1)="A","A(가을)",IF(MID($D12,5,1)="W","W(겨울)",IF(MID($D12,5,1)="X","X(사계절)",MID($D12,5,1))))) | I12: 8월1주 | J12: =IF($I12="","",IFERROR(DATE(기준정보!$C$7,VALUE(LEFT($I12,FIND("월",$I12)-1)),1+7*(VALUE(SUBSTITUTE(MID($I12,FIND("월",$I12)+1,5),"주",""))-1)),"")) | K12: =IF($J12="","",IF(AND(ISNUMBER(SEARCH("미얀마",$U12)),$J12-기준정보!$C$5>=기준정보!$C$8,$J12-기준정보!$C$5<=기준정보!$C$9),기준정보!$C$8-1,IF(AND(ISNUMBER(SEARCH("인도네시아",$U12)),$J12-기준정보!$C$5>=기준정보!$C$10,$J12-기준정보!$C$5<=기준정보!$C$11),기준정보!$C$10-1,$J12-기준정보!$C$5))) | L12: =IF($K12="","",IF(ISNUMBER(SEARCH("미얀마",$U12)),MAX(0,MIN($K12,기준정보!$C$9)-MAX($K12-기준정보!$C$6,기준정보!$C$8)+1),IF(ISNUMBER(SEARCH("인도네시아",$U12)),MAX(0,MIN($K12,기준정보!$C$11)-MAX($K12-기준정보!$C$6,기준정보!$C$10)+1),0))) | M12: =IF($K12="","",$K12-기준정보!$C$6-$L12) | N12: =IF($M12="","",$M12-기준정보!$C$4) | S12: =IF($H12="","",IF($H12="C","본사(소재팀)",IF($H12="완","생산처","확인 필요"))) | T12: 기도 | U12: 베트남 | Z12: 900 | AA12: 64382400 | AB12: 198000000 | AD12: =IF($J12="","출고일 미정",IF($P12="X","작지 미발행",IF($P12="부분","작지 일부 미발행",IF(AND($R12<>"",$R12>$M12),"소재입고 마감("&TEXT($M12,"MM/DD")&") 초과",IF($P12="","발행여부 확인 필요",IF($R12="","소재 입고일정 확인 필요","정상")))))) | AE12: =IF($J12="","",IF(OR(LEFT($AD12,2)="작지",LEFT($AD12,4)="소재입고"),IF(LEFT($G12,1)="A","★ 납기위험(A코드)","◆ 지연주의"),IF($AD12="정상","✓ 정상","? 확인필요")))
A13: 9 | B13: 김준래 | C13: 강기환 | D13: JWSXA27611 | E13: 남성 스트라이프 집업 긴팔 셔츠 | F13: ABU/CHR | G13: =IF($D13="","",IF(MID($D13,5,1)="A","A(가을)",IF(MID($D13,5,1)="W","W(겨울)",IF(MID($D13,5,1)="X","X(사계절)",MID($D13,5,1))))) | H13: 완 | I13: 8월1주 | J13: =IF($I13="","",IFERROR(DATE(기준정보!$C$7,VALUE(LEFT($I13,FIND("월",$I13)-1)),1+7*(VALUE(SUBSTITUTE(MID($I13,FIND("월",$I13)+1,5),"주",""))-1)),"")) | K13: =IF($J13="","",IF(AND(ISNUMBER(SEARCH("미얀마",$U13)),$J13-기준정보!$C$5>=기준정보!$C$8,$J13-기준정보!$C$5<=기준정보!$C$9),기준정보!$C$8-1,IF(AND(ISNUMBER(SEARCH("인도네시아",$U13)),$J13-기준정보!$C$5>=기준정보!$C$10,$J13-기준정보!$C$5<=기준정보!$C$11),기준정보!$C$10-1,$J13-기준정보!$C$5))) | L13: =IF($K13="","",IF(ISNUMBER(SEARCH("미얀마",$U13)),MAX(0,MIN($K13,기준정보!$C$9)-MAX($K13-기준정보!$C$6,기준정보!$C$8)+1),IF(ISNUMBER(SEARCH("인도네시아",$U13)),MAX(0,MIN($K13,기준정보!$C$11)-MAX($K13-기준정보!$C$6,기준정보!$C$10)+1),0))) | M13: =IF($K13="","",$K13-기준정보!$C$6-$L13) | N13: =IF($M13="","",$M13-기준정보!$C$4) | S13: =IF($H13="","",IF($H13="C","본사(소재팀)",IF($H13="완","생산처","확인 필요"))) | T13: 성원 | U13: 베트남 | Z13: 600 | AA13: 30298800 | AB13: 162000000 | AD13: =IF($J13="","출고일 미정",IF($P13="X","작지 미발행",IF($P13="부분","작지 일부 미발행",IF(AND($R13<>"",$R13>$M13),"소재입고 마감("&TEXT($M13,"MM/DD")&") 초과",IF($P13="","발행여부 확인 필요",IF($R13="","소재 입고일정 확인 필요","정상")))))) | AE13: =IF($J13="","",IF(OR(LEFT($AD13,2)="작지",LEFT($AD13,4)="소재입고"),IF(LEFT($G13,1)="A","★ 납기위험(A코드)","◆ 지연주의"),IF($AD13="정상","✓ 정상","? 확인필요")))
A14: 10 | B14: 김준래 | C14: 강기환 | D14: JWTBA27611 | E14: 남성 메리노울 긴팔 폴로 | F14: PEG/DEB | G14: =IF($D14="","",IF(MID($D14,5,1)="A","A(가을)",IF(MID($D14,5,1)="W","W(겨울)",IF(MID($D14,5,1)="X","X(사계절)",MID($D14,5,1))))) | H14: 완 | I14: 8월1주 | J14: =IF($I14="","",IFERROR(DATE(기준정보!$C$7,VALUE(LEFT($I14,FIND("월",$I14)-1)),1+7*(VALUE(SUBSTITUTE(MID($I14,FIND("월",$I14)+1,5),"주",""))-1)),"")) | K14: =IF($J14="","",IF(AND(ISNUMBER(SEARCH("미얀마",$U14)),$J14-기준정보!$C$5>=기준정보!$C$8,$J14-기준정보!$C$5<=기준정보!$C$9),기준정보!$C$8-1,IF(AND(ISNUMBER(SEARCH("인도네시아",$U14)),$J14-기준정보!$C$5>=기준정보!$C$10,$J14-기준정보!$C$5<=기준정보!$C$11),기준정보!$C$10-1,$J14-기준정보!$C$5))) | L14: =IF($K14="","",IF(ISNUMBER(SEARCH("미얀마",$U14)),MAX(0,MIN($K14,기준정보!$C$9)-MAX($K14-기준정보!$C$6,기준정보!$C$8)+1),IF(ISNUMBER(SEARCH("인도네시아",$U14)),MAX(0,MIN($K14,기준정보!$C$11)-MAX($K14-기준정보!$C$6,기준정보!$C$10)+1),0))) | M14: =IF($K14="","",$K14-기준정보!$C$6-$L14) | N14: =IF($M14="","",$M14-기준정보!$C$4) | S14: =IF($H14="","",IF($H14="C","본사(소재팀)",IF($H14="완","생산처","확인 필요"))) | T14: IKG | U14: 인도네시아 | Z14: 900 | AA14: 44559000 | AB14: 178200000 | AD14: =IF($J14="","출고일 미정",IF($P14="X","작지 미발행",IF($P14="부분","작지 일부 미발행",IF(AND($R14<>"",$R14>$M14),"소재입고 마감("&TEXT($M14,"MM/DD")&") 초과",IF($P14="","발행여부 확인 필요",IF($R14="","소재 입고일정 확인 필요","정상")))))) | AE14: =IF($J14="","",IF(OR(LEFT($AD14,2)="작지",LEFT($AD14,4)="소재입고"),IF(LEFT($G14,1)="A","★ 납기위험(A코드)","◆ 지연주의"),IF($AD14="정상","✓ 정상","? 확인필요")))
A15: 11 | B15: 정영준 | C15: 엄창용 | D15: JWTCA27611 | E15: 남성 핫멜트 집업 폴로 반팔 티셔츠 | F15: CO1/CO2 | G15: =IF($D15="","",IF(MID($D15,5,1)="A","A(가을)",IF(MID($D15,5,1)="W","W(겨울)",IF(MID($D15,5,1)="X","X(사계절)",MID($D15,5,1))))) | I15: 8월1주 | J15: =IF($I15="","",IFERROR(DATE(기준정보!$C$7,VALUE(LEFT($I15,FIND("월",$I15)-1)),1+7*(VALUE(SUBSTITUTE(MID($I15,FIND("월",$I15)+1,5),"주",""))-1)),"")) | K15: =IF($J15="","",IF(AND(ISNUMBER(SEARCH("미얀마",$U15)),$J15-기준정보!$C$5>=기준정보!$C$8,$J15-기준정보!$C$5<=기준정보!$C$9),기준정보!$C$8-1,IF(AND(ISNUMBER(SEARCH("인도네시아",$U15)),$J15-기준정보!$C$5>=기준정보!$C$10,$J15-기준정보!$C$5<=기준정보!$C$11),기준정보!$C$10-1,$J15-기준정보!$C$5))) | L15: =IF($K15="","",IF(ISNUMBER(SEARCH("미얀마",$U15)),MAX(0,MIN($K15,기준정보!$C$9)-MAX($K15-기준정보!$C$6,기준정보!$C$8)+1),IF(ISNUMBER(SEARCH("인도네시아",$U15)),MAX(0,MIN($K15,기준정보!$C$11)-MAX($K15-기준정보!$C$6,기준정보!$C$10)+1),0))) | M15: =IF($K15="","",$K15-기준정보!$C$6-$L15) | N15: =IF($M15="","",$M15-기준정보!$C$4) | S15: =IF($H15="","",IF($H15="C","본사(소재팀)",IF($H15="완","생산처","확인 필요"))) | Z15: 700 | AA15: 14000000 | AB15: 96600000 | AD15: =IF($J15="","출고일 미정",IF($P15="X","작지 미발행",IF($P15="부분","작지 일부 미발행",IF(AND($R15<>"",$R15>$M15),"소재입고 마감("&TEXT($M15,"MM/DD")&") 초과",IF($P15="","발행여부 확인 필요",IF($R15="","소재 입고일정 확인 필요","정상")))))) | AE15: =IF($J15="","",IF(OR(LEFT($AD15,2)="작지",LEFT($AD15,4)="소재입고"),IF(LEFT($G15,1)="A","★ 납기위험(A코드)","◆ 지연주의"),IF($AD15="정상","✓ 정상","? 확인필요")))
A16: 12 | B16: 문도혁 | C16: 정희영 | D16: TLJJA27611 | E16: 남성 인후드 방풍 재킷 | F16: CTP/DTL/CHR | G16: =IF($D16="","",IF(MID($D16,5,1)="A","A(가을)",IF(MID($D16,5,1)="W","W(겨울)",IF(MID($D16,5,1)="X","X(사계절)",MID($D16,5,1))))) | H16: 완 | I16: 8월1주 | J16: =IF($I16="","",IFERROR(DATE(기준정보!$C$7,VALUE(LEFT($I16,FIND("월",$I16)-1)),1+7*(VALUE(SUBSTITUTE(MID($I16,FIND("월",$I16)+1,5),"주",""))-1)),"")) | K16: =IF($J16="","",IF(AND(ISNUMBER(SEARCH("미얀마",$U16)),$J16-기준정보!$C$5>=기준정보!$C$8,$J16-기준정보!$C$5<=기준정보!$C$9),기준정보!$C$8-1,IF(AND(ISNUMBER(SEARCH("인도네시아",$U16)),$J16-기준정보!$C$5>=기준정보!$C$10,$J16-기준정보!$C$5<=기준정보!$C$11),기준정보!$C$10-1,$J16-기준정보!$C$5))) | L16: =IF($K16="","",IF(ISNUMBER(SEARCH("미얀마",$U16)),MAX(0,MIN($K16,기준정보!$C$9)-MAX($K16-기준정보!$C$6,기준정보!$C$8)+1),IF(ISNUMBER(SEARCH("인도네시아",$U16)),MAX(0,MIN($K16,기준정보!$C$11)-MAX($K16-기준정보!$C$6,기준정보!$C$10)+1),0))) | M16: =IF($K16="","",$K16-기준정보!$C$6-$L16) | N16: =IF($M16="","",$M16-기준정보!$C$4) | S16: =IF($H16="","",IF($H16="C","본사(소재팀)",IF($H16="완","생산처","확인 필요"))) | T16: 아이블 | U16: 베트남 | Z16: 6000 | AA16: 311274000 | AB16: 1500000000 | AD16: =IF($J16="","출고일 미정",IF($P16="X","작지 미발행",IF($P16="부분","작지 일부 미발행",IF(AND($R16<>"",$R16>$M16),"소재입고 마감("&TEXT($M16,"MM/DD")&") 초과",IF($P16="","발행여부 확인 필요",IF($R16="","소재 입고일정 확인 필요","정상")))))) | AE16: =IF($J16="","",IF(OR(LEFT($AD16,2)="작지",LEFT($AD16,4)="소재입고"),IF(LEFT($G16,1)="A","★ 납기위험(A코드)","◆ 지연주의"),IF($AD16="정상","✓ 정상","? 확인필요")))
A17: 13 | B17: 문도혁 | C17: 정희영 | D17: TLJJA27621 | E17: 남성 소프트쉘 칼라넥 재킷 | F17: DOE/DEB | G17: =IF($D17="","",IF(MID($D17,5,1)="A","A(가을)",IF(MID($D17,5,1)="W","W(겨울)",IF(MID($D17,5,1)="X","X(사계절)",MID($D17,5,1))))) | H17: 완 | I17: 8월1주 | J17: =IF($I17="","",IFERROR(DATE(기준정보!$C$7,VALUE(LEFT($I17,FIND("월",$I17)-1)),1+7*(VALUE(SUBSTITUTE(MID($I17,FIND("월",$I17)+1,5),"주",""))-1)),"")) | K17: =IF($J17="","",IF(AND(ISNUMBER(SEARCH("미얀마",$U17)),$J17-기준정보!$C$5>=기준정보!$C$8,$J17-기준정보!$C$5<=기준정보!$C$9),기준정보!$C$8-1,IF(AND(ISNUMBER(SEARCH("인도네시아",$U17)),$J17-기준정보!$C$5>=기준정보!$C$10,$J17-기준정보!$C$5<=기준정보!$C$11),기준정보!$C$10-1,$J17-기준정보!$C$5))) | L17: =IF($K17="","",IF(ISNUMBER(SEARCH("미얀마",$U17)),MAX(0,MIN($K17,기준정보!$C$9)-MAX($K17-기준정보!$C$6,기준정보!$C$8)+1),IF(ISNUMBER(SEARCH("인도네시아",$U17)),MAX(0,MIN($K17,기준정보!$C$11)-MAX($K17-기준정보!$C$6,기준정보!$C$10)+1),0))) | M17: =IF($K17="","",$K17-기준정보!$C$6-$L17) | N17: =IF($M17="","",$M17-기준정보!$C$4) | S17: =IF($H17="","",IF($H17="C","본사(소재팀)",IF($H17="완","생산처","확인 필요"))) | T17: 원전 | U17: 인도네시아 | Z17: 3000 | AA17: 164781000 | AB17: 810000000 | AD17: =IF($J17="","출고일 미정",IF($P17="X","작지 미발행",IF($P17="부분","작지 일부 미발행",IF(AND($R17<>"",$R17>$M17),"소재입고 마감("&TEXT($M17,"MM/DD")&") 초과",IF($P17="","발행여부 확인 필요",IF($R17="","소재 입고일정 확인 필요","정상")))))) | AE17: =IF($J17="","",IF(OR(LEFT($AD17,2)="작지",LEFT($AD17,4)="소재입고"),IF(LEFT($G17,1)="A","★ 납기위험(A코드)","◆ 지연주의"),IF($AD17="정상","✓ 정상","? 확인필요")))
A18: 14 | B18: 김준래 | C18: 정희영 | D18: TLPNA27605 | E18: 남성 데님 스트레이트 팬츠 | F18: IND | G18: =IF($D18="","",IF(MID($D18,5,1)="A","A(가을)",IF(MID($D18,5,1)="W","W(겨울)",IF(MID($D18,5,1)="X","X(사계절)",MID($D18,5,1))))) | H18: 완 | I18: 8월1주 | J18: =IF($I18="","",IFERROR(DATE(기준정보!$C$7,VALUE(LEFT($I18,FIND("월",$I18)-1)),1+7*(VALUE(SUBSTITUTE(MID($I18,FIND("월",$I18)+1,5),"주",""))-1)),"")) | K18: =IF($J18="","",IF(AND(ISNUMBER(SEARCH("미얀마",$U18)),$J18-기준정보!$C$5>=기준정보!$C$8,$J18-기준정보!$C$5<=기준정보!$C$9),기준정보!$C$8-1,IF(AND(ISNUMBER(SEARCH("인도네시아",$U18)),$J18-기준정보!$C$5>=기준정보!$C$10,$J18-기준정보!$C$5<=기준정보!$C$11),기준정보!$C$10-1,$J18-기준정보!$C$5))) | L18: =IF($K18="","",IF(ISNUMBER(SEARCH("미얀마",$U18)),MAX(0,MIN($K18,기준정보!$C$9)-MAX($K18-기준정보!$C$6,기준정보!$C$8)+1),IF(ISNUMBER(SEARCH("인도네시아",$U18)),MAX(0,MIN($K18,기준정보!$C$11)-MAX($K18-기준정보!$C$6,기준정보!$C$10)+1),0))) | M18: =IF($K18="","",$K18-기준정보!$C$6-$L18) | N18: =IF($M18="","",$M18-기준정보!$C$4) | S18: =IF($H18="","",IF($H18="C","본사(소재팀)",IF($H18="완","생산처","확인 필요"))) | T18: 파란 | U18: 중국 | Z18: 1500 | AA18: 42000000 | AB18: 267000000 | AD18: =IF($J18="","출고일 미정",IF($P18="X","작지 미발행",IF($P18="부분","작지 일부 미발행",IF(AND($R18<>"",$R18>$M18),"소재입고 마감("&TEXT($M18,"MM/DD")&") 초과",IF($P18="","발행여부 확인 필요",IF($R18="","소재 입고일정 확인 필요","정상")))))) | AE18: =IF($J18="","",IF(OR(LEFT($AD18,2)="작지",LEFT($AD18,4)="소재입고"),IF(LEFT($G18,1)="A","★ 납기위험(A코드)","◆ 지연주의"),IF($AD18="정상","✓ 정상","? 확인필요")))
A19: 15 | B19: 김준래 | C19: 정희영 | D19: TLPNA27607 | E19: 남성 쿠션 릴렛스핏 팬츠 | F19: RBW/DEB | G19: =IF($D19="","",IF(MID($D19,5,1)="A","A(가을)",IF(MID($D19,5,1)="W","W(겨울)",IF(MID($D19,5,1)="X","X(사계절)",MID($D19,5,1))))) | H19: 완 | I19: 8월1주 | J19: =IF($I19="","",IFERROR(DATE(기준정보!$C$7,VALUE(LEFT($I19,FIND("월",$I19)-1)),1+7*(VALUE(SUBSTITUTE(MID($I19,FIND("월",$I19)+1,5),"주",""))-1)),"")) | K19: =IF($J19="","",IF(AND(ISNUMBER(SEARCH("미얀마",$U19)),$J19-기준정보!$C$5>=기준정보!$C$8,$J19-기준정보!$C$5<=기준정보!$C$9),기준정보!$C$8-1,IF(AND(ISNUMBER(SEARCH("인도네시아",$U19)),$J19-기준정보!$C$5>=기준정보!$C$10,$J19-기준정보!$C$5<=기준정보!$C$11),기준정보!$C$10-1,$J19-기준정보!$C$5))) | L19: =IF($K19="","",IF(ISNUMBER(SEARCH("미얀마",$U19)),MAX(0,MIN($K19,기준정보!$C$9)-MAX($K19-기준정보!$C$6,기준정보!$C$8)+1),IF(ISNUMBER(SEARCH("인도네시아",$U19)),MAX(0,MIN($K19,기준정보!$C$11)-MAX($K19-기준정보!$C$6,기준정보!$C$10)+1),0))) | M19: =IF($K19="","",$K19-기준정보!$C$6-$L19) | N19: =IF($M19="","",$M19-기준정보!$C$4) | S19: =IF($H19="","",IF($H19="C","본사(소재팀)",IF($H19="완","생산처","확인 필요"))) | T19: TESSELLATION | U19: 베트남 | Z19: 3000 | AA19: 89340000 | AB19: 444000000 | AD19: =IF($J19="","출고일 미정",IF($P19="X","작지 미발행",IF($P19="부분","작지 일부 미발행",IF(AND($R19<>"",$R19>$M19),"소재입고 마감("&TEXT($M19,"MM/DD")&") 초과",IF($P19="","발행여부 확인 필요",IF($R19="","소재 입고일정 확인 필요","정상")))))) | AE19: =IF($J19="","",IF(OR(LEFT($AD19,2)="작지",LEFT($AD19,4)="소재입고"),IF(LEFT($G19,1)="A","★ 납기위험(A코드)","◆ 지연주의"),IF($AD19="정상","✓ 정상","? 확인필요")))
A20: 16 | B20: 김준래 | C20: 정희영 | D20: TLPNA27609 | E20: 남성 트리코트 스트레이트 팬츠 | F20: CTP/MID | G20: =IF($D20="","",IF(MID($D20,5,1)="A","A(가을)",IF(MID($D20,5,1)="W","W(겨울)",IF(MID($D20,5,1)="X","X(사계절)",MID($D20,5,1))))) | H20: 완 | I20: 8월1주 | J20: =IF($I20="","",IFERROR(DATE(기준정보!$C$7,VALUE(LEFT($I20,FIND("월",$I20)-1)),1+7*(VALUE(SUBSTITUTE(MID($I20,FIND("월",$I20)+1,5),"주",""))-1)),"")) | K20: =IF($J20="","",IF(AND(ISNUMBER(SEARCH("미얀마",$U20)),$J20-기준정보!$C$5>=기준정보!$C$8,$J20-기준정보!$C$5<=기준정보!$C$9),기준정보!$C$8-1,IF(AND(ISNUMBER(SEARCH("인도네시아",$U20)),$J20-기준정보!$C$5>=기준정보!$C$10,$J20-기준정보!$C$5<=기준정보!$C$11),기준정보!$C$10-1,$J20-기준정보!$C$5))) | L20: =IF($K20="","",IF(ISNUMBER(SEARCH("미얀마",$U20)),MAX(0,MIN($K20,기준정보!$C$9)-MAX($K20-기준정보!$C$6,기준정보!$C$8)+1),IF(ISNUMBER(SEARCH("인도네시아",$U20)),MAX(0,MIN($K20,기준정보!$C$11)-MAX($K20-기준정보!$C$6,기준정보!$C$10)+1),0))) | M20: =IF($K20="","",$K20-기준정보!$C$6-$L20) | N20: =IF($M20="","",$M20-기준정보!$C$4) | S20: =IF($H20="","",IF($H20="C","본사(소재팀)",IF($H20="완","생산처","확인 필요"))) | T20: 거림 | U20: 베트남 | Z20: 1500 | AA20: 43552500 | AB20: 282000000 | AD20: =IF($J20="","출고일 미정",IF($P20="X","작지 미발행",IF($P20="부분","작지 일부 미발행",IF(AND($R20<>"",$R20>$M20),"소재입고 마감("&TEXT($M20,"MM/DD")&") 초과",IF($P20="","발행여부 확인 필요",IF($R20="","소재 입고일정 확인 필요","정상")))))) | AE20: =IF($J20="","",IF(OR(LEFT($AD20,2)="작지",LEFT($AD20,4)="소재입고"),IF(LEFT($G20,1)="A","★ 납기위험(A코드)","◆ 지연주의"),IF($AD20="정상","✓ 정상","? 확인필요")))
A21: 17 | B21: 김준래 | C21: 정희영 | D21: TLPNA27611 | E21: 남성 테이퍼드 팬츠 | F21: SKA/MID | G21: =IF($D21="","",IF(MID($D21,5,1)="A","A(가을)",IF(MID($D21,5,1)="W","W(겨울)",IF(MID($D21,5,1)="X","X(사계절)",MID($D21,5,1))))) | H21: 완 | I21: 8월1주 | J21: =IF($I21="","",IFERROR(DATE(기준정보!$C$7,VALUE(LEFT($I21,FIND("월",$I21)-1)),1+7*(VALUE(SUBSTITUTE(MID($I21,FIND("월",$I21)+1,5),"주",""))-1)),"")) | K21: =IF($J21="","",IF(AND(ISNUMBER(SEARCH("미얀마",$U21)),$J21-기준정보!$C$5>=기준정보!$C$8,$J21-기준정보!$C$5<=기준정보!$C$9),기준정보!$C$8-1,IF(AND(ISNUMBER(SEARCH("인도네시아",$U21)),$J21-기준정보!$C$5>=기준정보!$C$10,$J21-기준정보!$C$5<=기준정보!$C$11),기준정보!$C$10-1,$J21-기준정보!$C$5))) | L21: =IF($K21="","",IF(ISNUMBER(SEARCH("미얀마",$U21)),MAX(0,MIN($K21,기준정보!$C$9)-MAX($K21-기준정보!$C$6,기준정보!$C$8)+1),IF(ISNUMBER(SEARCH("인도네시아",$U21)),MAX(0,MIN($K21,기준정보!$C$11)-MAX($K21-기준정보!$C$6,기준정보!$C$10)+1),0))) | M21: =IF($K21="","",$K21-기준정보!$C$6-$L21) | N21: =IF($M21="","",$M21-기준정보!$C$4) | S21: =IF($H21="","",IF($H21="C","본사(소재팀)",IF($H21="완","생산처","확인 필요"))) | T21: TBO | U21: 베트남 | Z21: 2000 | AA21: 58974000 | AB21: 336000000 | AD21: =IF($J21="","출고일 미정",IF($P21="X","작지 미발행",IF($P21="부분","작지 일부 미발행",IF(AND($R21<>"",$R21>$M21),"소재입고 마감("&TEXT($M21,"MM/DD")&") 초과",IF($P21="","발행여부 확인 필요",IF($R21="","소재 입고일정 확인 필요","정상")))))) | AE21: =IF($J21="","",IF(OR(LEFT($AD21,2)="작지",LEFT($AD21,4)="소재입고"),IF(LEFT($G21,1)="A","★ 납기위험(A코드)","◆ 지연주의"),IF($AD21="정상","✓ 정상","? 확인필요")))
A22: 18 | B22: 김준래 | C22: 정희영 | D22: TLSXA27601 | E22: 남성 체크 긴팔 셔츠 | F22: ABE/ASB/DTL | G22: =IF($D22="","",IF(MID($D22,5,1)="A","A(가을)",IF(MID($D22,5,1)="W","W(겨울)",IF(MID($D22,5,1)="X","X(사계절)",MID($D22,5,1))))) | H22: 완 | I22: 8월1주 | J22: =IF($I22="","",IFERROR(DATE(기준정보!$C$7,VALUE(LEFT($I22,FIND("월",$I22)-1)),1+7*(VALUE(SUBSTITUTE(MID($I22,FIND("월",$I22)+1,5),"주",""))-1)),"")) | K22: =IF($J22="","",IF(AND(ISNUMBER(SEARCH("미얀마",$U22)),$J22-기준정보!$C$5>=기준정보!$C$8,$J22-기준정보!$C$5<=기준정보!$C$9),기준정보!$C$8-1,IF(AND(ISNUMBER(SEARCH("인도네시아",$U22)),$J22-기준정보!$C$5>=기준정보!$C$10,$J22-기준정보!$C$5<=기준정보!$C$11),기준정보!$C$10-1,$J22-기준정보!$C$5))) | L22: =IF($K22="","",IF(ISNUMBER(SEARCH("미얀마",$U22)),MAX(0,MIN($K22,기준정보!$C$9)-MAX($K22-기준정보!$C$6,기준정보!$C$8)+1),IF(ISNUMBER(SEARCH("인도네시아",$U22)),MAX(0,MIN($K22,기준정보!$C$11)-MAX($K22-기준정보!$C$6,기준정보!$C$10)+1),0))) | M22: =IF($K22="","",$K22-기준정보!$C$6-$L22) | N22: =IF($M22="","",$M22-기준정보!$C$4) | S22: =IF($H22="","",IF($H22="C","본사(소재팀)",IF($H22="완","생산처","확인 필요"))) | T22: 픽스쳐 | U22: 베트남 | Z22: 3000 | AA22: 90000000 | AB22: 504000000 | AD22: =IF($J22="","출고일 미정",IF($P22="X","작지 미발행",IF($P22="부분","작지 일부 미발행",IF(AND($R22<>"",$R22>$M22),"소재입고 마감("&TEXT($M22,"MM/DD")&") 초과",IF($P22="","발행여부 확인 필요",IF($R22="","소재 입고일정 확인 필요","정상")))))) | AE22: =IF($J22="","",IF(OR(LEFT($AD22,2)="작지",LEFT($AD22,4)="소재입고"),IF(LEFT($G22,1)="A","★ 납기위험(A코드)","◆ 지연주의"),IF($AD22="정상","✓ 정상","? 확인필요")))
A23: 19 | B23: 최진민 | C23: 조이슬 | D23: TLTBA27401 | E23: 남성 베이직 긴팔 쿼터집업 티셔츠 | F23: SKA/DTL/DEB | G23: =IF($D23="","",IF(MID($D23,5,1)="A","A(가을)",IF(MID($D23,5,1)="W","W(겨울)",IF(MID($D23,5,1)="X","X(사계절)",MID($D23,5,1))))) | I23: 8월1주 | J23: =IF($I23="","",IFERROR(DATE(기준정보!$C$7,VALUE(LEFT($I23,FIND("월",$I23)-1)),1+7*(VALUE(SUBSTITUTE(MID($I23,FIND("월",$I23)+1,5),"주",""))-1)),"")) | K23: =IF($J23="","",IF(AND(ISNUMBER(SEARCH("미얀마",$U23)),$J23-기준정보!$C$5>=기준정보!$C$8,$J23-기준정보!$C$5<=기준정보!$C$9),기준정보!$C$8-1,IF(AND(ISNUMBER(SEARCH("인도네시아",$U23)),$J23-기준정보!$C$5>=기준정보!$C$10,$J23-기준정보!$C$5<=기준정보!$C$11),기준정보!$C$10-1,$J23-기준정보!$C$5))) | L23: =IF($K23="","",IF(ISNUMBER(SEARCH("미얀마",$U23)),MAX(0,MIN($K23,기준정보!$C$9)-MAX($K23-기준정보!$C$6,기준정보!$C$8)+1),IF(ISNUMBER(SEARCH("인도네시아",$U23)),MAX(0,MIN($K23,기준정보!$C$11)-MAX($K23-기준정보!$C$6,기준정보!$C$10)+1),0))) | M23: =IF($K23="","",$K23-기준정보!$C$6-$L23) | N23: =IF($M23="","",$M23-기준정보!$C$4) | S23: =IF($H23="","",IF($H23="C","본사(소재팀)",IF($H23="완","생산처","확인 필요"))) | T23: 태화 | U23: 베트남 | Z23: 4500 | AA23: 112500000 | AB23: 576000000 | AD23: =IF($J23="","출고일 미정",IF($P23="X","작지 미발행",IF($P23="부분","작지 일부 미발행",IF(AND($R23<>"",$R23>$M23),"소재입고 마감("&TEXT($M23,"MM/DD")&") 초과",IF($P23="","발행여부 확인 필요",IF($R23="","소재 입고일정 확인 필요","정상")))))) | AE23: =IF($J23="","",IF(OR(LEFT($AD23,2)="작지",LEFT($AD23,4)="소재입고"),IF(LEFT($G23,1)="A","★ 납기위험(A코드)","◆ 지연주의"),IF($AD23="정상","✓ 정상","? 확인필요")))
A24: 20 | B24: 최진민 | C24: 조이슬 | D24: TLTBA27403 | E24: 남성 우븐 포켓 긴팔 쿼터집업 티셔츠 | F24: ASB/CHR | G24: =IF($D24="","",IF(MID($D24,5,1)="A","A(가을)",IF(MID($D24,5,1)="W","W(겨울)",IF(MID($D24,5,1)="X","X(사계절)",MID($D24,5,1))))) | I24: 8월1주 | J24: =IF($I24="","",IFERROR(DATE(기준정보!$C$7,VALUE(LEFT($I24,FIND("월",$I24)-1)),1+7*(VALUE(SUBSTITUTE(MID($I24,FIND("월",$I24)+1,5),"주",""))-1)),"")) | K24: =IF($J24="","",IF(AND(ISNUMBER(SEARCH("미얀마",$U24)),$J24-기준정보!$C$5>=기준정보!$C$8,$J24-기준정보!$C$5<=기준정보!$C$9),기준정보!$C$8-1,IF(AND(ISNUMBER(SEARCH("인도네시아",$U24)),$J24-기준정보!$C$5>=기준정보!$C$10,$J24-기준정보!$C$5<=기준정보!$C$11),기준정보!$C$10-1,$J24-기준정보!$C$5))) | L24: =IF($K24="","",IF(ISNUMBER(SEARCH("미얀마",$U24)),MAX(0,MIN($K24,기준정보!$C$9)-MAX($K24-기준정보!$C$6,기준정보!$C$8)+1),IF(ISNUMBER(SEARCH("인도네시아",$U24)),MAX(0,MIN($K24,기준정보!$C$11)-MAX($K24-기준정보!$C$6,기준정보!$C$10)+1),0))) | M24: =IF($K24="","",$K24-기준정보!$C$6-$L24) | N24: =IF($M24="","",$M24-기준정보!$C$4) | S24: =IF($H24="","",IF($H24="C","본사(소재팀)",IF($H24="완","생산처","확인 필요"))) | T24: 장안 | U24: 베트남 | Z24: 3000 | AA24: 78000000 | AB24: 414000000 | AD24: =IF($J24="","출고일 미정",IF($P24="X","작지 미발행",IF($P24="부분","작지 일부 미발행",IF(AND($R24<>"",$R24>$M24),"소재입고 마감("&TEXT($M24,"MM/DD")&") 초과",IF($P24="","발행여부 확인 필요",IF($R24="","소재 입고일정 확인 필요","정상")))))) | AE24: =IF($J24="","",IF(OR(LEFT($AD24,2)="작지",LEFT($AD24,4)="소재입고"),IF(LEFT($G24,1)="A","★ 납기위험(A코드)","◆ 지연주의"),IF($AD24="정상","✓ 정상","? 확인필요")))
A25: 21 | B25: 최진민 | C25: 조이슬 | D25: TLTBA27411 | E25: 남성 베이직 긴팔 라운드 티셔츠 | F25: CTP/DEB | G25: =IF($D25="","",IF(MID($D25,5,1)="A","A(가을)",IF(MID($D25,5,1)="W","W(겨울)",IF(MID($D25,5,1)="X","X(사계절)",MID($D25,5,1))))) | I25: 8월1주 | J25: =IF($I25="","",IFERROR(DATE(기준정보!$C$7,VALUE(LEFT($I25,FIND("월",$I25)-1)),1+7*(VALUE(SUBSTITUTE(MID($I25,FIND("월",$I25)+1,5),"주",""))-1)),"")) | K25: =IF($J25="","",IF(AND(ISNUMBER(SEARCH("미얀마",$U25)),$J25-기준정보!$C$5>=기준정보!$C$8,$J25-기준정보!$C$5<=기준정보!$C$9),기준정보!$C$8-1,IF(AND(ISNUMBER(SEARCH("인도네시아",$U25)),$J25-기준정보!$C$5>=기준정보!$C$10,$J25-기준정보!$C$5<=기준정보!$C$11),기준정보!$C$10-1,$J25-기준정보!$C$5))) | L25: =IF($K25="","",IF(ISNUMBER(SEARCH("미얀마",$U25)),MAX(0,MIN($K25,기준정보!$C$9)-MAX($K25-기준정보!$C$6,기준정보!$C$8)+1),IF(ISNUMBER(SEARCH("인도네시아",$U25)),MAX(0,MIN($K25,기준정보!$C$11)-MAX($K25-기준정보!$C$6,기준정보!$C$10)+1),0))) | M25: =IF($K25="","",$K25-기준정보!$C$6-$L25) | N25: =IF($M25="","",$M25-기준정보!$C$4) | S25: =IF($H25="","",IF($H25="C","본사(소재팀)",IF($H25="완","생산처","확인 필요"))) | T25: 장안 | U25: 베트남 | Z25: 1800 | AA25: 41400000 | AB25: 212400000 | AD25: =IF($J25="","출고일 미정",IF($P25="X","작지 미발행",IF($P25="부분","작지 일부 미발행",IF(AND($R25<>"",$R25>$M25),"소재입고 마감("&TEXT($M25,"MM/DD")&") 초과",IF($P25="","발행여부 확인 필요",IF($R25="","소재 입고일정 확인 필요","정상")))))) | AE25: =IF($J25="","",IF(OR(LEFT($AD25,2)="작지",LEFT($AD25,4)="소재입고"),IF(LEFT($G25,1)="A","★ 납기위험(A코드)","◆ 지연주의"),IF($AD25="정상","✓ 정상","? 확인필요")))
A26: 22 | B26: 최진민 | C26: 조이슬 | D26: TLTBA27421 | E26: 남성 울라이크 릴렉스핏 긴팔 후드 티셔츠 | F26: HYL/SKA | G26: =IF($D26="","",IF(MID($D26,5,1)="A","A(가을)",IF(MID($D26,5,1)="W","W(겨울)",IF(MID($D26,5,1)="X","X(사계절)",MID($D26,5,1))))) | I26: 8월1주 | J26: =IF($I26="","",IFERROR(DATE(기준정보!$C$7,VALUE(LEFT($I26,FIND("월",$I26)-1)),1+7*(VALUE(SUBSTITUTE(MID($I26,FIND("월",$I26)+1,5),"주",""))-1)),"")) | K26: =IF($J26="","",IF(AND(ISNUMBER(SEARCH("미얀마",$U26)),$J26-기준정보!$C$5>=기준정보!$C$8,$J26-기준정보!$C$5<=기준정보!$C$9),기준정보!$C$8-1,IF(AND(ISNUMBER(SEARCH("인도네시아",$U26)),$J26-기준정보!$C$5>=기준정보!$C$10,$J26-기준정보!$C$5<=기준정보!$C$11),기준정보!$C$10-1,$J26-기준정보!$C$5))) | L26: =IF($K26="","",IF(ISNUMBER(SEARCH("미얀마",$U26)),MAX(0,MIN($K26,기준정보!$C$9)-MAX($K26-기준정보!$C$6,기준정보!$C$8)+1),IF(ISNUMBER(SEARCH("인도네시아",$U26)),MAX(0,MIN($K26,기준정보!$C$11)-MAX($K26-기준정보!$C$6,기준정보!$C$10)+1),0))) | M26: =IF($K26="","",$K26-기준정보!$C$6-$L26) | N26: =IF($M26="","",$M26-기준정보!$C$4) | S26: =IF($H26="","",IF($H26="C","본사(소재팀)",IF($H26="완","생산처","확인 필요"))) | T26: 장안 | U26: 베트남 | Z26: 1500 | AA26: 48000000 | AB26: 222000000 | AD26: =IF($J26="","출고일 미정",IF($P26="X","작지 미발행",IF($P26="부분","작지 일부 미발행",IF(AND($R26<>"",$R26>$M26),"소재입고 마감("&TEXT($M26,"MM/DD")&") 초과",IF($P26="","발행여부 확인 필요",IF($R26="","소재 입고일정 확인 필요","정상")))))) | AE26: =IF($J26="","",IF(OR(LEFT($AD26,2)="작지",LEFT($AD26,4)="소재입고"),IF(LEFT($G26,1)="A","★ 납기위험(A코드)","◆ 지연주의"),IF($AD26="정상","✓ 정상","? 확인필요")))
A27: 23 | B27: 김준래 | C27: 정희영 | D27: TLTBA27601 | E27: 남성 폴로 긴팔 티셔츠 | F27: DTL/MID/ABE | G27: =IF($D27="","",IF(MID($D27,5,1)="A","A(가을)",IF(MID($D27,5,1)="W","W(겨울)",IF(MID($D27,5,1)="X","X(사계절)",MID($D27,5,1))))) | H27: 완 | I27: 8월1주 | J27: =IF($I27="","",IFERROR(DATE(기준정보!$C$7,VALUE(LEFT($I27,FIND("월",$I27)-1)),1+7*(VALUE(SUBSTITUTE(MID($I27,FIND("월",$I27)+1,5),"주",""))-1)),"")) | K27: =IF($J27="","",IF(AND(ISNUMBER(SEARCH("미얀마",$U27)),$J27-기준정보!$C$5>=기준정보!$C$8,$J27-기준정보!$C$5<=기준정보!$C$9),기준정보!$C$8-1,IF(AND(ISNUMBER(SEARCH("인도네시아",$U27)),$J27-기준정보!$C$5>=기준정보!$C$10,$J27-기준정보!$C$5<=기준정보!$C$11),기준정보!$C$10-1,$J27-기준정보!$C$5))) | L27: =IF($K27="","",IF(ISNUMBER(SEARCH("미얀마",$U27)),MAX(0,MIN($K27,기준정보!$C$9)-MAX($K27-기준정보!$C$6,기준정보!$C$8)+1),IF(ISNUMBER(SEARCH("인도네시아",$U27)),MAX(0,MIN($K27,기준정보!$C$11)-MAX($K27-기준정보!$C$6,기준정보!$C$10)+1),0))) | M27: =IF($K27="","",$K27-기준정보!$C$6-$L27) | N27: =IF($M27="","",$M27-기준정보!$C$4) | S27: =IF($H27="","",IF($H27="C","본사(소재팀)",IF($H27="완","생산처","확인 필요"))) | T27: TESSELLATION | U27: 베트남 | Z27: 5000 | AA27: 131340000 | AB27: 640000000 | AD27: =IF($J27="","출고일 미정",IF($P27="X","작지 미발행",IF($P27="부분","작지 일부 미발행",IF(AND($R27<>"",$R27>$M27),"소재입고 마감("&TEXT($M27,"MM/DD")&") 초과",IF($P27="","발행여부 확인 필요",IF($R27="","소재 입고일정 확인 필요","정상")))))) | AE27: =IF($J27="","",IF(OR(LEFT($AD27,2)="작지",LEFT($AD27,4)="소재입고"),IF(LEFT($G27,1)="A","★ 납기위험(A코드)","◆ 지연주의"),IF($AD27="정상","✓ 정상","? 확인필요")))
A28: 24 | B28: 김준래 | C28: 정희영 | D28: TLTBA27603 | E28: 남성 패턴 폴로 긴팔 티셔츠 | F28: SKA/CHR | G28: =IF($D28="","",IF(MID($D28,5,1)="A","A(가을)",IF(MID($D28,5,1)="W","W(겨울)",IF(MID($D28,5,1)="X","X(사계절)",MID($D28,5,1))))) | H28: 완 | I28: 8월1주 | J28: =IF($I28="","",IFERROR(DATE(기준정보!$C$7,VALUE(LEFT($I28,FIND("월",$I28)-1)),1+7*(VALUE(SUBSTITUTE(MID($I28,FIND("월",$I28)+1,5),"주",""))-1)),"")) | K28: =IF($J28="","",IF(AND(ISNUMBER(SEARCH("미얀마",$U28)),$J28-기준정보!$C$5>=기준정보!$C$8,$J28-기준정보!$C$5<=기준정보!$C$9),기준정보!$C$8-1,IF(AND(ISNUMBER(SEARCH("인도네시아",$U28)),$J28-기준정보!$C$5>=기준정보!$C$10,$J28-기준정보!$C$5<=기준정보!$C$11),기준정보!$C$10-1,$J28-기준정보!$C$5))) | L28: =IF($K28="","",IF(ISNUMBER(SEARCH("미얀마",$U28)),MAX(0,MIN($K28,기준정보!$C$9)-MAX($K28-기준정보!$C$6,기준정보!$C$8)+1),IF(ISNUMBER(SEARCH("인도네시아",$U28)),MAX(0,MIN($K28,기준정보!$C$11)-MAX($K28-기준정보!$C$6,기준정보!$C$10)+1),0))) | M28: =IF($K28="","",$K28-기준정보!$C$6-$L28) | N28: =IF($M28="","",$M28-기준정보!$C$4) | S28: =IF($H28="","",IF($H28="C","본사(소재팀)",IF($H28="완","생산처","확인 필요"))) | T28: 장안 | U28: 베트남 | Z28: 5000 | AA28: 134310000 | AB28: 690000000 | AD28: =IF($J28="","출고일 미정",IF($P28="X","작지 미발행",IF($P28="부분","작지 일부 미발행",IF(AND($R28<>"",$R28>$M28),"소재입고 마감("&TEXT($M28,"MM/DD")&") 초과",IF($P28="","발행여부 확인 필요",IF($R28="","소재 입고일정 확인 필요","정상")))))) | AE28: =IF($J28="","",IF(OR(LEFT($AD28,2)="작지",LEFT($AD28,4)="소재입고"),IF(LEFT($G28,1)="A","★ 납기위험(A코드)","◆ 지연주의"),IF($AD28="정상","✓ 정상","? 확인필요")))
A29: 25 | B29: 김준래 | C29: 정희영 | D29: TLTBA27621 | E29: 남성 소프트필 폴로 긴팔 티셔츠 | F29: ABU/DEB | G29: =IF($D29="","",IF(MID($D29,5,1)="A","A(가을)",IF(MID($D29,5,1)="W","W(겨울)",IF(MID($D29,5,1)="X","X(사계절)",MID($D29,5,1))))) | H29: 완 | I29: 8월1주 | J29: =IF($I29="","",IFERROR(DATE(기준정보!$C$7,VALUE(LEFT($I29,FIND("월",$I29)-1)),1+7*(VALUE(SUBSTITUTE(MID($I29,FIND("월",$I29)+1,5),"주",""))-1)),"")) | K29: =IF($J29="","",IF(AND(ISNUMBER(SEARCH("미얀마",$U29)),$J29-기준정보!$C$5>=기준정보!$C$8,$J29-기준정보!$C$5<=기준정보!$C$9),기준정보!$C$8-1,IF(AND(ISNUMBER(SEARCH("인도네시아",$U29)),$J29-기준정보!$C$5>=기준정보!$C$10,$J29-기준정보!$C$5<=기준정보!$C$11),기준정보!$C$10-1,$J29-기준정보!$C$5))) | L29: =IF($K29="","",IF(ISNUMBER(SEARCH("미얀마",$U29)),MAX(0,MIN($K29,기준정보!$C$9)-MAX($K29-기준정보!$C$6,기준정보!$C$8)+1),IF(ISNUMBER(SEARCH("인도네시아",$U29)),MAX(0,MIN($K29,기준정보!$C$11)-MAX($K29-기준정보!$C$6,기준정보!$C$10)+1),0))) | M29: =IF($K29="","",$K29-기준정보!$C$6-$L29) | N29: =IF($M29="","",$M29-기준정보!$C$4) | S29: =IF($H29="","",IF($H29="C","본사(소재팀)",IF($H29="완","생산처","확인 필요"))) | T29: IKG | U29: 인도네시아 | Z29: 5000 | AA29: 98560000 | AB29: 690000000 | AD29: =IF($J29="","출고일 미정",IF($P29="X","작지 미발행",IF($P29="부분","작지 일부 미발행",IF(AND($R29<>"",$R29>$M29),"소재입고 마감("&TEXT($M29,"MM/DD")&") 초과",IF($P29="","발행여부 확인 필요",IF($R29="","소재 입고일정 확인 필요","정상")))))) | AE29: =IF($J29="","",IF(OR(LEFT($AD29,2)="작지",LEFT($AD29,4)="소재입고"),IF(LEFT($G29,1)="A","★ 납기위험(A코드)","◆ 지연주의"),IF($AD29="정상","✓ 정상","? 확인필요")))
A30: 26 | B30: 김준래 | C30: 정희영 | D30: TNTBA27605 | E30: 남녀공용 쿠션 라운드 티셔츠 | F30: GBU/DEB | G30: =IF($D30="","",IF(MID($D30,5,1)="A","A(가을)",IF(MID($D30,5,1)="W","W(겨울)",IF(MID($D30,5,1)="X","X(사계절)",MID($D30,5,1))))) | H30: 완 | I30: 8월1주 | J30: =IF($I30="","",IFERROR(DATE(기준정보!$C$7,VALUE(LEFT($I30,FIND("월",$I30)-1)),1+7*(VALUE(SUBSTITUTE(MID($I30,FIND("월",$I30)+1,5),"주",""))-1)),"")) | K30: =IF($J30="","",IF(AND(ISNUMBER(SEARCH("미얀마",$U30)),$J30-기준정보!$C$5>=기준정보!$C$8,$J30-기준정보!$C$5<=기준정보!$C$9),기준정보!$C$8-1,IF(AND(ISNUMBER(SEARCH("인도네시아",$U30)),$J30-기준정보!$C$5>=기준정보!$C$10,$J30-기준정보!$C$5<=기준정보!$C$11),기준정보!$C$10-1,$J30-기준정보!$C$5))) | L30: =IF($K30="","",IF(ISNUMBER(SEARCH("미얀마",$U30)),MAX(0,MIN($K30,기준정보!$C$9)-MAX($K30-기준정보!$C$6,기준정보!$C$8)+1),IF(ISNUMBER(SEARCH("인도네시아",$U30)),MAX(0,MIN($K30,기준정보!$C$11)-MAX($K30-기준정보!$C$6,기준정보!$C$10)+1),0))) | M30: =IF($K30="","",$K30-기준정보!$C$6-$L30) | N30: =IF($M30="","",$M30-기준정보!$C$4) | S30: =IF($H30="","",IF($H30="C","본사(소재팀)",IF($H30="완","생산처","확인 필요"))) | T30: TESSELLATION | U30: 베트남 | Z30: 2000 | AA30: 52938000 | AB30: 276000000 | AD30: =IF($J30="","출고일 미정",IF($P30="X","작지 미발행",IF($P30="부분","작지 일부 미발행",IF(AND($R30<>"",$R30>$M30),"소재입고 마감("&TEXT($M30,"MM/DD")&") 초과",IF($P30="","발행여부 확인 필요",IF($R30="","소재 입고일정 확인 필요","정상")))))) | AE30: =IF($J30="","",IF(OR(LEFT($AD30,2)="작지",LEFT($AD30,4)="소재입고"),IF(LEFT($G30,1)="A","★ 납기위험(A코드)","◆ 지연주의"),IF($AD30="정상","✓ 정상","? 확인필요")))
A31: 27 | B31: 김준래 | C31: 정희영 | D31: TNTBA27607 | E31: 남녀공용 쿠션 후디드 긴팔 티셔츠 | F31: RBW/DEB | G31: =IF($D31="","",IF(MID($D31,5,1)="A","A(가을)",IF(MID($D31,5,1)="W","W(겨울)",IF(MID($D31,5,1)="X","X(사계절)",MID($D31,5,1))))) | H31: 완 | I31: 8월1주 | J31: =IF($I31="","",IFERROR(DATE(기준정보!$C$7,VALUE(LEFT($I31,FIND("월",$I31)-1)),1+7*(VALUE(SUBSTITUTE(MID($I31,FIND("월",$I31)+1,5),"주",""))-1)),"")) | K31: =IF($J31="","",IF(AND(ISNUMBER(SEARCH("미얀마",$U31)),$J31-기준정보!$C$5>=기준정보!$C$8,$J31-기준정보!$C$5<=기준정보!$C$9),기준정보!$C$8-1,IF(AND(ISNUMBER(SEARCH("인도네시아",$U31)),$J31-기준정보!$C$5>=기준정보!$C$10,$J31-기준정보!$C$5<=기준정보!$C$11),기준정보!$C$10-1,$J31-기준정보!$C$5))) | L31: =IF($K31="","",IF(ISNUMBER(SEARCH("미얀마",$U31)),MAX(0,MIN($K31,기준정보!$C$9)-MAX($K31-기준정보!$C$6,기준정보!$C$8)+1),IF(ISNUMBER(SEARCH("인도네시아",$U31)),MAX(0,MIN($K31,기준정보!$C$11)-MAX($K31-기준정보!$C$6,기준정보!$C$10)+1),0))) | M31: =IF($K31="","",$K31-기준정보!$C$6-$L31) | N31: =IF($M31="","",$M31-기준정보!$C$4) | S31: =IF($H31="","",IF($H31="C","본사(소재팀)",IF($H31="완","생산처","확인 필요"))) | T31: TESSELLATION | U31: 베트남 | Z31: 3000 | AA31: 104736000 | AB31: 504000000 | AD31: =IF($J31="","출고일 미정",IF($P31="X","작지 미발행",IF($P31="부분","작지 일부 미발행",IF(AND($R31<>"",$R31>$M31),"소재입고 마감("&TEXT($M31,"MM/DD")&") 초과",IF($P31="","발행여부 확인 필요",IF($R31="","소재 입고일정 확인 필요","정상")))))) | AE31: =IF($J31="","",IF(OR(LEFT($AD31,2)="작지",LEFT($AD31,4)="소재입고"),IF(LEFT($G31,1)="A","★ 납기위험(A코드)","◆ 지연주의"),IF($AD31="정상","✓ 정상","? 확인필요")))
A32: 28 | B32: 정영준 | C32: 서은미 | D32: TVJJA27612 | E32: 여성 중기장 후디드 재킷 | F32: GBU/DEB | G32: =IF($D32="","",IF(MID($D32,5,1)="A","A(가을)",IF(MID($D32,5,1)="W","W(겨울)",IF(MID($D32,5,1)="X","X(사계절)",MID($D32,5,1))))) | I32: 8월1주 | J32: =IF($I32="","",IFERROR(DATE(기준정보!$C$7,VALUE(LEFT($I32,FIND("월",$I32)-1)),1+7*(VALUE(SUBSTITUTE(MID($I32,FIND("월",$I32)+1,5),"주",""))-1)),"")) | K32: =IF($J32="","",IF(AND(ISNUMBER(SEARCH("미얀마",$U32)),$J32-기준정보!$C$5>=기준정보!$C$8,$J32-기준정보!$C$5<=기준정보!$C$9),기준정보!$C$8-1,IF(AND(ISNUMBER(SEARCH("인도네시아",$U32)),$J32-기준정보!$C$5>=기준정보!$C$10,$J32-기준정보!$C$5<=기준정보!$C$11),기준정보!$C$10-1,$J32-기준정보!$C$5))) | L32: =IF($K32="","",IF(ISNUMBER(SEARCH("미얀마",$U32)),MAX(0,MIN($K32,기준정보!$C$9)-MAX($K32-기준정보!$C$6,기준정보!$C$8)+1),IF(ISNUMBER(SEARCH("인도네시아",$U32)),MAX(0,MIN($K32,기준정보!$C$11)-MAX($K32-기준정보!$C$6,기준정보!$C$10)+1),0))) | M32: =IF($K32="","",$K32-기준정보!$C$6-$L32) | N32: =IF($M32="","",$M32-기준정보!$C$4) | S32: =IF($H32="","",IF($H32="C","본사(소재팀)",IF($H32="완","생산처","확인 필요"))) | T32: 아이블 | U32: 베트남 | Z32: 3000 | AA32: 144000000 | AB32: 660000000 | AD32: =IF($J32="","출고일 미정",IF($P32="X","작지 미발행",IF($P32="부분","작지 일부 미발행",IF(AND($R32<>"",$R32>$M32),"소재입고 마감("&TEXT($M32,"MM/DD")&") 초과",IF($P32="","발행여부 확인 필요",IF($R32="","소재 입고일정 확인 필요","정상")))))) | AE32: =IF($J32="","",IF(OR(LEFT($AD32,2)="작지",LEFT($AD32,4)="소재입고"),IF(LEFT($G32,1)="A","★ 납기위험(A코드)","◆ 지연주의"),IF($AD32="정상","✓ 정상","? 확인필요")))
A33: 29 | B33: 정영준 | C33: 서은미 | D33: TVJJA27622 | E33: 여성 중기장 스탠드넥 재킷 | F33: CO1/CO2 | G33: =IF($D33="","",IF(MID($D33,5,1)="A","A(가을)",IF(MID($D33,5,1)="W","W(겨울)",IF(MID($D33,5,1)="X","X(사계절)",MID($D33,5,1))))) | I33: 8월1주 | J33: =IF($I33="","",IFERROR(DATE(기준정보!$C$7,VALUE(LEFT($I33,FIND("월",$I33)-1)),1+7*(VALUE(SUBSTITUTE(MID($I33,FIND("월",$I33)+1,5),"주",""))-1)),"")) | K33: =IF($J33="","",IF(AND(ISNUMBER(SEARCH("미얀마",$U33)),$J33-기준정보!$C$5>=기준정보!$C$8,$J33-기준정보!$C$5<=기준정보!$C$9),기준정보!$C$8-1,IF(AND(ISNUMBER(SEARCH("인도네시아",$U33)),$J33-기준정보!$C$5>=기준정보!$C$10,$J33-기준정보!$C$5<=기준정보!$C$11),기준정보!$C$10-1,$J33-기준정보!$C$5))) | L33: =IF($K33="","",IF(ISNUMBER(SEARCH("미얀마",$U33)),MAX(0,MIN($K33,기준정보!$C$9)-MAX($K33-기준정보!$C$6,기준정보!$C$8)+1),IF(ISNUMBER(SEARCH("인도네시아",$U33)),MAX(0,MIN($K33,기준정보!$C$11)-MAX($K33-기준정보!$C$6,기준정보!$C$10)+1),0))) | M33: =IF($K33="","",$K33-기준정보!$C$6-$L33) | N33: =IF($M33="","",$M33-기준정보!$C$4) | S33: =IF($H33="","",IF($H33="C","본사(소재팀)",IF($H33="완","생산처","확인 필요"))) | T33: 포마트 | U33: 베트남 | Z33: 4000 | AA33: 160000000 | AB33: 792000000 | AD33: =IF($J33="","출고일 미정",IF($P33="X","작지 미발행",IF($P33="부분","작지 일부 미발행",IF(AND($R33<>"",$R33>$M33),"소재입고 마감("&TEXT($M33,"MM/DD")&") 초과",IF($P33="","발행여부 확인 필요",IF($R33="","소재 입고일정 확인 필요","정상")))))) | AE33: =IF($J33="","",IF(OR(LEFT($AD33,2)="작지",LEFT($AD33,4)="소재입고"),IF(LEFT($G33,1)="A","★ 납기위험(A코드)","◆ 지연주의"),IF($AD33="정상","✓ 정상","? 확인필요")))
A34: 30 | B34: 문도혁 | C34: 서은미 | D34: TVPNA27604 | E34: 여성 트리코트 팬츠 | F34: CHR/DBE | G34: =IF($D34="","",IF(MID($D34,5,1)="A","A(가을)",IF(MID($D34,5,1)="W","W(겨울)",IF(MID($D34,5,1)="X","X(사계절)",MID($D34,5,1))))) | H34: C | I34: 8월1주 | J34: =IF($I34="","",IFERROR(DATE(기준정보!$C$7,VALUE(LEFT($I34,FIND("월",$I34)-1)),1+7*(VALUE(SUBSTITUTE(MID($I34,FIND("월",$I34)+1,5),"주",""))-1)),"")) | K34: =IF($J34="","",IF(AND(ISNUMBER(SEARCH("미얀마",$U34)),$J34-기준정보!$C$5>=기준정보!$C$8,$J34-기준정보!$C$5<=기준정보!$C$9),기준정보!$C$8-1,IF(AND(ISNUMBER(SEARCH("인도네시아",$U34)),$J34-기준정보!$C$5>=기준정보!$C$10,$J34-기준정보!$C$5<=기준정보!$C$11),기준정보!$C$10-1,$J34-기준정보!$C$5))) | L34: =IF($K34="","",IF(ISNUMBER(SEARCH("미얀마",$U34)),MAX(0,MIN($K34,기준정보!$C$9)-MAX($K34-기준정보!$C$6,기준정보!$C$8)+1),IF(ISNUMBER(SEARCH("인도네시아",$U34)),MAX(0,MIN($K34,기준정보!$C$11)-MAX($K34-기준정보!$C$6,기준정보!$C$10)+1),0))) | M34: =IF($K34="","",$K34-기준정보!$C$6-$L34) | N34: =IF($M34="","",$M34-기준정보!$C$4) | S34: =IF($H34="","",IF($H34="C","본사(소재팀)",IF($H34="완","생산처","확인 필요"))) | T34: 거림 | U34: 베트남 | Z34: 1500 | AA34: 49314000 | AB34: 267000000 | AD34: =IF($J34="","출고일 미정",IF($P34="X","작지 미발행",IF($P34="부분","작지 일부 미발행",IF(AND($R34<>"",$R34>$M34),"소재입고 마감("&TEXT($M34,"MM/DD")&") 초과",IF($P34="","발행여부 확인 필요",IF($R34="","소재 입고일정 확인 필요","정상")))))) | AE34: =IF($J34="","",IF(OR(LEFT($AD34,2)="작지",LEFT($AD34,4)="소재입고"),IF(LEFT($G34,1)="A","★ 납기위험(A코드)","◆ 지연주의"),IF($AD34="정상","✓ 정상","? 확인필요")))
A35: 31 | B35: 문도혁 | C35: 서은미 | D35: TVPNA27606 | E35: 여성 데님 팬츠 | F35: IND | G35: =IF($D35="","",IF(MID($D35,5,1)="A","A(가을)",IF(MID($D35,5,1)="W","W(겨울)",IF(MID($D35,5,1)="X","X(사계절)",MID($D35,5,1))))) | H35: 완 | I35: 8월1주 | J35: =IF($I35="","",IFERROR(DATE(기준정보!$C$7,VALUE(LEFT($I35,FIND("월",$I35)-1)),1+7*(VALUE(SUBSTITUTE(MID($I35,FIND("월",$I35)+1,5),"주",""))-1)),"")) | K35: =IF($J35="","",IF(AND(ISNUMBER(SEARCH("미얀마",$U35)),$J35-기준정보!$C$5>=기준정보!$C$8,$J35-기준정보!$C$5<=기준정보!$C$9),기준정보!$C$8-1,IF(AND(ISNUMBER(SEARCH("인도네시아",$U35)),$J35-기준정보!$C$5>=기준정보!$C$10,$J35-기준정보!$C$5<=기준정보!$C$11),기준정보!$C$10-1,$J35-기준정보!$C$5))) | L35: =IF($K35="","",IF(ISNUMBER(SEARCH("미얀마",$U35)),MAX(0,MIN($K35,기준정보!$C$9)-MAX($K35-기준정보!$C$6,기준정보!$C$8)+1),IF(ISNUMBER(SEARCH("인도네시아",$U35)),MAX(0,MIN($K35,기준정보!$C$11)-MAX($K35-기준정보!$C$6,기준정보!$C$10)+1),0))) | M35: =IF($K35="","",$K35-기준정보!$C$6-$L35) | N35: =IF($M35="","",$M35-기준정보!$C$4) | S35: =IF($H35="","",IF($H35="C","본사(소재팀)",IF($H35="완","생산처","확인 필요"))) | T35: 파란 | U35: 중국 | Z35: 1500 | AA35: 57000000 | AB35: 282000000 | AD35: =IF($J35="","출고일 미정",IF($P35="X","작지 미발행",IF($P35="부분","작지 일부 미발행",IF(AND($R35<>"",$R35>$M35),"소재입고 마감("&TEXT($M35,"MM/DD")&") 초과",IF($P35="","발행여부 확인 필요",IF($R35="","소재 입고일정 확인 필요","정상")))))) | AE35: =IF($J35="","",IF(OR(LEFT($AD35,2)="작지",LEFT($AD35,4)="소재입고"),IF(LEFT($G35,1)="A","★ 납기위험(A코드)","◆ 지연주의"),IF($AD35="정상","✓ 정상","? 확인필요")))
A36: 32 | B36: 문도혁 | C36: 서은미 | D36: TVPNA27608 | E36: 여성 부츠컷 팬츠 | F36: DNV/DEB | G36: =IF($D36="","",IF(MID($D36,5,1)="A","A(가을)",IF(MID($D36,5,1)="W","W(겨울)",IF(MID($D36,5,1)="X","X(사계절)",MID($D36,5,1))))) | H36: C | I36: 8월1주 | J36: =IF($I36="","",IFERROR(DATE(기준정보!$C$7,VALUE(LEFT($I36,FIND("월",$I36)-1)),1+7*(VALUE(SUBSTITUTE(MID($I36,FIND("월",$I36)+1,5),"주",""))-1)),"")) | K36: =IF($J36="","",IF(AND(ISNUMBER(SEARCH("미얀마",$U36)),$J36-기준정보!$C$5>=기준정보!$C$8,$J36-기준정보!$C$5<=기준정보!$C$9),기준정보!$C$8-1,IF(AND(ISNUMBER(SEARCH("인도네시아",$U36)),$J36-기준정보!$C$5>=기준정보!$C$10,$J36-기준정보!$C$5<=기준정보!$C$11),기준정보!$C$10-1,$J36-기준정보!$C$5))) | L36: =IF($K36="","",IF(ISNUMBER(SEARCH("미얀마",$U36)),MAX(0,MIN($K36,기준정보!$C$9)-MAX($K36-기준정보!$C$6,기준정보!$C$8)+1),IF(ISNUMBER(SEARCH("인도네시아",$U36)),MAX(0,MIN($K36,기준정보!$C$11)-MAX($K36-기준정보!$C$6,기준정보!$C$10)+1),0))) | M36: =IF($K36="","",$K36-기준정보!$C$6-$L36) | N36: =IF($M36="","",$M36-기준정보!$C$4) | S36: =IF($H36="","",IF($H36="C","본사(소재팀)",IF($H36="완","생산처","확인 필요"))) | T36: 거림 | U36: 베트남 | Z36: 1500 | AA36: 48429000 | AB36: 282000000 | AD36: =IF($J36="","출고일 미정",IF($P36="X","작지 미발행",IF($P36="부분","작지 일부 미발행",IF(AND($R36<>"",$R36>$M36),"소재입고 마감("&TEXT($M36,"MM/DD")&") 초과",IF($P36="","발행여부 확인 필요",IF($R36="","소재 입고일정 확인 필요","정상")))))) | AE36: =IF($J36="","",IF(OR(LEFT($AD36,2)="작지",LEFT($AD36,4)="소재입고"),IF(LEFT($G36,1)="A","★ 납기위험(A코드)","◆ 지연주의"),IF($AD36="정상","✓ 정상","? 확인필요")))
A37: 33 | B37: 문도혁 | C37: 서은미 | D37: TVPNA27612 | E37: 여성 크롭 테이퍼드 팬츠 | F37: ABE/MID | G37: =IF($D37="","",IF(MID($D37,5,1)="A","A(가을)",IF(MID($D37,5,1)="W","W(겨울)",IF(MID($D37,5,1)="X","X(사계절)",MID($D37,5,1))))) | H37: C | I37: 8월1주 | J37: =IF($I37="","",IFERROR(DATE(기준정보!$C$7,VALUE(LEFT($I37,FIND("월",$I37)-1)),1+7*(VALUE(SUBSTITUTE(MID($I37,FIND("월",$I37)+1,5),"주",""))-1)),"")) | K37: =IF($J37="","",IF(AND(ISNUMBER(SEARCH("미얀마",$U37)),$J37-기준정보!$C$5>=기준정보!$C$8,$J37-기준정보!$C$5<=기준정보!$C$9),기준정보!$C$8-1,IF(AND(ISNUMBER(SEARCH("인도네시아",$U37)),$J37-기준정보!$C$5>=기준정보!$C$10,$J37-기준정보!$C$5<=기준정보!$C$11),기준정보!$C$10-1,$J37-기준정보!$C$5))) | L37: =IF($K37="","",IF(ISNUMBER(SEARCH("미얀마",$U37)),MAX(0,MIN($K37,기준정보!$C$9)-MAX($K37-기준정보!$C$6,기준정보!$C$8)+1),IF(ISNUMBER(SEARCH("인도네시아",$U37)),MAX(0,MIN($K37,기준정보!$C$11)-MAX($K37-기준정보!$C$6,기준정보!$C$10)+1),0))) | M37: =IF($K37="","",$K37-기준정보!$C$6-$L37) | N37: =IF($M37="","",$M37-기준정보!$C$4) | S37: =IF($H37="","",IF($H37="C","본사(소재팀)",IF($H37="완","생산처","확인 필요"))) | T37: TBO | U37: 베트남 | Z37: 2500 | AA37: 71710000 | AB37: 445000000 | AD37: =IF($J37="","출고일 미정",IF($P37="X","작지 미발행",IF($P37="부분","작지 일부 미발행",IF(AND($R37<>"",$R37>$M37),"소재입고 마감("&TEXT($M37,"MM/DD")&") 초과",IF($P37="","발행여부 확인 필요",IF($R37="","소재 입고일정 확인 필요","정상")))))) | AE37: =IF($J37="","",IF(OR(LEFT($AD37,2)="작지",LEFT($AD37,4)="소재입고"),IF(LEFT($G37,1)="A","★ 납기위험(A코드)","◆ 지연주의"),IF($AD37="정상","✓ 정상","? 확인필요")))
A38: 34 | B38: 문도혁 | C38: 서은미 | D38: TVPOA27622 | E38: 여성 메쉬 하이브리드 스커트 | F38: CO1/CO2 | G38: =IF($D38="","",IF(MID($D38,5,1)="A","A(가을)",IF(MID($D38,5,1)="W","W(겨울)",IF(MID($D38,5,1)="X","X(사계절)",MID($D38,5,1))))) | I38: 8월1주 | J38: =IF($I38="","",IFERROR(DATE(기준정보!$C$7,VALUE(LEFT($I38,FIND("월",$I38)-1)),1+7*(VALUE(SUBSTITUTE(MID($I38,FIND("월",$I38)+1,5),"주",""))-1)),"")) | K38: =IF($J38="","",IF(AND(ISNUMBER(SEARCH("미얀마",$U38)),$J38-기준정보!$C$5>=기준정보!$C$8,$J38-기준정보!$C$5<=기준정보!$C$9),기준정보!$C$8-1,IF(AND(ISNUMBER(SEARCH("인도네시아",$U38)),$J38-기준정보!$C$5>=기준정보!$C$10,$J38-기준정보!$C$5<=기준정보!$C$11),기준정보!$C$10-1,$J38-기준정보!$C$5))) | L38: =IF($K38="","",IF(ISNUMBER(SEARCH("미얀마",$U38)),MAX(0,MIN($K38,기준정보!$C$9)-MAX($K38-기준정보!$C$6,기준정보!$C$8)+1),IF(ISNUMBER(SEARCH("인도네시아",$U38)),MAX(0,MIN($K38,기준정보!$C$11)-MAX($K38-기준정보!$C$6,기준정보!$C$10)+1),0))) | M38: =IF($K38="","",$K38-기준정보!$C$6-$L38) | N38: =IF($M38="","",$M38-기준정보!$C$4) | S38: =IF($H38="","",IF($H38="C","본사(소재팀)",IF($H38="완","생산처","확인 필요"))) | Z38: 600 | AA38: 19800000 | AB38: 112800000 | AD38: =IF($J38="","출고일 미정",IF($P38="X","작지 미발행",IF($P38="부분","작지 일부 미발행",IF(AND($R38<>"",$R38>$M38),"소재입고 마감("&TEXT($M38,"MM/DD")&") 초과",IF($P38="","발행여부 확인 필요",IF($R38="","소재 입고일정 확인 필요","정상")))))) | AE38: =IF($J38="","",IF(OR(LEFT($AD38,2)="작지",LEFT($AD38,4)="소재입고"),IF(LEFT($G38,1)="A","★ 납기위험(A코드)","◆ 지연주의"),IF($AD38="정상","✓ 정상","? 확인필요")))
A39: 35 | B39: 정영준 | C39: 서은미 | D39: TVSXA27602 | E39: 여성 체크 긴팔 셔츠 | F39: CO1/CO2/CO3 | G39: =IF($D39="","",IF(MID($D39,5,1)="A","A(가을)",IF(MID($D39,5,1)="W","W(겨울)",IF(MID($D39,5,1)="X","X(사계절)",MID($D39,5,1))))) | I39: 8월1주 | J39: =IF($I39="","",IFERROR(DATE(기준정보!$C$7,VALUE(LEFT($I39,FIND("월",$I39)-1)),1+7*(VALUE(SUBSTITUTE(MID($I39,FIND("월",$I39)+1,5),"주",""))-1)),"")) | K39: =IF($J39="","",IF(AND(ISNUMBER(SEARCH("미얀마",$U39)),$J39-기준정보!$C$5>=기준정보!$C$8,$J39-기준정보!$C$5<=기준정보!$C$9),기준정보!$C$8-1,IF(AND(ISNUMBER(SEARCH("인도네시아",$U39)),$J39-기준정보!$C$5>=기준정보!$C$10,$J39-기준정보!$C$5<=기준정보!$C$11),기준정보!$C$10-1,$J39-기준정보!$C$5))) | L39: =IF($K39="","",IF(ISNUMBER(SEARCH("미얀마",$U39)),MAX(0,MIN($K39,기준정보!$C$9)-MAX($K39-기준정보!$C$6,기준정보!$C$8)+1),IF(ISNUMBER(SEARCH("인도네시아",$U39)),MAX(0,MIN($K39,기준정보!$C$11)-MAX($K39-기준정보!$C$6,기준정보!$C$10)+1),0))) | M39: =IF($K39="","",$K39-기준정보!$C$6-$L39) | N39: =IF($M39="","",$M39-기준정보!$C$4) | S39: =IF($H39="","",IF($H39="C","본사(소재팀)",IF($H39="완","생산처","확인 필요"))) | T39: 픽스쳐 | U39: 베트남 | Z39: 3000 | AA39: 78654000 | AB39: 444000000 | AD39: =IF($J39="","출고일 미정",IF($P39="X","작지 미발행",IF($P39="부분","작지 일부 미발행",IF(AND($R39<>"",$R39>$M39),"소재입고 마감("&TEXT($M39,"MM/DD")&") 초과",IF($P39="","발행여부 확인 필요",IF($R39="","소재 입고일정 확인 필요","정상")))))) | AE39: =IF($J39="","",IF(OR(LEFT($AD39,2)="작지",LEFT($AD39,4)="소재입고"),IF(LEFT($G39,1)="A","★ 납기위험(A코드)","◆ 지연주의"),IF($AD39="정상","✓ 정상","? 확인필요")))
A40: 36 | B40: 정영준 | C40: 서은미 | D40: TVTBA27602 | E40: 여성 베이직 피케 긴팔 폴로 | F40: CO1/CO2/CO3 | G40: =IF($D40="","",IF(MID($D40,5,1)="A","A(가을)",IF(MID($D40,5,1)="W","W(겨울)",IF(MID($D40,5,1)="X","X(사계절)",MID($D40,5,1))))) | H40: 슬림 | I40: 8월1주 | J40: =IF($I40="","",IFERROR(DATE(기준정보!$C$7,VALUE(LEFT($I40,FIND("월",$I40)-1)),1+7*(VALUE(SUBSTITUTE(MID($I40,FIND("월",$I40)+1,5),"주",""))-1)),"")) | K40: =IF($J40="","",IF(AND(ISNUMBER(SEARCH("미얀마",$U40)),$J40-기준정보!$C$5>=기준정보!$C$8,$J40-기준정보!$C$5<=기준정보!$C$9),기준정보!$C$8-1,IF(AND(ISNUMBER(SEARCH("인도네시아",$U40)),$J40-기준정보!$C$5>=기준정보!$C$10,$J40-기준정보!$C$5<=기준정보!$C$11),기준정보!$C$10-1,$J40-기준정보!$C$5))) | L40: =IF($K40="","",IF(ISNUMBER(SEARCH("미얀마",$U40)),MAX(0,MIN($K40,기준정보!$C$9)-MAX($K40-기준정보!$C$6,기준정보!$C$8)+1),IF(ISNUMBER(SEARCH("인도네시아",$U40)),MAX(0,MIN($K40,기준정보!$C$11)-MAX($K40-기준정보!$C$6,기준정보!$C$10)+1),0))) | M40: =IF($K40="","",$K40-기준정보!$C$6-$L40) | N40: =IF($M40="","",$M40-기준정보!$C$4) | S40: =IF($H40="","",IF($H40="C","본사(소재팀)",IF($H40="완","생산처","확인 필요"))) | T40: TESSELLATION | U40: 베트남 | Z40: 5000 | AA40: 90000000 | AB40: 640000000 | AD40: =IF($J40="","출고일 미정",IF($P40="X","작지 미발행",IF($P40="부분","작지 일부 미발행",IF(AND($R40<>"",$R40>$M40),"소재입고 마감("&TEXT($M40,"MM/DD")&") 초과",IF($P40="","발행여부 확인 필요",IF($R40="","소재 입고일정 확인 필요","정상")))))) | AE40: =IF($J40="","",IF(OR(LEFT($AD40,2)="작지",LEFT($AD40,4)="소재입고"),IF(LEFT($G40,1)="A","★ 납기위험(A코드)","◆ 지연주의"),IF($AD40="정상","✓ 정상","? 확인필요")))
A41: 37 | B41: 정영준 | C41: 서은미 | D41: TVTBA27604 | E41: 여성 체크 긴팔 폴로 | F41: CO1/CO2 | G41: =IF($D41="","",IF(MID($D41,5,1)="A","A(가을)",IF(MID($D41,5,1)="W","W(겨울)",IF(MID($D41,5,1)="X","X(사계절)",MID($D41,5,1))))) | H41: 슬림 | I41: 8월1주 | J41: =IF($I41="","",IFERROR(DATE(기준정보!$C$7,VALUE(LEFT($I41,FIND("월",$I41)-1)),1+7*(VALUE(SUBSTITUTE(MID($I41,FIND("월",$I41)+1,5),"주",""))-1)),"")) | K41: =IF($J41="","",IF(AND(ISNUMBER(SEARCH("미얀마",$U41)),$J41-기준정보!$C$5>=기준정보!$C$8,$J41-기준정보!$C$5<=기준정보!$C$9),기준정보!$C$8-1,IF(AND(ISNUMBER(SEARCH("인도네시아",$U41)),$J41-기준정보!$C$5>=기준정보!$C$10,$J41-기준정보!$C$5<=기준정보!$C$11),기준정보!$C$10-1,$J41-기준정보!$C$5))) | L41: =IF($K41="","",IF(ISNUMBER(SEARCH("미얀마",$U41)),MAX(0,MIN($K41,기준정보!$C$9)-MAX($K41-기준정보!$C$6,기준정보!$C$8)+1),IF(ISNUMBER(SEARCH("인도네시아",$U41)),MAX(0,MIN($K41,기준정보!$C$11)-MAX($K41-기준정보!$C$6,기준정보!$C$10)+1),0))) | M41: =IF($K41="","",$K41-기준정보!$C$6-$L41) | N41: =IF($M41="","",$M41-기준정보!$C$4) | S41: =IF($H41="","",IF($H41="C","본사(소재팀)",IF($H41="완","생산처","확인 필요"))) | T41: 장안 | U41: 베트남 | Z41: 3000 | AA41: 66000000 | AB41: 414000000 | AD41: =IF($J41="","출고일 미정",IF($P41="X","작지 미발행",IF($P41="부분","작지 일부 미발행",IF(AND($R41<>"",$R41>$M41),"소재입고 마감("&TEXT($M41,"MM/DD")&") 초과",IF($P41="","발행여부 확인 필요",IF($R41="","소재 입고일정 확인 필요","정상")))))) | AE41: =IF($J41="","",IF(OR(LEFT($AD41,2)="작지",LEFT($AD41,4)="소재입고"),IF(LEFT($G41,1)="A","★ 납기위험(A코드)","◆ 지연주의"),IF($AD41="정상","✓ 정상","? 확인필요")))
...

Sheet 금액 요약
B2: 27FW 구분별 금액 요약 — 원가합 · 소매가합
B3: 구분: 의류(J/T/V 등) · 용품(품번 Q로 시작) · WM/피싱(품번 8로 시작, 27FW 현재 0건). 트래커 값 수정 시 자동 갱신됩니다.
B5: 구분 | C5: 스타일 수 | D5: 기획수량 (장) | E5: 원가합 (원) | F5: 소매가합 (원) | G5: 소매가합 비중
B6: 의류 | C6: =SUMPRODUCT((LEFT('소재역산 트래커'!$D$5:$D$429,1)<>"Q")*(LEFT('소재역산 트래커'!$D$5:$D$429,1)<>"8")*('소재역산 트래커'!$D$5:$D$429<>"")) | D6: =SUMPRODUCT((LEFT('소재역산 트래커'!$D$5:$D$429,1)<>"Q")*(LEFT('소재역산 트래커'!$D$5:$D$429,1)<>"8")*('소재역산 트래커'!$D$5:$D$429<>"")*'소재역산 트래커'!$Z$5:$Z$429) | E6: =SUMPRODUCT((LEFT('소재역산 트래커'!$D$5:$D$429,1)<>"Q")*(LEFT('소재역산 트래커'!$D$5:$D$429,1)<>"8")*('소재역산 트래커'!$D$5:$D$429<>"")*'소재역산 트래커'!$AA$5:$AA$429) | F6: =SUMPRODUCT((LEFT('소재역산 트래커'!$D$5:$D$429,1)<>"Q")*(LEFT('소재역산 트래커'!$D$5:$D$429,1)<>"8")*('소재역산 트래커'!$D$5:$D$429<>"")*'소재역산 트래커'!$AB$5:$AB$429) | G6: =IF($F$9=0,"",F6/$F$9)
B7: 용품 (Q) | C7: =SUMPRODUCT((LEFT('소재역산 트래커'!$D$5:$D$429,1)="Q")*1) | D7: =SUMPRODUCT((LEFT('소재역산 트래커'!$D$5:$D$429,1)="Q")*1*'소재역산 트래커'!$Z$5:$Z$429) | E7: =SUMPRODUCT((LEFT('소재역산 트래커'!$D$5:$D$429,1)="Q")*1*'소재역산 트래커'!$AA$5:$AA$429) | F7: =SUMPRODUCT((LEFT('소재역산 트래커'!$D$5:$D$429,1)="Q")*1*'소재역산 트래커'!$AB$5:$AB$429) | G7: =IF($F$9=0,"",F7/$F$9)
B8: WM/피싱 (8) | C8: =SUMPRODUCT((LEFT('소재역산 트래커'!$D$5:$D$429,1)="8")*1) | D8: =SUMPRODUCT((LEFT('소재역산 트래커'!$D$5:$D$429,1)="8")*1*'소재역산 트래커'!$Z$5:$Z$429) | E8: =SUMPRODUCT((LEFT('소재역산 트래커'!$D$5:$D$429,1)="8")*1*'소재역산 트래커'!$AA$5:$AA$429) | F8: =SUMPRODUCT((LEFT('소재역산 트래커'!$D$5:$D$429,1)="8")*1*'소재역산 트래커'!$AB$5:$AB$429) | G8: =IF($F$9=0,"",F8/$F$9)
B9: 합계 | C9: =SUM(C6:C8) | D9: =SUM(D6:D8) | E9: =SUM(E6:E8) | F9: =SUM(F6:F8) | G9: =IF(F9=0,"",1)
B12: 의류 내 비수기 선정 비중 (27FW 비수기 수령 시 자동 계산)
B13: 비수기 = KS_비수기 선정 27FW 탭 N열 'O' 기준 — 트래커 '비수기 선정' 열 입력 시 갱신
B15: 구분 | C15: 스타일 수 | D15: 기획수량 (장) | E15: 원가합 (원) | F15: 소매가합 (원)
B16: 의류 전체 | C16: =C6 | D16: =D6 | E16: =E6 | F16: =F6
B17: 비수기 선정 (의류) | C17: =SUMPRODUCT((LEFT('소재역산 트래커'!$D$5:$D$429,1)<>"Q")*(LEFT('소재역산 트래커'!$D$5:$D$429,1)<>"8")*('소재역산 트래커'!$D$5:$D$429<>"")*('소재역산 트래커'!$O$5:$O$429="O")) | D17: =SUMPRODUCT((LEFT('소재역산 트래커'!$D$5:$D$429,1)<>"Q")*(LEFT('소재역산 트래커'!$D$5:$D$429,1)<>"8")*('소재역산 트래커'!$D$5:$D$429<>"")*('소재역산 트래커'!$O$5:$O$429="O")*'소재역산 트래커'!$Z$5:$Z$429) | E17: =SUMPRODUCT((LEFT('소재역산 트래커'!$D$5:$D$429,1)<>"Q")*(LEFT('소재역산 트래커'!$D$5:$D$429,1)<>"8")*('소재역산 트래커'!$D$5:$D$429<>"")*('소재역산 트래커'!$O$5:$O$429="O")*'소재역산 트래커'!$AA$5:$AA$429) | F17: =SUMPRODUCT((LEFT('소재역산 트래커'!$D$5:$D$429,1)<>"Q")*(LEFT('소재역산 트래커'!$D$5:$D$429,1)<>"8")*('소재역산 트래커'!$D$5:$D$429<>"")*('소재역산 트래커'!$O$5:$O$429="O")*'소재역산 트래커'!$AB$5:$AB$429)
B18: 비수기 비중 | C18: =IF(C16=0,"",C17/C16) | D18: =IF(D16=0,"",D17/D16) | E18: =IF(E16=0,"",E17/E16) | F18: =IF(F16=0,"",F17/F16)
B20: * 원가합 = Σ(기획수량×입고원가), 소매가합 = Σ(기획수량×예상소매가) — 생진테 추출본 기준. 기획수량 미입력 스타일은 합계 미포함

Sheet 리스크 요약
B2: 27FW 소재일정 리스크 요약 (생진테 출고일 · 띤쨘/르바란 보정)
B3: ="기준일: "&TEXT(기준정보!$C$4,"YYYY-MM-DD")&" · 소재마감 = 출고일 − "&(기준정보!$C$5+기준정보!$C$6)&"일 − 휴무보정"&" · A "&COUNTIF('소재역산 트래커'!$G$5:$G$429,"A(가을)")&" / W "&COUNTIF('소재역산 트래커'!$G$5:$G$429,"W(겨울)")&" / X "&COUNTIF('소재역산 트래커'!$G$5:$G$429,"X(사계절)")
B5: 전체 스타일 | D5: A코드(가을) 스타일 | F5: ★ 납기위험(A코드) | H5: ◆ 지연주의(W/X) | J5: 출고일 미정
B6: =COUNTA('소재역산 트래커'!$D$5:$D$429) | D6: =COUNTIF('소재역산 트래커'!$G$5:$G$429,"A(가을)") | F6: =COUNTIF('소재역산 트래커'!$AE$5:$AE$429,"★*") | H6: =COUNTIF('소재역산 트래커'!$AE$5:$AE$429,"◆*") | J6: =COUNTIF('소재역산 트래커'!$AD$5:$AD$429,"출고일 미정")
B9: MD별 현황
B10: MD | C10: 스타일 수 | D10: A코드 | E10: 출고일 미정 | F10: 작지 미발행(X/부분) | G10: 비수기 선정 | H10: ★ 납기위험 | I10: 조율완료
B11: 김준래 | C11: =COUNTIF('소재역산 트래커'!$B$5:$B$429,$B11) | D11: =COUNTIFS('소재역산 트래커'!$B$5:$B$429,$B11,'소재역산 트래커'!$G$5:$G$429,"A(가을)") | E11: =COUNTIFS('소재역산 트래커'!$B$5:$B$429,$B11,'소재역산 트래커'!$AD$5:$AD$429,"출고일 미정") | F11: =COUNTIFS('소재역산 트래커'!$B$5:$B$429,$B11,'소재역산 트래커'!$P$5:$P$429,"X")+COUNTIFS('소재역산 트래커'!$B$5:$B$429,$B11,'소재역산 트래커'!$P$5:$P$429,"부분") | G11: =COUNTIFS('소재역산 트래커'!$B$5:$B$429,$B11,'소재역산 트래커'!$O$5:$O$429,"O") | H11: =COUNTIFS('소재역산 트래커'!$B$5:$B$429,$B11,'소재역산 트래커'!$AE$5:$AE$429,"★*") | I11: =COUNTIFS('소재역산 트래커'!$B$5:$B$429,$B11,'소재역산 트래커'!$AF$5:$AF$429,"조율완료")
B12: 문도혁 | C12: =COUNTIF('소재역산 트래커'!$B$5:$B$429,$B12) | D12: =COUNTIFS('소재역산 트래커'!$B$5:$B$429,$B12,'소재역산 트래커'!$G$5:$G$429,"A(가을)") | E12: =COUNTIFS('소재역산 트래커'!$B$5:$B$429,$B12,'소재역산 트래커'!$AD$5:$AD$429,"출고일 미정") | F12: =COUNTIFS('소재역산 트래커'!$B$5:$B$429,$B12,'소재역산 트래커'!$P$5:$P$429,"X")+COUNTIFS('소재역산 트래커'!$B$5:$B$429,$B12,'소재역산 트래커'!$P$5:$P$429,"부분") | G12: =COUNTIFS('소재역산 트래커'!$B$5:$B$429,$B12,'소재역산 트래커'!$O$5:$O$429,"O") | H12: =COUNTIFS('소재역산 트래커'!$B$5:$B$429,$B12,'소재역산 트래커'!$AE$5:$AE$429,"★*") | I12: =COUNTIFS('소재역산 트래커'!$B$5:$B$429,$B12,'소재역산 트래커'!$AF$5:$AF$429,"조율완료")
B13: 박술홍 | C13: =COUNTIF('소재역산 트래커'!$B$5:$B$429,$B13) | D13: =COUNTIFS('소재역산 트래커'!$B$5:$B$429,$B13,'소재역산 트래커'!$G$5:$G$429,"A(가을)") | E13: =COUNTIFS('소재역산 트래커'!$B$5:$B$429,$B13,'소재역산 트래커'!$AD$5:$AD$429,"출고일 미정") | F13: =COUNTIFS('소재역산 트래커'!$B$5:$B$429,$B13,'소재역산 트래커'!$P$5:$P$429,"X")+COUNTIFS('소재역산 트래커'!$B$5:$B$429,$B13,'소재역산 트래커'!$P$5:$P$429,"부분") | G13: =COUNTIFS('소재역산 트래커'!$B$5:$B$429,$B13,'소재역산 트래커'!$O$5:$O$429,"O") | H13: =COUNTIFS('소재역산 트래커'!$B$5:$B$429,$B13,'소재역산 트래커'!$AE$5:$AE$429,"★*") | I13: =COUNTIFS('소재역산 트래커'!$B$5:$B$429,$B13,'소재역산 트래커'!$AF$5:$AF$429,"조율완료")
B14: 박지인 | C14: =COUNTIF('소재역산 트래커'!$B$5:$B$429,$B14) | D14: =COUNTIFS('소재역산 트래커'!$B$5:$B$429,$B14,'소재역산 트래커'!$G$5:$G$429,"A(가을)") | E14: =COUNTIFS('소재역산 트래커'!$B$5:$B$429,$B14,'소재역산 트래커'!$AD$5:$AD$429,"출고일 미정") | F14: =COUNTIFS('소재역산 트래커'!$B$5:$B$429,$B14,'소재역산 트래커'!$P$5:$P$429,"X")+COUNTIFS('소재역산 트래커'!$B$5:$B$429,$B14,'소재역산 트래커'!$P$5:$P$429,"부분") | G14: =COUNTIFS('소재역산 트래커'!$B$5:$B$429,$B14,'소재역산 트래커'!$O$5:$O$429,"O") | H14: =COUNTIFS('소재역산 트래커'!$B$5:$B$429,$B14,'소재역산 트래커'!$AE$5:$AE$429,"★*") | I14: =COUNTIFS('소재역산 트래커'!$B$5:$B$429,$B14,'소재역산 트래커'!$AF$5:$AF$429,"조율완료")
